Workbook

Sheet Master Anggota
B2: NO | C2: NPP | D2: Update NPP | E2: N A M A | F2: Status | G2: Tanggal Bergabung | H2: Area | I2: NPP | J2: STATUS | K2: TEMPAT KERJA | L2: WAJIB | M2: MANA SUKA | N2: PKPRI | O2: POKOK | P2: KHUSUS | Q2: KHUSUS | R2: Keterangan | S2: Keterangan
B3: 1 | C3: 00553 | D3: =VLOOKUP(E3,[1]Mei!$E$6:$F$173,2,0) -> 00553 | E3: Abdul Cahyo Nugroho | F3: Aktif | H3: Cakung | I3: 00553 | J3: =IF(LEFT(I3,2)="00","Tetap","Dilayani") -> Tetap | K3: SPI | L3: 100000 | M3: 150000 | O3: 20000 | Q3: 20000 | R3: 00. Awal
B4: 2 | C4: PHL | D4: =VLOOKUP(E4,[1]Mei!$E$6:$F$173,2,0) -> #N/A | E4: Rikiansyah | F4: Purna Bakti 2025 | H4: Cakung | I4: PHL | J4: =IF(LEFT(I4,2)="00","Tetap","Dilayani") -> Dilayani | K4: Divisi Pemasaran | L4: 100000 | M4: 100000 | O4: 50000 | Q4: 50000 | R4: 00. Awal
B5: 3 | C5: 00549 | D5: =VLOOKUP(E5,[1]Mei!$E$6:$F$173,2,0) -> 00549 | E5: Ahmad Fauzi - 00549 | F5: Aktif | H5: Cakung | I5: 00549 | J5: =IF(LEFT(I5,2)="00","Tetap","Dilayani") -> Tetap | K5: Divisi Produksi | L5: 100000 | M5: 100000 | O5: 50000 | Q5: 50000 | R5: 00. Awal
B6: 4 | C6: 01778 | D6: =VLOOKUP(E6,[1]Mei!$E$6:$F$173,2,0) -> #N/A | E6: Iman Solaeman | F6: Purna Bakti 2025 | G6: 45909 | I6: 01778 | J6: =IF(LEFT(I6,2)="00","Tetap","Dilayani") -> Dilayani | K6: Divisi SDM & Umum | L6: 100000 | M6: 300000
B7: 5 | C7: Nasabah | D7: =VLOOKUP(E7,[1]Mei!$E$6:$F$173,2,0) -> #N/A | E7: Tan Kian Liem/I Komang S. J | F7: Purna Bakti 2024 | I7: Nasabah | J7: Nasabah
B8: 6 | C8: 01154 | D8: =VLOOKUP(E8,[1]Mei!$E$6:$F$173,2,0) -> #N/A | E8: Sana | F8: Purna Bakti 2024 | H8: Cakung | I8: 01154 | J8: =IF(LEFT(I8,2)="00","Tetap","Dilayani") -> Dilayani | K8: Divisi Penggemukan | L8: 100000 | M8: 100000 | O8: 20000 | Q8: =O8+P8 -> 20000 | R8: 00. Awal
B9: 7 | C9: 01156 | D9: =VLOOKUP(E9,[1]Mei!$E$6:$F$173,2,0) -> #N/A | E9: Nasrul | F9: Purna Bakti 2024 | H9: Cakung | I9: 01156 | J9: =IF(LEFT(I9,2)="00","Tetap","Dilayani") -> Dilayani | K9: Divisi Penggemukan | L9: 100000 | M9: 100000 | O9: 20000 | Q9: =O9+P9 -> 20000 | R9: 00. Awal
B10: 8 | C10: 00309 | D10: =VLOOKUP(E10,[1]Mei!$E$6:$F$173,2,0) -> #N/A | E10: Ahmad Rusli | F10: Purna Bakti 2024 | H10: Cakung | I10: 00309 | J10: Tetap | K10: Bidang Umum | L10: 100000 | M10: 75000 | N10: 200 | O10: 5000 | Q10: 505000 | R10: 00. Awal
B11: 9 | C11: 00546 | D11: =VLOOKUP(E11,[1]Mei!$E$6:$F$173,2,0) -> 00546 | E11: Andrian Fadly | F11: Aktif | H11: Cakung | I11: 00546 | J11: =IF(LEFT(I11,2)="00","Tetap","Dilayani") -> Tetap | K11: Divisi Pemasaran | L11: 100000 | M11: 50000 | O11: 20000 | R11: 00. Awal
B12: 10 | C12: 00511 | D12: =VLOOKUP(E12,[1]Mei!$E$6:$F$173,2,0) -> 00511 | E12: Andung Juanda | F12: Aktif | H12: Cakung | I12: 00511 | J12: =IF(LEFT(I12,2)="00","Tetap","Dilayani") -> Tetap | K12: Divisi Produksi | L12: 100000 | M12: 50000 | O12: 5000 | R12: 00. Awal
B13: 11 | C13: 00340 | D13: =VLOOKUP(E13,[1]Mei!$E$6:$F$173,2,0) -> 00340 | E13: Anwari | F13: Aktif | H13: Cakung | I13: 00340 | J13: =IF(LEFT(I13,2)="00","Tetap","Dilayani") -> Tetap | K13: Divisi Produksi | L13: 100000 | M13: 275000 | N13: 200 | O13: 5000 | R13: 00. Awal
B14: 12 | C14: 00345 | D14: =VLOOKUP(E14,[1]Mei!$E$6:$F$173,2,0) -> #N/A | E14: Ardiansyah | F14: Purna Bakti 2026 | H14: Cakung | I14: 00345 | J14: =IF(LEFT(I14,2)="00","Tetap","Dilayani") -> Tetap | K14: Bidang Umum | L14: 100000 | M14: 275000 | N14: 200 | O14: 5000 | R14: 00. Awal
B15: 13 | C15: 01774 | D15: =VLOOKUP(E15,[1]Mei!$E$6:$F$173,2,0) -> #N/A | E15: Ery Martadinata | F15: Purna Bakti 2025 | G15: 45896 | I15: 01774 | J15: =IF(LEFT(I15,2)="00","Tetap","Dilayani") -> Dilayani | K15: Divisi SDM & Umum | L15: 100000 | M15: 100000
B16: 14 | C16: 00519 | D16: =VLOOKUP(E16,[1]Mei!$E$6:$F$173,2,0) -> 00519 | E16: Budi Laksono | F16: Aktif | H16: Cakung | I16: 00519 | J16: =IF(LEFT(I16,2)="00","Tetap","Dilayani") -> Tetap | K16: Divisi Pemasaran | L16: 100000 | M16: 125000 | N16: 0 | O16: 5000 | R16: 00. Awal
B17: 15 | C17: 00325 | D17: =VLOOKUP(E17,[1]Mei!$E$6:$F$173,2,0) -> 00325 | E17: Dadi Muhamad Mulyadi | F17: Aktif | H17: Pulogadung | I17: 00325 | J17: =IF(LEFT(I17,2)="00","Tetap","Dilayani") -> Tetap | K17: RPH Pulogadung | L17: 100000 | M17: 75000 | N17: 200 | O17: 5000 | R17: 00. Awal
B18: 16 | C18: 00543 | D18: =VLOOKUP(E18,[1]Mei!$E$6:$F$173,2,0) -> 00543 | E18: Dara Maulida | F18: Aktif | H18: Cakung | I18: 00543 | J18: =IF(LEFT(I18,2)="00","Tetap","Dilayani") -> Tetap | K18: Divisi Pemasaran | L18: 100000 | M18: 100000 | O18: 20000 | R18: 00. Awal
B19: 17 | C19: 00540 | D19: =VLOOKUP(E19,[1]Mei!$E$6:$F$173,2,0) -> 00540 | E19: Dedy Kurniawan | F19: Aktif | H19: Cakung | I19: 00540 | J19: =IF(LEFT(I19,2)="00","Tetap","Dilayani") -> Tetap | K19: Divisi Pemasaran | L19: 100000 | M19: 125000 | O19: 5000 | R19: 00. Awal
B20: 18 | C20: 00539 | D20: =VLOOKUP(E20,[1]Mei!$E$6:$F$173,2,0) -> 00539 | E20: Dewi Kartini | F20: Aktif | H20: Cakung | I20: 00539 | J20: =IF(LEFT(I20,2)="00","Tetap","Dilayani") -> Tetap | K20: Bidang Keuangan | L20: 100000 | M20: 50000 | N20: 0 | O20: 20000 | R20: 00. Awal
B21: 19 | C21: Nasabah | D21: =VLOOKUP(E21,[1]Mei!$E$6:$F$173,2,0) -> #N/A | E21: Kadelis / Udin / Wati | F21: Purna Bakti 2025 | G21: 45919 | H21: Kapuk | I21: Nasabah | J21: =IF(LEFT(I21,2)="00","Tetap","Dilayani") -> Dilayani | K21: Nasabah Kapuk
B22: 20 | C22: 00380 | D22: =VLOOKUP(E22,[1]Mei!$E$6:$F$173,2,0) -> #N/A | E22: Didi Tarmudi | F22: Purna Bakti 2025 | H22: Cakung | I22: 00380 | J22: =IF(LEFT(I22,2)="00","Tetap","Dilayani") -> Tetap | K22: RPH Cakung | L22: 100000 | M22: 175000 | N22: 200 | O22: 5000 | R22: 00. Awal
B23: 21 | C23: 00518 | D23: =VLOOKUP(E23,[1]Mei!$E$6:$F$173,2,0) -> 00518 | E23: Diki Firmansyah | F23: Aktif | H23: Cakung | I23: 00518 | J23: =IF(LEFT(I23,2)="00","Tetap","Dilayani") -> Tetap | K23: RPH Pulogadung | L23: 150000 | M23: 100000 | O23: 50000 | R23: 00. Awal
B24: 22 | C24: Nasabah | D24: =VLOOKUP(E24,[1]Mei!$E$6:$F$173,2,0) -> #N/A | E24: Ny. Tuti/Dahyuri | F24: Purna Bakti 2025 | G24: 45919 | I24: Nasabah | J24: Nasabah
B25: 23 | C25: 00490 | D25: =VLOOKUP(E25,[1]Mei!$E$6:$F$173,2,0) -> 00490 | E25: Eka Yanuar Santosa | F25: Aktif | H25: Cakung | I25: 00490 | J25: =IF(LEFT(I25,2)="00","Tetap","Dilayani") -> Tetap | K25: Bidang Umum | L25: 100000 | M25: 75000 | N25: 200 | O25: 5000 | R25: 00. Awal
B26: 24 | C26: Nasabah | D26: =VLOOKUP(E26,[1]Mei!$E$6:$F$173,2,0) -> #N/A | E26: Victor David Sambuaga | F26: Purna Bakti 2025 | G26: 45919 | I26: Nasabah | J26: Nasabah
B27: 25 | C27: 00496 | D27: =VLOOKUP(E27,[1]Mei!$E$6:$F$173,2,0) -> 00496 | E27: Ferika Pujiyanti | F27: Aktif | H27: Cakung | I27: 00496 | J27: =IF(LEFT(I27,2)="00","Tetap","Dilayani") -> Tetap | K27: Bidang Keuangan | L27: 100000 | M27: 150000 | N27: 200 | O27: 5000 | R27: 00. Awal
B28: 26 | C28: 00517 | D28: =VLOOKUP(E28,[1]Mei!$E$6:$F$173,2,0) -> 00517 | E28: Gunawan | F28: Aktif | H28: Cakung | I28: 00517 | J28: =IF(LEFT(I28,2)="00","Tetap","Dilayani") -> Tetap | K28: Bidang Litbang | L28: 100000 | M28: 300000 | N28: 200 | O28: 5000 | R28: 00. Awal
B29: 27 | C29: 00552 | D29: =VLOOKUP(E29,[1]Mei!$E$6:$F$173,2,0) -> 00552 | E29: Alfian Noor | F29: Aktif | H29: Cakung | I29: 00552 | J29: =IF(LEFT(I29,2)="00","Tetap","Dilayani") -> Tetap | K29: Bidang Umum | L29: 200000 | M29: 100000 | O29: 20000 | R29: 00. Awal
B30: 28 | C30: Nasabah | D30: =VLOOKUP(E30,[1]Mei!$E$6:$F$173,2,0) -> #N/A | E30: Roni Sambuaga | F30: Purna Bakti 2025 | G30: 45919 | I30: Nasabah | J30: Nasabah
B31: 29 | C31: Nasabah | D31: =VLOOKUP(E31,[1]Mei!$E$6:$F$173,2,0) -> #N/A | E31: Agus Tomi - Nasabah | F31: Purna Bakti 2025 | G31: 45895 | I31: Nasabah | J31: Nasabah | K31: Kapuk
B32: 30 | C32: 00541 | D32: =VLOOKUP(E32,[1]Mei!$E$6:$F$173,2,0) -> 00541 | E32: Hendra | F32: Aktif | H32: Cakung | I32: 00541 | J32: =IF(LEFT(I32,2)="00","Tetap","Dilayani") -> Tetap | K32: Divisi Pemasaran | L32: 100000 | M32: 150000 | O32: 20000 | R32: 00. Awal
B33: 31 | C33: 00537 | D33: =VLOOKUP(E33,[1]Mei!$E$6:$F$173,2,0) -> 00537 | E33: Heni Triandini | F33: Aktif | H33: Cakung | I33: 00537 | J33: =IF(LEFT(I33,2)="00","Tetap","Dilayani") -> Tetap | K33: Bidang Keuangan | L33: 100000 | M33: 100000 | N33: 0 | O33: 20000 | R33: 00. Awal
B34: 32 | C34: 00322 | D34: =VLOOKUP(E34,[1]Mei!$E$6:$F$173,2,0) -> 00322 | E34: Heru Purboyo | F34: Aktif | H34: Cakung | I34: 00322 | J34: =IF(LEFT(I34,2)="00","Tetap","Dilayani") -> Tetap | K34: RPH Pulogadung | L34: 100000 | M34: 20000 | N34: 200 | O34: 5000 | R34: 00. Awal
B35: 33 | C35: 00547 | D35: =VLOOKUP(E35,[1]Mei!$E$6:$F$173,2,0) -> 00547 | E35: Heru Sri Margono | F35: Aktif | H35: Cakung | I35: 00547 | J35: =IF(LEFT(I35,2)="00","Tetap","Dilayani") -> Tetap | K35: Bidang Keuangan | L35: 100000 | M35: 100000 | O35: 20000 | R35: 00. Awal
B36: 34 | C36: 00554 | D36: =VLOOKUP(E36,[1]Mei!$E$6:$F$173,2,0) -> 00554 | E36: Indra Suwanda | F36: Aktif | H36: Cakung | I36: 00554 | J36: =IF(LEFT(I36,2)="00","Tetap","Dilayani") -> Tetap | K36: Divisi Produksi | L36: 100000 | M36: 100000 | O36: 20000 | Q36: =O36+P36 -> 20000 | R36: 00. Awal
B37: 35 | C37: 00355 | D37: =VLOOKUP(E37,[1]Mei!$E$6:$F$173,2,0) -> #N/A | E37: Abdul Ghofir | F37: Purna Bakti 2021 | H37: Cakung | I37: 00355 | J37: =IF(LEFT(I37,2)="00","Tetap","Dilayani") -> Tetap | K37: Divisi Produksi | L37: =25000+25000+50000 -> 100000 | M37: =25000+25000+100000 -> 150000 | N37: 200 | O37: 5000 | Q37: 5000 | R37: 00. Awal
B38: 36 | C38: 00363 | D38: =VLOOKUP(E38,[1]Mei!$E$6:$F$173,2,0) -> 00363 | E38: Ir. Djoko Maryono | F38: Aktif | H38: Cakung | I38: 00363 | J38: =IF(LEFT(I38,2)="00","Tetap","Dilayani") -> Tetap | K38: RPH Cakung | L38: 150000 | M38: 10000 | N38: 200 | O38: 5000 | R38: 00. Awal
B39: 37 | C39: 00396 | D39: =VLOOKUP(E39,[1]Mei!$E$6:$F$173,2,0) -> 00396 | E39: Ir. Okto Hendri Fahlefi | F39: Aktif | H39: Cakung | I39: 00396 | J39: =IF(LEFT(I39,2)="00","Tetap","Dilayani") -> Tetap | K39: Divisi Pemasaran | L39: 150000 | M39: 200000 | N39: 200 | O39: 5000 | R39: 00. Awal
B40: 38 | C40: 00387 | D40: =VLOOKUP(E40,[1]Mei!$E$6:$F$173,2,0) -> 00387 | E40: Ismail | F40: Aktif | H40: Cakung | I40: 00387 | J40: =IF(LEFT(I40,2)="00","Tetap","Dilayani") -> Tetap | K40: Divisi Pemasaran | L40: 100000 | M40: 10000 | N40: 200 | O40: 5000 | R40: 00. Awal
B41: 39 | C41: 00508 | D41: =VLOOKUP(E41,[1]Mei!$E$6:$F$173,2,0) -> 00508 | E41: Iwan Setiawan | F41: Aktif | H41: Cakung | I41: 00508 | J41: =IF(LEFT(I41,2)="00","Tetap","Dilayani") -> Tetap | K41: Divisi Produksi | L41: 100000 | M41: 50000 | N41: 200 | O41: 5000 | R41: 00. Awal
...

Sheet Pivo Simpanan
A1: Status | B1: (Multiple Items)
A3: NPP | B3: N A M A | C3: Bulan | D3: Kategori | E3: Keterangan | F3: Sum of SHU | G3: Sum of Khusus | H3: Sum of SIMPANAN WAJIB | I3: Sum of SIMPANAN MANASUKA | J3: Simpanan + Manasuka | K3: Total
A4: PHL | B4: Siswanto | C4: 00. Saldo Akhir 2025 | F4: 7510261 | G4: 0 | H4: 15436622 | I4: 1360000 | J4: 16796622 | K4: 24306883
C5: 01. Jan 2026 | D5: Setoran Simpanan | E5: 46045 | F5: 0 | G5: 0 | H5: 0 | I5: 0 | J5: 0 | K5: 0
C6: 02. Feb 2026 | D6: Setoran Simpanan | E6: 46078 | F6: 0 | G6: 0 | H6: 100000 | I6: 10000 | J6: 110000 | K6: 110000
C7: 03. Mar 2026 | D7: Setoran Simpanan | E7: 46106 | F7: 0 | G7: 0 | H7: 100000 | I7: 10000 | J7: 110000 | K7: 110000
C8: 04. Apr 2026 | D8: Setoran Simpanan | E8: 46136 | F8: 0 | G8: 0 | H8: 100000 | I8: 10000 | J8: 110000 | K8: 110000
C9: 05. Mei 2026 | D9: Setoran Simpanan | E9: 46167 | F9: 0 | G9: 0 | H9: 100000 | I9: 10000 | J9: 110000 | K9: 110000
C10: 06. Jun 2026 | D10: Setoran Simpanan | E10: 46198 | F10: 0 | G10: 0 | H10: 100000 | I10: 10000 | J10: 110000 | K10: 110000
C11: 07. Jul 2026 | D11: Setoran Simpanan | E11: 46227 | F11: 0 | G11: 0 | H11: 100000 | I11: 10000 | J11: 110000 | K11: 110000
C12: 08. Agu 2026 | D12: Setoran Simpanan | E12: 46258 | F12: 0 | G12: 0 | H12: 100000 | I12: 10000 | J12: 110000 | K12: 110000
A13: Grand Total | F13: 7510261 | G13: 0 | H13: 16136622 | I13: 1430000 | J13: 17566622 | K13: 25076883
J16: =GETPIVOTDATA("Simpanan + Manasuka",$A$3)*4 -> 70266488

Sheet Detail Simpanan
B1: NO | C1: N A M A | D1: Status | E1: Tanggal Bergabung | F1: Area | G1: NPP | H1: Khusus | I1: SHU | J1: SIMPANAN WAJIB | K1: SIMPANAN MANASUKA | L1: Bulan | M1: Keterangan | N1: Kategori
B2: 1 | C2: A. Rafik | D2: =VLOOKUP(C2,'Master Anggota'!$E$2:$J$678,2,0) -> Aktif | G2: =VLOOKUP(C2,'Master Anggota'!$E$2:$J$678,5,0) -> 01776 | H2: 0 | I2: 0 | J2: 800000 | K2: 1600000 | L2: 00. Saldo Akhir 2025 | M2: Saldo Awal | N2: Saldo Awal
B3: 2 | C3: Aan Supriyatin | D3: =VLOOKUP(C3,'Master Anggota'!$E$2:$J$678,2,0) -> Aktif | G3: =VLOOKUP(C3,'Master Anggota'!$E$2:$J$678,5,0) -> 01739 | H3: 0 | I3: 0 | J3: 1000000 | K3: 1800000 | L3: 00. Saldo Akhir 2025 | M3: Saldo Awal | N3: Saldo Awal
B4: 3 | C4: Abdul Cahyo Nugroho | D4: =VLOOKUP(C4,'Master Anggota'!$E$2:$J$678,2,0) -> Aktif | G4: =VLOOKUP(C4,'Master Anggota'!$E$2:$J$678,5,0) -> 00553 | H4: 0 | I4: 3694115 | J4: 10278197 | K4: 831668 | L4: 00. Saldo Akhir 2025 | M4: Saldo Awal | N4: Saldo Awal
B5: 4 | C5: Achmad Ikang Zulkarnain | D5: =VLOOKUP(C5,'Master Anggota'!$E$2:$J$678,2,0) -> Aktif | G5: =VLOOKUP(C5,'Master Anggota'!$E$2:$J$678,5,0) -> PHL Distribusi | H5: 0 | I5: 0 | J5: 600000 | K5: 900000 | L5: 00. Saldo Akhir 2025 | M5: Saldo Awal | N5: Saldo Awal
B6: 5 | C6: Adam Bakhtiar | D6: =VLOOKUP(C6,'Master Anggota'!$E$2:$J$678,2,0) -> Aktif | G6: =VLOOKUP(C6,'Master Anggota'!$E$2:$J$678,5,0) -> PHL Produksi | H6: 0 | I6: 0 | J6: 200000 | K6: 100000 | L6: 00. Saldo Akhir 2025 | M6: Saldo Awal | N6: Saldo Awal
B7: 6 | C7: Ade Kurnia | D7: =VLOOKUP(C7,'Master Anggota'!$E$2:$J$678,2,0) -> Aktif | G7: =VLOOKUP(C7,'Master Anggota'!$E$2:$J$678,5,0) -> 01651 | H7: 0 | I7: 413679 | J7: 2200000 | K7: 1100000 | L7: 00. Saldo Akhir 2025 | M7: Saldo Awal | N7: Saldo Awal
B8: 7 | C8: Ady Sucipto | D8: =VLOOKUP(C8,'Master Anggota'!$E$2:$J$678,2,0) -> Aktif | G8: =VLOOKUP(C8,'Master Anggota'!$E$2:$J$678,5,0) -> 00616 | H8: 0 | I8: 0 | J8: 1100000 | K8: 2800000 | L8: 00. Saldo Akhir 2025 | M8: Saldo Awal | N8: Saldo Awal
B9: 8 | C9: Aep Saefudin | D9: =VLOOKUP(C9,'Master Anggota'!$E$2:$J$678,2,0) -> Aktif | G9: =VLOOKUP(C9,'Master Anggota'!$E$2:$J$678,5,0) -> PHL Produksi | H9: 0 | I9: 0 | J9: 200000 | K9: 100000 | L9: 00. Saldo Akhir 2025 | M9: Saldo Awal | N9: Saldo Awal
B10: 9 | C10: Afan Wahyu Syafii | D10: =VLOOKUP(C10,'Master Anggota'!$E$2:$J$678,2,0) -> Aktif | G10: =VLOOKUP(C10,'Master Anggota'!$E$2:$J$678,5,0) -> 00582 | H10: 0 | I10: 1828753 | J10: 6600000 | K10: 5150000 | L10: 00. Saldo Akhir 2025 | M10: Saldo Awal | N10: Saldo Awal
B11: 10 | C11: Agung | D11: =VLOOKUP(C11,'Master Anggota'!$E$2:$J$678,2,0) -> Aktif | G11: =VLOOKUP(C11,'Master Anggota'!$E$2:$J$678,5,0) -> PHL Produksi | H11: 0 | I11: 0 | J11: 200000 | K11: 100000 | L11: 00. Saldo Akhir 2025 | M11: Saldo Awal | N11: Saldo Awal
B12: 11 | C12: Agung Pambudi | D12: =VLOOKUP(C12,'Master Anggota'!$E$2:$J$678,2,0) -> Aktif | G12: =VLOOKUP(C12,'Master Anggota'!$E$2:$J$678,5,0) -> 00535 | H12: 0 | I12: 4501436 | J12: 11232731 | K12: 3260000 | L12: 00. Saldo Akhir 2025 | M12: Saldo Awal | N12: Saldo Awal
B13: 12 | C13: Agus Tomi | D13: =VLOOKUP(C13,'Master Anggota'!$E$2:$J$678,2,0) -> Aktif | G13: =VLOOKUP(C13,'Master Anggota'!$E$2:$J$678,5,0) -> 01740 | H13: 0 | I13: 0 | J13: 1000000 | K13: 900000 | L13: 00. Saldo Akhir 2025 | M13: Saldo Awal | N13: Saldo Awal
... B203: 202 | C203: Marwanto | D203: =VLOOKUP(C203,'Master Anggota'!$E$2:$J$678,2,0) -> PHL | G203: =VLOOKUP(C203,'Master Anggota'!$E$2:$J$678,5,0) -> 01510 | H203: 0 | I203: 5314988 | J203: 11230749 | K203: 8720000 | L203: 00. Saldo Akhir 2025 | M203: Saldo Awal | N203: Saldo Awal
B204: 203 | C204: Taufiqurrahman | D204: =VLOOKUP(C204,'Master Anggota'!$E$2:$J$678,2,0) -> Aktif | G204: =VLOOKUP(C204,'Master Anggota'!$E$2:$J$678,5,0) -> 00558 | H204: 0 | I204: 0 | J204: 0 | K204: -7500000 | L204: 01. Jan 2026 | M204: 46036 | N204: Pengambilan Manasuka
B205: 204 | C205: Ferika Pujiyanti | D205: =VLOOKUP(C205,'Master Anggota'!$E$2:$J$678,2,0) -> Aktif | G205: =VLOOKUP(C205,'Master Anggota'!$E$2:$J$678,5,0) -> 00496 | H205: 0 | I205: 0 | J205: 0 | K205: -4000000 | L205: 01. Jan 2026 | M205: 46036 | N205: Pengambilan Manasuka
B206: 205 | C206: Fellix Stephen Willa | D206: =VLOOKUP(C206,'Master Anggota'!$E$2:$J$678,2,0) -> Aktif | G206: =VLOOKUP(C206,'Master Anggota'!$E$2:$J$678,5,0) -> 00565 | H206: 0 | I206: 0 | J206: 0 | K206: 0 | L206: 01. Jan 2026 | M206: 46036 | N206: Ditolak Pengajuan Pengambilan Manasukanya
B207: 206 | C207: Septi Priawandra | D207: =VLOOKUP(C207,'Master Anggota'!$E$2:$J$678,2,0) -> Aktif | G207: =VLOOKUP(C207,'Master Anggota'!$E$2:$J$678,5,0) -> 00583 | H207: 0 | I207: 0 | J207: 0 | K207: -1000000 | L207: 01. Jan 2026 | M207: 46045 | N207: Pengambilan Manasuka
B208: 207 | C208: Wawan Satriawan | D208: =VLOOKUP(C208,'Master Anggota'!$E$2:$J$678,2,0) -> Aktif | G208: =VLOOKUP(C208,'Master Anggota'!$E$2:$J$678,5,0) -> 00548 | H208: 0 | I208: 0 | J208: 0 | K208: -1000000 | L208: 01. Jan 2026 | M208: 46045 | N208: Pengambilan Manasuka
B209: 208 | C209: Putu Dharma Santika | D209: =VLOOKUP(C209,'Master Anggota'!$E$2:$J$678,2,0) -> Aktif | G209: =VLOOKUP(C209,'Master Anggota'!$E$2:$J$678,5,0) -> 01560 | H209: 0 | I209: 0 | J209: 0 | K209: -1500000 | L209: 01. Jan 2026 | M209: 46045 | N209: Pengambilan Manasuka
B210: 209 | C210: Suwitno | D210: =VLOOKUP(C210,'Master Anggota'!$E$2:$J$678,2,0) -> Aktif | G210: =VLOOKUP(C210,'Master Anggota'!$E$2:$J$678,5,0) -> 00515 | H210: 0 | I210: 0 | J210: 0 | K210: -3000000 | L210: 01. Jan 2026 | M210: 46056 | N210: Pengambilan Manasuka
B211: 210 | C211: Mumuh Mulyawan | D211: =VLOOKUP(C211,'Master Anggota'!$E$2:$J$678,2,0) -> Aktif | G211: =VLOOKUP(C211,'Master Anggota'!$E$2:$J$678,5,0) -> 00596 | H211: 0 | I211: 0 | J211: 0 | K211: -1500000 | L211: 01. Jan 2026 | M211: 46052 | N211: Pengambilan Manasuka
B212: 211 | C212: Margono - 00281 | D212: =VLOOKUP(C212,'Master Anggota'!$E$2:$J$678,2,0) -> Aktif | G212: =VLOOKUP(C212,'Master Anggota'!$E$2:$J$678,5,0) -> 00281 | H212: 0 | I212: 0 | J212: 100000 | K212: 150000 | L212: 01. Jan 2026 | M212: 46045 | N212: Setoran Simpanan
B213: 212 | C213: Margono QQ Rista - 00281 | D213: =VLOOKUP(C213,'Master Anggota'!$E$2:$J$678,2,0) -> Purna Bakti 2026 | G213: =VLOOKUP(C213,'Master Anggota'!$E$2:$J$678,5,0) -> 00281 | H213: 0 | I213: 0 | J213: 100000 | K213: 150000 | L213: 01. Jan 2026 | M213: 46045 | N213: Setoran Simpanan
B214: 213 | C214: Sri Hartoyo | D214: =VLOOKUP(C214,'Master Anggota'!$E$2:$J$678,2,0) -> Purna Bakti 2026 | G214: =VLOOKUP(C214,'Master Anggota'!$E$2:$J$678,5,0) -> 00288 | H214: 0 | I214: 0 | J214: 100000 | K214: 100000 | L214: 01. Jan 2026 | M214: 46045 | N214: Setoran Simpanan
B215: 214 | C215: Sugiarto | D215: =VLOOKUP(C215,'Master Anggota'!$E$2:$J$678,2,0) -> Aktif | G215: =VLOOKUP(C215,'Master Anggota'!$E$2:$J$678,5,0) -> 00293 | H215: 0 | I215: 0 | J215: 100000 | K215: 100000 | L215: 01. Jan 2026 | M215: 46045 | N215: Setoran Simpanan
... B393: 392 | C393: Tiolenta Martiana | D393: =VLOOKUP(C393,'Master Anggota'!$E$2:$J$678,2,0) -> Aktif | G393: =VLOOKUP(C393,'Master Anggota'!$E$2:$J$678,5,0) -> 00564 | H393: 0 | I393: 0 | J393: 0 | K393: -1500000 | L393: 00. Saldo Akhir 2025 | M393: 46021 | N393: Pengambilan Manasuka
C394: Erina Fitriani | D394: =VLOOKUP(C394,'Master Anggota'!$E$2:$J$678,2,0) -> Aktif | G394: =VLOOKUP(C394,'Master Anggota'!$E$2:$J$678,5,0) -> Koka | H394: 0 | I394: 0 | J394: 100000 | K394: 100000 | L394: 00. Saldo Akhir 2025 | M394: Saldo Awal | N394: Koreksi Saldo Awal
B395: 393 | C395: Erina Fitriani | D395: =VLOOKUP(C395,'Master Anggota'!$E$2:$J$678,2,0) -> Aktif | G395: =VLOOKUP(C395,'Master Anggota'!$E$2:$J$678,5,0) -> Koka | H395: 0 | I395: 0 | J395: 100000 | K395: 100000 | L395: 01. Jan 2026 | M395: 46052 | N395: Setoran Simpanan
B396: 394 | C396: Indra Jaya Nugraha Putra | D396: =VLOOKUP(C396,'Master Anggota'!$E$2:$J$678,2,0) -> Purna Bakti 2026 | G396: =VLOOKUP(C396,'Master Anggota'!$E$2:$J$678,5,0) -> 00571 | H396: 0 | I396: 0 | J396: 0 | K396: -650000 | L396: 01. Jan 2026 | M396: 46055 | N396: Pengambilan Manasuka
B397: 395 | C397: Herda | D397: =VLOOKUP(C397,'Master Anggota'!$E$2:$J$678,2,0) -> Aktif | G397: =VLOOKUP(C397,'Master Anggota'!$E$2:$J$678,5,0) -> 00578 | H397: 0 | I397: 0 | J397: 0 | K397: -3000000 | L397: 02. Feb 2026 | M397: 46064 | N397: Pengambilan Manasuka
B398: 396 | C398: Ari Wibowo - 00579 | D398: =VLOOKUP(C398,'Master Anggota'!$E$2:$J$678,2,0) -> Aktif | G398: =VLOOKUP(C398,'Master Anggota'!$E$2:$J$678,5,0) -> 00579 | H398: 0 | I398: 0 | J398: 0 | K398: -2500000 | L398: 01. Jan 2026 | M398: 46064 | N398: Pengambilan Manasuka
B399: 397 | C399: Margono QQ Rista - 00281 | D399: =VLOOKUP(C399,'Master Anggota'!$E$2:$J$678,2,0) -> Purna Bakti 2026 | G399: =VLOOKUP(C399,'Master Anggota'!$E$2:$J$678,5,0) -> 00281 | H399: 0 | I399: -2995908 | J399: -11498737 | K399: -5225000 | L399: 02. Feb 2026 | M399: 46066 | N399: Pensiun / Keluar Dari Koperasi
B400: 398 | C400: Yadi Supriyadi (Diver) | D400: =VLOOKUP(C400,'Master Anggota'!$E$2:$J$678,2,0) -> Aktif | G400: =VLOOKUP(C400,'Master Anggota'!$E$2:$J$678,5,0) -> PHL | H400: 0 | I400: 0 | J400: 100000 | K400: 200000 | L400: 01. Jan 2026 | M400: 46056 | N400: Setoran Simpanan
B401: 399 | C401: Nowo Susiyanto | D401: =VLOOKUP(C401,'Master Anggota'!$E$2:$J$678,2,0) -> Aktif | G401: =VLOOKUP(C401,'Master Anggota'!$E$2:$J$678,5,0) -> 00311 | H401: 0 | I401: 0 | J401: 0 | K401: -2000000 | L401: 01. Jan 2026 | M401: 46030 | N401: Pengambilan Manasuka
B402: 400 | C402: Muhammad Dzil Ikram Jani | D402: =VLOOKUP(C402,'Master Anggota'!$E$2:$J$678,2,0) -> Aktif | G402: =VLOOKUP(C402,'Master Anggota'!$E$2:$J$678,5,0) -> 00521 | H402: 0 | I402: 0 | J402: 0 | K402: -3600000 | L402: 01. Jan 2026 | M402: 46048 | N402: Pengambilan Manasuka
B403: 401 | C403: Sugiarto | D403: =VLOOKUP(C403,'Master Anggota'!$E$2:$J$678,2,0) -> Aktif | G403: =VLOOKUP(C403,'Master Anggota'!$E$2:$J$678,5,0) -> 00293 | H403: 0 | I403: 0 | J403: 0 | K403: -1000000 | L403: 01. Jan 2026 | M403: 46030 | N403: Pengambilan Manasuka
B404: 402 | C404: Minan Khusnaeni | D404: =VLOOKUP(C404,'Master Anggota'!$E$2:$J$678,2,0) -> Aktif | G404: =VLOOKUP(C404,'Master Anggota'!$E$2:$J$678,5,0) -> 00401 | H404: 0 | I404: 0 | J404: 0 | K404: -6000000 | L404: 01. Jan 2026 | M404: 46030 | N404: Pengambilan Manasuka
B405: 403 | C405: Keren | D405: =VLOOKUP(C405,'Master Anggota'!$E$2:$J$678,2,0) -> Aktif | G405: =VLOOKUP(C405,'Master Anggota'!$E$2:$J$678,5,0) -> 00570 | H405: 0 | I405: 0 | J405: 0 | K405: -3300000 | L405: 01. Jan 2026 | M405: 46024 | N405: Setoran Simpanan
B406: 404 | C406: Ketut Wijaya | D406: =VLOOKUP(C406,'Master Anggota'!$E$2:$J$678,2,0) -> Aktif | G406: =VLOOKUP(C406,'Master Anggota'!$E$2:$J$678,5,0) -> 00514 | H406: 0 | I406: 0 | J406: 0 | K406: -2500000 | L406: 01. Jan 2026 | M406: 46036 | N406: Pengambilan Manasuka
...

Sheet Pivo Pinjaman
A2: Npp | B2: (All)
A4: Sum of Nilai | C4: Metod
A5: Nama | B5: Tanggal | C5: 0. Sisa Pinjaman 2025 | D5: 1. Pokok Pinjaman | E5: 2. Jasa Admin | F5: 3. Cicilan | G5: Grand Total
A6: Bayu Adithya Permana | B6: 46022 | C6: 93450000 | G6: 93450000
B7: 46045 | D7: 93000000 | E7: 25400000 | F7: -93450000 | G7: 24950000
B8: 46078 | F8: -5920000 | G8: -5920000
B9: 46106 | F9: -5920000 | G9: -5920000
B10: 46136 | F10: -5920000 | G10: -5920000
B11: 46167 | F11: -5920000 | G11: -5920000
B12: 46198 | F12: -5920000 | G12: -5920000
B13: 46227 | F13: -5920000 | G13: -5920000
B14: 46258 | F14: -5920000 | G14: -5920000
A15: Bayu Adithya Permana Total | C15: 93450000 | D15: 93000000 | E15: 25400000 | F15: -134890000 | G15: 76960000
A17: Grand Total | C17: 93450000 | D17: 93000000 | E17: 25400000 | F17: -134890000 | G17: 76960000

Sheet Detail Pinjaman
A3: No | B3: Nama | C3: Npp | D3: Tanggal | E3: Nilai | F3: Metod | G3: D | H3: K | I3: Mulai | J3: Terakhir | K3: Cicilan
A4: 1 | B4: Abdul Cahyo Nugroho | C4: =VLOOKUP(B4,'Master Anggota'!$E$2:$I$279,5,0) -> 00553 | D4: 46022 | E4: 6600000 | F4: 0. Sisa Pinjaman 2025 | H4: Dipotong mulai jan 2026 sebanyak 10x | I4: 46047 | J4: 46320 | K4: 660000
A5: 2 | B5: Ade Kurnia | C5: =VLOOKUP(B5,'Master Anggota'!$E$2:$I$279,5,0) -> 01651 | D5: 46022 | E5: 880000 | F5: 0. Sisa Pinjaman 2025
A6: 3 | B6: Agung Pambudi | C6: =VLOOKUP(B6,'Master Anggota'!$E$2:$I$279,5,0) -> 00535 | D6: 46022 | E6: 6570667 | F6: 0. Sisa Pinjaman 2025
A7: 4 | B7: Agus Tomi | C7: =VLOOKUP(B7,'Master Anggota'!$E$2:$I$279,5,0) -> 01740 | D7: 46022 | E7: 0 | F7: 0. Sisa Pinjaman 2025
A8: 5 | B8: Agus Tomi - Nasabah | C8: =VLOOKUP(B8,'Master Anggota'!$E$2:$I$279,5,0) -> Nasabah | D8: 46022 | E8: 1862000 | F8: 0. Sisa Pinjaman 2025
A9: 6 | B9: Ahmad Fauzi - 01743 | C9: =VLOOKUP(B9,'Master Anggota'!$E$2:$I$279,5,0) -> 01743 | D9: 46022 | E9: 0 | F9: 0. Sisa Pinjaman 2025
A10: 7 | B10: Ahmad Jamaludin | C10: =VLOOKUP(B10,'Master Anggota'!$E$2:$I$279,5,0) -> 00369 | D10: 46022 | E10: 12687500 | F10: 0. Sisa Pinjaman 2025
A11: 8 | B11: Ahmat Saifudin | C11: =VLOOKUP(B11,'Master Anggota'!$E$2:$I$279,5,0) -> 01665 | D11: 46022 | E11: 917140 | F11: 0. Sisa Pinjaman 2025
A12: 9 | B12: Alfian Noor | C12: =VLOOKUP(B12,'Master Anggota'!$E$2:$I$279,5,0) -> 00552 | D12: 46022 | E12: 105800000 | F12: 0. Sisa Pinjaman 2025
A13: 10 | B13: Allan Louby Van Houten | C13: =VLOOKUP(B13,'Master Anggota'!$E$2:$I$279,5,0) -> 00607 | D13: 46022 | E13: =15010000-1060000 -> 13950000 | F13: 0. Sisa Pinjaman 2025
A14: 11 | B14: Amir Suroto | C14: =VLOOKUP(B14,'Master Anggota'!$E$2:$I$279,5,0) -> 01302 | D14: 46022 | E14: 19800000 | F14: 0. Sisa Pinjaman 2025
A15: 12 | B15: Amrun Maruf Effendi | C15: =VLOOKUP(B15,'Master Anggota'!$E$2:$I$279,5,0) -> 00315 | D15: 46022 | E15: 0 | F15: 0. Sisa Pinjaman 2025
A16: 13 | B16: Andri Kurniawan | C16: =VLOOKUP(B16,'Master Anggota'!$E$2:$I$279,5,0) -> 00576 | D16: 46022 | E16: 33450002 | F16: 0. Sisa Pinjaman 2025
A17: 14 | B17: Andrian Fadly | C17: =VLOOKUP(B17,'Master Anggota'!$E$2:$I$279,5,0) -> 00546 | D17: 46022 | E17: 29925000 | F17: 0. Sisa Pinjaman 2025
A18: 15 | B18: Anton Efendi | C18: =VLOOKUP(B18,'Master Anggota'!$E$2:$I$279,5,0) -> 00614 | D18: 46022 | E18: 14466668 | F18: 0. Sisa Pinjaman 2025
A19: 16 | B19: Ardiansyah | C19: =VLOOKUP(B19,'Master Anggota'!$E$2:$I$279,5,0) -> 00345 | D19: 46022 | E19: 88666664 | F19: 0. Sisa Pinjaman 2025
A20: 17 | B20: Ari Wibowo - 00533 | C20: =VLOOKUP(B20,'Master Anggota'!$E$2:$I$279,5,0) -> 00533 | D20: 46022 | E20: 62225000 | F20: 0. Sisa Pinjaman 2025
A21: 18 | B21: ari Wibowo - 00579 | C21: =VLOOKUP(B21,'Master Anggota'!$E$2:$I$279,5,0) -> 00579 | D21: 46022 | E21: 7665000 | F21: 0. Sisa Pinjaman 2025
A22: 19 | B22: Arief Indrawan | C22: =VLOOKUP(B22,'Master Anggota'!$E$2:$I$279,5,0) -> 00577 | D22: 46022 | E22: 37376667 | F22: 0. Sisa Pinjaman 2025
A23: 20 | B23: Arsim | C23: =VLOOKUP(B23,'Master Anggota'!$E$2:$I$279,5,0) -> 00566 | D23: 46022 | E23: 0 | F23: 0. Sisa Pinjaman 2025
A24: 21 | B24: Asta | C24: =VLOOKUP(B24,'Master Anggota'!$E$2:$I$279,5,0) -> 01720 | D24: 46022 | E24: =4420000+360000 -> 4780000 | F24: 0. Sisa Pinjaman 2025
A25: 22 | B25: Bayu Adithya Permana | C25: =VLOOKUP(B25,'Master Anggota'!$E$2:$I$279,5,0) -> 00498 | D25: 46022 | E25: 93450000 | F25: 0. Sisa Pinjaman 2025
A26: 23 | B26: Clarissa Dini | C26: =VLOOKUP(B26,'Master Anggota'!$E$2:$I$279,5,0) -> 00610 | D26: 46022 | E26: 0 | F26: 0. Sisa Pinjaman 2025
A27: 24 | B27: Dadi Muhamad Mulyadi | C27: =VLOOKUP(B27,'Master Anggota'!$E$2:$I$279,5,0) -> 00325 | D27: 46022 | E27: 0 | F27: 0. Sisa Pinjaman 2025
A28: 25 | B28: Darsim | C28: =VLOOKUP(B28,'Master Anggota'!$E$2:$I$279,5,0) -> PHL | D28: 46022 | E28: 9800000 | F28: 0. Sisa Pinjaman 2025
A29: 26 | B29: Dedy Kurniawan | C29: =VLOOKUP(B29,'Master Anggota'!$E$2:$I$279,5,0) -> 00540 | D29: 46022 | E29: 9300000 | F29: 0. Sisa Pinjaman 2025
A30: 27 | B30: Deri Hendriawan | C30: =VLOOKUP(B30,'Master Anggota'!$E$2:$I$279,5,0) -> 01532 | D30: 46022 | E30: 0 | F30: 0. Sisa Pinjaman 2025
A31: 28 | B31: Didi Rahmat | C31: =VLOOKUP(B31,'Master Anggota'!$E$2:$I$279,5,0) -> 00591 | D31: 46022 | E31: 31591669 | F31: 0. Sisa Pinjaman 2025
A32: 29 | B32: Didi Tarmudi | C32: =VLOOKUP(B32,'Master Anggota'!$E$2:$I$279,5,0) -> 00380 | D32: 46022 | E32: 0 | F32: 0. Sisa Pinjaman 2025
A33: 30 | B33: Eddy Sukaryan | C33: =VLOOKUP(B33,'Master Anggota'!$E$2:$I$279,5,0) -> 00327 | D33: 46022 | E33: 129816758 | F33: 0. Sisa Pinjaman 2025
A34: 31 | B34: Eka Yanuar Santosa | C34: =VLOOKUP(B34,'Master Anggota'!$E$2:$I$279,5,0) -> 00490 | D34: 46022 | E34: 11000000 | F34: 0. Sisa Pinjaman 2025
A35: 32 | B35: Eko Junaidi | C35: =VLOOKUP(B35,'Master Anggota'!$E$2:$I$279,5,0) -> 00520 | D35: 46022 | E35: 16500000 | F35: 0. Sisa Pinjaman 2025
A36: 33 | B36: Erfan Faulana | C36: =VLOOKUP(B36,'Master Anggota'!$E$2:$I$279,5,0) -> 01730 | D36: 46022 | E36: 1890000 | F36: 0. Sisa Pinjaman 2025
... A52: 49 | B52: Heru Sri Margono | C52: =VLOOKUP(B52,'Master Anggota'!$E$2:$I$279,5,0) -> 00547 | D52: 46022 | E52: 54471667 | F52: 0. Sisa Pinjaman 2025
A53: 50 | B53: Hesby Aga Ardila Nugroho | C53: =VLOOKUP(B53,'Master Anggota'!$E$2:$I$279,5,0) -> 01561 | D53: 46022 | E53: =7350001-200001 -> 7150000 | F53: 0. Sisa Pinjaman 2025
A54: 51 | B54: I Gede mustika | C54: =VLOOKUP(B54,'Master Anggota'!$E$2:$I$279,5,0) -> 00525 | D54: 46022 | E54: 76628333 | F54: 0. Sisa Pinjaman 2025
A55: 52 | B55: I Made Mustada | C55: =VLOOKUP(B55,'Master Anggota'!$E$2:$I$279,5,0) -> 00328 | D55: 46022 | E55: 13650000 | F55: 0. Sisa Pinjaman 2025
A56: 53 | B56: Idris Rusmianto | C56: =VLOOKUP(B56,'Master Anggota'!$E$2:$I$279,5,0) -> 00529 | D56: 46022 | E56: 12146672 | F56: 0. Sisa Pinjaman 2025
A57: 54 | B57: Indra Jaya Nugraha Putra | C57: =VLOOKUP(B57,'Master Anggota'!$E$2:$I$279,5,0) -> 00571 | D57: 46022 | E57: 0 | F57: 0. Sisa Pinjaman 2025
...

Sheet Data Base Pinjaman
B2: No | C2: Nama | D2: Npp | E2: Pokok | F2: Admin | G2: Mulai dipotong | H2: Terakhir dipotong | I2: lama Cicilan | J2: Cicilan
B3: 1 | C3: Ade Kurnia | D3: =VLOOKUP(C3,'Master Anggota'!$E$2:$I$279,5,0) -> 01651 | E3: 3000000 | F3: 300000 | G3: 46078 | H3: 46351 | I3: 10 | J3: Lunas
B4: 2 | C4: Bayu Adithya Permana | D4: =VLOOKUP(C4,'Master Anggota'!$E$2:$I$279,5,0) -> 00498 | E4: 93000000 | F4: 25400000 | G4: 46078 | H4: 46655 | I4: 20 | J4: 5920000
B5: 3 | C5: Ramli | D5: =VLOOKUP(C5,'Master Anggota'!$E$2:$I$279,5,0) -> 00526 | E5: 50000000 | F5: 15000000 | G5: 46106 | H5: 46808 | I5: 24 | J5: 2708333
B6: 4 | C6: Dedy Kurniawan | D6: =VLOOKUP(C6,'Master Anggota'!$E$2:$I$279,5,0) -> 00540 | E6: 15000000 | F6: 3600000 | G6: 46078 | H6: 46777 | I6: 24 | J6: 775000
B7: 5 | C7: Ngadiono | D7: =VLOOKUP(C7,'Master Anggota'!$E$2:$I$279,5,0) -> 01544 | E7: 13000000 | F7: 1300000 | G7: 46078 | H7: Lunas | I7: 10 | J7: 1430000
B8: 6 | C8: ALVIN AVRIALDY | D8: =VLOOKUP(C8,'Master Anggota'!$E$2:$I$279,5,0) -> PHL | E8: 3000000 | F8: 300000 | G8: 46078 | H8: 46351 | I8: 10 | J8: 330000
B9: 7 | C9: Ir. Djoko Maryono | D9: =VLOOKUP(C9,'Master Anggota'!$E$2:$I$279,5,0) -> 00363 | E9: 15000000 | F9: 1350000 | G9: Saat Pensiun | H9: Saat Pensiun | I9: 1 | J9: 16350000
B10: 8 | C10: Erfan Faulana | D10: =VLOOKUP(C10,'Master Anggota'!$E$2:$I$279,5,0) -> 01730 | E10: 4000000 | F10: 240000 | G10: 46078 | H10: 46228 | I10: 6 | J10: Lunas
B11: 9 | C11: Hermansyah | D11: =VLOOKUP(C11,'Master Anggota'!$E$2:$I$279,5,0) -> 01719 | E11: 3500000 | F11: 175000 | G11: 46078 | H11: 46198 | I11: 5 | J11: Lunas
B12: 10 | C12: Ahmat Saifudin | D12: =VLOOKUP(C12,'Master Anggota'!$E$2:$I$279,5,0) -> 01665 | E12: 3500000 | F12: 210000 | G12: 46106 | H12: 46259 | I12: 6 | J12: 618333
B13: 11 | C13: Nyoman Artawan | D13: =VLOOKUP(C13,'Master Anggota'!$E$2:$I$279,5,0) -> 00523 | E13: 25000000 | F13: 3000000 | G13: 46106 | H13: 46443 | I13: 12 | J13: 2333333
B14: 12 | C14: Sudari | D14: =VLOOKUP(C14,'Master Anggota'!$E$2:$I$279,5,0) -> 01602 | E14: 5000000 | F14: 300000 | G14: 46106 | H14: Lunas | I14: 6 | J14: 883333
B15: 13 | C15: Ahmad Fauzi - 01743 | D15: =VLOOKUP(C15,'Master Anggota'!$E$2:$I$279,5,0) -> 01743 | E15: 700000 | F15: 14000 | G15: 46106 | H15: 46137 | I15: 2 | J15: 357000
B16: 14 | C16: ROBERT LAKBURLAWAI | D16: =VLOOKUP(C16,'Master Anggota'!$E$2:$I$279,5,0) -> PHL | E16: 5100000 | F16: 306000 | G16: 46106 | H16: 46259 | I16: 6 | J16: 901000
B17: 15 | C17: Muhammad Ade Faizal | D17: =VLOOKUP(C17,'Master Anggota'!$E$2:$I$279,5,0) -> 01703 | E17: 3000000 | F17: 180000 | G17: 46106 | H17: 46259 | I17: 6 | J17: 530000
B18: 16 | C18: Ferry Firmanto | D18: =VLOOKUP(C18,'Master Anggota'!$E$2:$I$279,5,0) -> 00563 | E18: 50000000 | F18: 15000000 | G18: 46106 | H18: 46808 | I18: 24 | J18: 2708333
B19: 17 | C19: Sri Wahyuningsih | D19: =VLOOKUP(C19,'Master Anggota'!$E$2:$I$279,5,0) -> 00633 | E19: 25000000 | F19: 3750000 | G19: 46106 | H19: 46532 | I19: 15 | J19: 1916667
B20: 18 | C20: Abdul Cahyo Nugroho | D20: =VLOOKUP(C20,'Master Anggota'!$E$2:$I$279,5,0) -> 00553 | G20: 46047 | H20: 46290 | I20: 10 | J20: 660000
B21: 19 | C21: Agung Pambudi | D21: =VLOOKUP(C21,'Master Anggota'!$E$2:$I$279,5,0) -> 00535 | G21: 46016 | H21: 46351 | J21: 597333
B22: 20 | C22: Agus Tomi - Nasabah | D22: =VLOOKUP(C22,'Master Anggota'!$E$2:$I$279,5,0) -> Nasabah | G22: 45863 | H22: 46198 | J22: 189000
B23: 21 | C23: Ahmad Jamaludin | D23: =VLOOKUP(C23,'Master Anggota'!$E$2:$I$279,5,0) -> 00369 | G23: 45772 | H23: 46228 | J23: 1812500
B24: 22 | C24: Alfian Noor | D24: =VLOOKUP(C24,'Master Anggota'!$E$2:$I$279,5,0) -> 00552 | G24: 46047 | H24: 46746 | J24: 4408333
B25: 23 | C25: Allan Louby Van Houten | D25: =VLOOKUP(C25,'Master Anggota'!$E$2:$I$279,5,0) -> 00607 | G25: 45833 | H25: Lunas | J25: 775000
B26: 24 | C26: Amir Suroto | D26: =VLOOKUP(C26,'Master Anggota'!$E$2:$I$279,5,0) -> 01302 | G26: 46016 | H26: 46290 | J26: 2200000
B27: 25 | C27: Andri Kurniawan | D27: =VLOOKUP(C27,'Master Anggota'!$E$2:$I$279,5,0) -> 00576 | G27: 45894 | H27: 46593 | J27: 1858333
B28: 26 | C28: Andrian Fadly | D28: =VLOOKUP(C28,'Master Anggota'!$E$2:$I$279,5,0) -> 00546 | G28: 45894 | H28: 46593 | J28: 1575000
B29: 27 | C29: Anton Efendi | D29: =VLOOKUP(C29,'Master Anggota'!$E$2:$I$279,5,0) -> 00614 | G29: 45925 | H29: Lunas | J29: 723333
B30: 28 | C30: Ari Wibowo - 00533 | D30: =VLOOKUP(C30,'Master Anggota'!$E$2:$I$279,5,0) -> 00533 | G30: 45894 | H30: 46593 | J30: 3275000
B31: 29 | C31: ari Wibowo - 00579 | D31: =VLOOKUP(C31,'Master Anggota'!$E$2:$I$279,5,0) -> 00579 | G31: 45894 | H31: 46320 | J31: 767000
B32: 30 | C32: Arief Indrawan | D32: =VLOOKUP(C32,'Master Anggota'!$E$2:$I$279,5,0) -> 00577 | G32: 45955 | H32: 46655 | J32: 1603333
B33: 31 | C33: Asta | D33: =VLOOKUP(C33,'Master Anggota'!$E$2:$I$279,5,0) -> 01720 | G33: 45658 | H33: 46137 | J33: 1195000
B34: 32 | C34: Darsim | D34: =VLOOKUP(C34,'Master Anggota'!$E$2:$I$279,5,0) -> PHL | G34: 45894 | H34: Lunas | J34: 0
B35: 33 | C35: Didi Rahmat | D35: =VLOOKUP(C35,'Master Anggota'!$E$2:$I$279,5,0) -> 00591 | G35: 45833 | H35: Lunas | J35: 0
B36: 34 | C36: Eddy Sukaryan | D36: =VLOOKUP(C36,'Master Anggota'!$E$2:$I$279,5,0) -> 00327 | G36: 45833 | H36: 46532 | J36: 3275000
B37: 35 | C37: Eddy Sukaryan | D37: =VLOOKUP(C37,'Master Anggota'!$E$2:$I$279,5,0) -> 00327 | G37: 45955 | H37: 46655 | J37: 3149608
B38: 36 | C38: Eka Yanuar Santosa | D38: =VLOOKUP(C38,'Master Anggota'!$E$2:$I$279,5,0) -> 00490 | G38: 45833 | H38: 46106 | J38: 2750000
B39: 37 | C39: Eko Junaidi | D39: =VLOOKUP(C39,'Master Anggota'!$E$2:$I$279,5,0) -> 00520 | G39: 46047 | H39: 46290 | J39: 1650000
B40: 38 | C40: Fellix Stephen Willa | D40: =VLOOKUP(C40,'Master Anggota'!$E$2:$I$279,5,0) -> 00565 | G40: 46047 | H40: 46624 | J40: 3125000
B41: 39 | C41: Fitriya Hariyani | D41: =VLOOKUP(C41,'Master Anggota'!$E$2:$I$279,5,0) -> Nasabah | G41: 46016 | H41: 46351 | J41: 1866667
...

Sheet Sheet1
A1: No | B1: Nama | C1: Npp | D1: Cicilan
A2: 1 | B2: Bayu Adithya Permana | C2: 00498 | D2: 5920000
A3: 2 | B3: Ramli | C3: 00526 | D3: 2708333
A4: 3 | B4: Dedy Kurniawan | C4: 00540 | D4: 775000
A5: 4 | B5: ALVIN AVRIALDY | C5: PHL | D5: 330000
A6: 5 | B6: Ahmat Saifudin | C6: 01665 | D6: 618333
A7: 6 | B7: Nyoman Artawan | C7: 00523 | D7: 2333333
A8: 7 | B8: Sudari | C8: 01602 | D8: 883333
A9: 8 | B9: ROBERT LAKBURLAWAI | C9: PHL | D9: 901000
A10: 9 | B10: Muhammad Ade Faizal | C10: 01703 | D10: 530000
A11: 10 | B11: Ferry Firmanto | C11: 00563 | D11: 2708333
A12: 11 | B12: Sri Wahyuningsih | C12: 00633 | D12: 1916667
A13: 12 | B13: Abdul Cahyo Nugroho | C13: 00553 | D13: 660000
... A87: 86 | B87: Andung Juanda | C87: 00511 | D87: 1291667
A88: 87 | B88: Sobri | D88: 3841667
A89: 88 | B89: Sumihar H. Tambunan | D89: 280000
A90: 89 | B90: Rudiansyah | D90: 3161667
A91: 90 | B91: Tri Iswahyudi | D91: 1801667
A92: 91 | B92: Rina Oktaviani | D92: 1413333
A93: 92 | B93: Ade Kurnia | D93: 550000
A94: 93 | B94: Hermansyah | D94: 550000
A95: 94 | B95: Erfan Faulana | D95: 660000
A96: 95 | B96: Washadi | D96: 220000
A97: 96 | B97: Wiyan Eko Supriyanto | D97: 1303846
A98: 97 | B98: Gede Arnawa | D98: 1033333
A99: 98 | B99: Ahmad Fauzi - 01743 | D99: 458571
... A104: 103 | B104: Umayah | D104: 3316667
A105: 104 | B105: Jafar Dwiyanto | C105: 01541 | D105: 1650000
A106: 105 | B106: Putu Dharma Santika | C106: 01560 | D106: 165000
A107: 106 | B107: Suwarno | C107: 00509 | D107: 653333
B112: Row Labels | C112: Sum of Cicilan | E112: Row Labels | F112: Sum of Cicilan
B113: A. Rafik | C113: 337500 | E113: A. Rafik | F113: 337500 | G113: =VLOOKUP(E113,[2]Juli!$E$5:$J$176,6,0) -> 337500 | H113: =G113-F113 -> 0
B114: Abdul Cahyo Nugroho | C114: 660000 | E114: Abdul Cahyo Nugroho | F114: 660000 | G114: =VLOOKUP(E114,[2]Juli!$E$5:$J$176,6,0) -> 660000 | H114: =G114-F114 -> 0
B115: Ade Kurnia | C115: 550000 | E115: Ade Kurnia | F115: 550000 | G115: =VLOOKUP(E115,[2]Juli!$E$5:$J$176,6,0) -> 550000 | H115: =G115-F115 -> 0
B116: Agung Pambudi | C116: 597333 | E116: Agung Pambudi | F116: 597333 | G116: =VLOOKUP(E116,[2]Juli!$E$5:$J$176,6,0) -> 597333 | H116: =G116-F116 -> 0
B117: Ahmad Fauzi - 01743 | C117: 458571 | E117: Ahmad Fauzi - 01743 | F117: 458571 | G117: =VLOOKUP(E117,[2]Juli!$E$5:$J$176,6,0) -> 458571 | H117: =G117-F117 -> 0
B118: Ahmad Jamaludin | C118: 1812500 | E118: Ahmad Jamaludin | F118: 1812500 | G118: =VLOOKUP(E118,[2]Juli!$E$5:$J$176,6,0) -> 1812500 | H118: =G118-F118 -> 0
B119: Ahmat Saifudin | C119: 618333 | E119: Ahmat Saifudin | F119: 618333 | G119: =VLOOKUP(E119,[2]Juli!$E$5:$J$176,6,0) -> 618333 | H119: =G119-F119 -> 0
B120: Alfian Noor | C120: 4408333 | E120: Alfian Noor | F120: 4408333 | G120: =VLOOKUP(E120,[2]Juli!$E$5:$J$176,6,0) -> 4408333 | H120: =G120-F120 -> 0
B121: Allan Louby Van Houten | C121: 775000 | E121: Allan Louby Van Houten | F121: 0 | G121: 0 | H121: =G121-F121 -> 0
...

Sheet Sheet2
C2: Nama | D2: Cicilan
C3: Bayu Adithya Permana | D3: 5920000
C4: Ramli | D4: 2708333
C5: Dedy Kurniawan | D5: 775000
C6: ALVIN AVRIALDY | D6: 330000
C7: Ahmat Saifudin | D7: 618333
C8: Nyoman Artawan | D8: 2333333
C9: ROBERT LAKBURLAWAI | D9: 901000
C10: Muhammad Ade Faizal | D10: 530000
C11: Ferry Firmanto | D11: 2708333
C12: Sri Wahyuningsih | D12: 1916667
C13: Abdul Cahyo Nugroho | D13: 660000
C14: Agung Pambudi | D14: 597333
... C115: Sugiyatwoko | D115: 2333334
C119: Row Labels | D119: Sum of Cicilan | F119: Row Labels | G119: Sum of Cicilan
C120: A. Rafik | D120: 337500 | F120: A. Rafik | G120: 337500
C121: Abdul Cahyo Nugroho | D121: 660000 | F121: Abdul Cahyo Nugroho | G121: 660000
C122: Achmad Ikang Zulkarnain | D122: 397000 | F122: Achmad Ikang Zulkarnain | G122: 397000
C123: Ade Kurnia | D123: 550000 | F123: Ade Kurnia | G123: 550000
C124: Agung Pambudi | D124: 597333 | F124: Agung Pambudi | G124: 597333
C125: Ahmad Fauzi - 00549 | D125: 1033333 | F125: Ahmad Fauzi - 00549 | G125: 1033333
C126: Ahmad Fauzi - 01743 | D126: 458571 | F126: Ahmad Fauzi - 01743 | G126: 458571
C127: Ahmat Saifudin | D127: 618333 | F127: Ahmat Saifudin | G127: 618333
C128: Alfian Noor | D128: 4408333 | F128: Alfian Noor | G128: 4408333
C129: ALVIN AVRIALDY | D129: 330000 | F129: ALVIN AVRIALDY | G129: 330000
C130: Amir Suroto | D130: 2200000 | F130: Amir Suroto | G130: 2200000
C131: Andi Yanto | D131: 540000 | F131: Andi Yanto | G131: 540000
... C224: Grand Total | D224: 190907911 | F224: Grand Total | G224: 190907911
