Workbook

Sheet Pinjaman Barang Sekunder
A1: PINJAMAN BARANG SEKUNDER 2026
B2: Barang Pertama
A3: No | B3: Nama | C3: Barang | D3: Jumlah Pinjaman | G3: Tgl. Pinjaman Cair | H3: Lama Angsuran (x) | I3: Cicilan Perbulan | J3: Saldo Angsuran Tahun Lalu | K3: Bulan | W3: Pelunasan | X3: Total Angsuran | Y3: Sisa Angsuran | Z3: Status | AA3: Keterangan
D4: Pokok | E4: Bunga (20%) | F4: Jumlah | K4: Jan | L4: Feb | M4: Mar | N4: Apr | O4: Mei | P4: Jun | Q4: Jul | R4: Ags | S4: Sep | T4: Okt | U4: Nov | V4: Des
A5: 1 | B5: Rudiansyah | C5: HP Samsung | D5: 2650000 | E5: =D5*20% -> 530000 | F5: =D5+E5 -> 3180000 | G5: 45692 | H5: 12 | I5: =F5/H5 -> 265000 | J5: 2385000 | K5: 265000 | L5: 265000 | M5: 265000 | X5: =J5+K5+L5+M5+N5+O5+P5+Q5+R5+S5+T5+U5+V5+W5 -> 3180000 | Y5: =F5-X5 -> 0 | Z5: =IF(X5=0," ",IF(Y5=0,"Lunas","")) -> Lunas
A6: 2 | B6: Dadi Muhamad Mulyadi | C6: HP Samsung | D6: 4500000 | E6: =D6*20% -> 900000 | F6: =D6+E6 -> 5400000 | G6: 45632 | H6: 15 | I6: =F6/H6 -> 360000 | J6: 3960000 | K6: 360000 | L6: 360000 | M6: 360000 | N6: 360000 | X6: =J6+K6+L6+M6+N6+O6+P6+Q6+R6+S6+T6+U6+V6+W6 -> 5400000 | Y6: =F6-X6 -> 0 | Z6: =IF(X6=0," ",IF(Y6=0,"Lunas","")) -> Lunas
A7: 3 | B7: Siswanto/PHL | C7: Infinix Note 50 Pro 8/256Gb | D7: 3000000 | E7: =D7*20% -> 600000 | F7: =D7+E7 -> 3600000 | G7: 45959 | H7: 10 | I7: =F7/H7 -> 360000 | J7: 720000 | K7: 360000 | L7: 360000 | M7: 360000 | W7: 1800000 | X7: =J7+K7+L7+M7+N7+O7+P7+Q7+R7+S7+T7+U7+V7+W7 -> 3600000 | Y7: =F7-X7 -> 0 | Z7: =IF(X7=0," ",IF(Y7=0,"Lunas","")) -> Lunas
A8: 4 | B8: Parsono | C8: Handphone Vivo V50 5G | D8: 6900000 | E8: =D8*20% -> 1380000 | F8: =D8+E8 -> 8280000 | G8: 45831 | H8: 10 | I8: =F8/H8 -> 828000 | J8: 4968000 | K8: 828000 | L8: 828000 | M8: 828000 | N8: 828000 | X8: =J8+K8+L8+M8+N8+O8+P8+Q8+R8+S8+T8+U8+V8+W8 -> 8280000 | Y8: =F8-X8 -> 0 | Z8: =IF(X8=0," ",IF(Y8=0,"Lunas","")) -> Lunas
A9: 5 | B9: Jafar Dwiyanto | C9: HP Samsung Galaxy A26 5G | D9: 3000000 | E9: =D9*20% -> 600000 | F9: =D9+E9 -> 3600000 | G9: 45972 | H9: 10 | I9: =F9/H9 -> 360000 | J9: 360000 | K9: 360000 | L9: 360000 | M9: 360000 | N9: 360000 | O9: =360000+1800000 -> 2160000 | P9: 360000 | Q9: -720000 | X9: =J9+K9+L9+M9+N9+O9+P9+Q9+R9+S9+T9+U9+V9+W9 -> 3600000 | Y9: =F9-X9 -> 0 | Z9: =IF(X9=0," ",IF(Y9=0,"Lunas","")) -> Lunas
A10: 6 | B10: Bayu Adhitya Permana | C10: Laptop Advance | D10: 7500000 | E10: =D10*20% -> 1500000 | F10: =D10+E10 -> 9000000 | G10: 45798 | H10: 10 | I10: =F10/H10 -> 900000 | J10: 5400000 | K10: 900000 | L10: 900000 | M10: 900000 | N10: 900000 | X10: =J10+K10+L10+M10+N10+O10+P10+Q10+R10+S10+T10+U10+V10+W10 -> 9000000 | Y10: =F10-X10 -> 0 | Z10: =IF(X10=0," ",IF(Y10=0,"Lunas","")) -> Lunas
A11: 7 | B11: Eddy Sukaryan | C11: HP Oppo Reno 11 Pro 5g | D11: 7999000 | E11: =D11*20% -> 1599800 | F11: =D11+E11 -> 9598800 | G11: 45854 | H11: 12 | I11: =F11/H11 -> 799900 | J11: 3999500 | K11: 799900 | L11: 799900 | M11: 799900 | N11: 799900 | O11: 799900 | P11: 799900 | Q11: 799900 | X11: =J11+K11+L11+M11+N11+O11+P11+Q11+R11+S11+T11+U11+V11+W11 -> 9598800 | Y11: =F11-X11 -> 0 | Z11: =IF(X11=0," ",IF(Y11=0,"Lunas","")) -> Lunas
A12: 8 | B12: Sunardi - 00376 | C12: Laptop Advan Workplus 12600H | D12: 7000000 | E12: =D12*20% -> 1400000 | F12: =D12+E12 -> 8400000 | G12: 45995 | H12: 10 | I12: =F12/H12 -> 840000 | K12: 840000 | L12: 840000 | M12: 840000 | N12: 840000 | O12: 840000 | P12: 840000 | Q12: 840000 | R12: 840000 | X12: =J12+K12+L12+M12+N12+O12+P12+Q12+R12+S12+T12+U12+V12+W12 -> 6720000 | Y12: =F12-X12 -> 1680000 | Z12: =IF(X12=0," ",IF(Y12=0,"Lunas",""))
A13: 9 | B13: Sobri | C13: HP Samsung A55 8/128Gb | D13: 5049000 | E13: =D13*20% -> 1009800 | F13: =D13+E13 -> 6058800 | G13: 12/19/2025 | H13: 12 | I13: =F13/H13 -> 504900 | K13: 504900 | L13: 504900 | M13: 504900 | N13: 504900 | O13: 504900 | P13: 504900 | Q13: 504900 | R13: 504900 | X13: =J13+K13+L13+M13+N13+O13+P13+Q13+R13+S13+T13+U13+V13+W13 -> 4039200 | Y13: =F13-X13 -> 2019600 | Z13: =IF(X13=0," ",IF(Y13=0,"Lunas",""))
A14: 10 | B14: Sigit Hartanto | C14: Laptop Asus TUF A15 (Ryzen 5) | D14: 9500000 | E14: =D14*20% -> 1900000 | F14: =D14+E14 -> 11400000 | G14: 46064 | H14: 10 | I14: =F14/H14 -> 1140000 | M14: 1140000 | N14: 1140000 | O14: 1140000 | P14: 1140000 | Q14: 1140000 | R14: 1140000 | X14: =J14+K14+L14+M14+N14+O14+P14+Q14+R14+S14+T14+U14+V14+W14 -> 6840000 | Y14: =F14-X14 -> 4560000 | Z14: =IF(X14=0," ",IF(Y14=0,"Lunas",""))
A15: 11 | B15: Parsono | C15: Laptop Advan Workplus 12600H | D15: 7500000 | E15: =D15*20% -> 1500000 | F15: =D15+E15 -> 9000000 | H15: 10 | I15: =F15/H15 -> 900000 | O15: 900000 | P15: 900000 | Q15: 900000 | R15: 900000 | X15: =J15+K15+L15+M15+N15+O15+P15+Q15+R15+S15+T15+U15+V15+W15 -> 3600000 | Y15: =F15-X15 -> 5400000 | Z15: =IF(X15=0," ",IF(Y15=0,"Lunas",""))
A16: 12 | B16: Umayah | C16: Kacamata | D16: 700000 | E16: 0 | F16: =D16+E16 -> 700000 | G16: 46141 | H16: 3 | I16: =F16/H16 -> 233333.33 | P16: 233333 | Q16: 233333 | R16: 233333 | X16: =J16+K16+L16+M16+N16+O16+P16+Q16+R16+S16+T16+U16+V16+W16 -> 699999 | Y16: =F16-X16 -> 1 | Z16: =IF(X16=0," ",IF(Y16=0,"Lunas",""))
A17: 13 | B17: Sumihar H. Tambunan | C17: Kacamata | D17: 750000 | E17: 0 | F17: =D17+E17 -> 750000 | G17: 46141 | H17: 3 | I17: =F17/H17 -> 250000 | P17: 250000 | Q17: 250000 | R17: 250000 | X17: =J17+K17+L17+M17+N17+O17+P17+Q17+R17+S17+T17+U17+V17+W17 -> 750000 | Y17: =F17-X17 -> 0 | Z17: =IF(X17=0," ",IF(Y17=0,"Lunas","")) -> Lunas
A18: 14 | B18: Bayu Adhitya Permana | C18: Laptop HP 14 I3 1115G4 | D18: 5000000 | E18: =D18*20% -> 1000000 | F18: =D18+E18 -> 6000000 | G18: 46188 | H18: 10 | I18: =F18/H18 -> 600000 | Q18: 600000 | R18: 600000 | X18: =J18+K18+L18+M18+N18+O18+P18+Q18+R18+S18+T18+U18+V18+W18 -> 1200000 | Y18: =F18-X18 -> 4800000 | Z18: =IF(X18=0," ",IF(Y18=0,"Lunas",""))
B19: Ismail | C19: Kasbon | D19: 1000000 | E19: =1.5%*D19 -> 15000 | H19: 1 | X19: =J19+K19+L19+M19+N19+O19+P19+Q19+R19+S19+T19+U19+V19+W19 -> 0 | Y19: =F19-X19 -> 0 | Z19: =IF(X19=0," ",IF(Y19=0,"Lunas",""))
B20: Eka Yanuar Santosa | C20: HP Infinix Note 60 Pro 8/256 | D20: 4600000 | E20: =D20*20% -> 920000 | F20: =D20+E20 -> 5520000 | G20: 46233 | H20: 10 | I20: =F20/H20 -> 552000 | S20: 552000 | X20: =J20+K20+L20+M20+N20+O20+P20+Q20+R20+S20+T20+U20+V20+W20 -> 552000 | Y20: =F20-X20 -> 4968000 | Z20: =IF(X20=0," ",IF(Y20=0,"Lunas",""))
B21: Rizki Munardi | C21: Samsung A57 8/128 | D21: 7000000 | E21: =D21*20% -> 1400000 | F21: =D21+E21 -> 8400000 | G21: 46233 | H21: 10 | I21: =F21/H21 -> 840000 | S21: 840000 | X21: =J21+K21+L21+M21+N21+O21+P21+Q21+R21+S21+T21+U21+V21+W21 -> 840000 | Y21: =F21-X21 -> 7560000 | Z21: =IF(X21=0," ",IF(Y21=0,"Lunas",""))
B22: Sunardi - 00376 | C22: Advan Laptop Workplus intel 15 12600H | D22: 6000000 | E22: =D22*20% -> 1200000 | F22: =D22+E22 -> 7200000 | G22: 46245 | H22: 10 | I22: =F22/H22 -> 720000 | S22: 720000 | X22: =J22+K22+L22+M22+N22+O22+P22+Q22+R22+S22+T22+U22+V22+W22 -> 720000 | Y22: =F22-X22 -> 6480000 | Z22: =IF(X22=0," ",IF(Y22=0,"Lunas",""))
B23: Eddy Sukaryan | C23: HP Oppo Reno Series | D23: 7500000 | E23: =D23*20% -> 1500000 | F23: =D23+E23 -> 9000000 | G23: Ditolak
B24: Siswanto/PHL | C24: Lenovo Thinkpad Yoga L390 i5 8/256 | D24: 4050000 | E24: =D24*20% -> 810000 | F24: =D24+E24 -> 4860000
K26: =SUM(K5:K18) -> 5217800 | L26: =SUM(L5:L18) -> 5217800 | M26: =SUM(M5:M18) -> 6357800 | N26: =SUM(N5:N18) -> 5732800 | O26: =SUM(O5:O18) -> 6344800 | P26: =SUM(P5:P18) -> 5028133 | Q26: =SUM(Q5:Q18) -> 4548133 | R26: =SUM(R5:R18) -> 4468233 | ... V26: =SUM(V5:V18) -> 0 | X26: =SUM(X5:X18) -> 66507999 | Y26: =SUM(Y5:Y18) -> 18459601

Sheet Sheet1
B4: No | C4: Nama | D4: Barang | E4: Tanggal | F4: Jumlah Pinjaman
F5: Pokok | G5: Bunga (20%) | H5: Cicilan | I5: Saldo
B6: 1 | C6: Jafar Dwiyanto | D6: HP Samsung Galaxy A26 5G | E6: 45972 | F6: 3000000 | G6: 600000 | I6: =SUM(F6:H6) -> 3600000
E7: 46016 | H7: 360000 | I7: =I6+SUM(F7:G7)-H7 -> 3240000
E8: 46047 | H8: 360000 | I8: =I7+SUM(F8:G8)-H8 -> 2880000
E9: 46078 | H9: 360000 | I9: =I8+SUM(F9:G9)-H9 -> 2520000
E10: 46106 | H10: 360000 | I10: =I9+SUM(F10:G10)-H10 -> 2160000
E11: 46137 | H11: 360000 | I11: =I10+SUM(F11:G11)-H11 -> 1800000
E12: 46161 | H12: 360000 | I12: =I11+SUM(F12:G12)-H12 -> 1440000
E13: 46167 | H13: 1800000 | I13: =I12+SUM(F13:G13)-H13 -> -360000
E14: 46198 | H14: 360000 | I14: =I13+SUM(F14:G14)-H14 -> -720000
I15: =I14+SUM(F15:G15)-H15 -> -720000

Sheet Jaket Touring
A1: PINJAMAN BARANG SEKUNDER 2026
B2: Barang Pertama
A3: No | B3: Nama | C3: Barang | D3: Jumlah Pinjaman | G3: Tgl. Pinjaman Cair | H3: Lama Angsuran (x) | I3: Cicilan Perbulan | J3: Saldo Angsuran Tahun Lalu | K3: Bulan | W3: Pelunasan | X3: Total Angsuran | Y3: Sisa Angsuran | Z3: Status | AA3: Keterangan
D4: Pokok | E4: Bunga (20%) | F4: Jumlah | K4: Jan | L4: Feb | M4: Mar | N4: Apr | O4: Mei | P4: Jun | Q4: Jul | R4: Ags | S4: Sep | T4: Okt | U4: Nov | V4: Des
A5: 1 | B5: Hendra | C5: Jaket Turing DJ | D5: 285000 | E5: =D5*20% -> 57000 | F5: =D5+E5 -> 342000 | H5: 3 | I5: =F5/H5 -> 114000 | S5: 114000 | T5: 114000 | U5: 114000 | X5: =J5+K5+L5+M5+N5+O5+P5+Q5+R5+S5+T5+U5+V5+W5 -> 342000 | Y5: =F5-X5 -> 0 | Z5: =IF(X5=0," ",IF(Y5=0,"Lunas","")) -> Lunas
A6: 2 | B6: Ferry Firmanto | C6: Jaket Turing DJ | D6: 285000 | E6: =D6*20% -> 57000 | F6: =D6+E6 -> 342000 | H6: 3 | I6: =F6/H6 -> 114000 | S6: 114000 | T6: 114000 | U6: 114000 | X6: =J6+K6+L6+M6+N6+O6+P6+Q6+R6+S6+T6+U6+V6+W6 -> 342000 | Y6: =F6-X6 -> 0 | Z6: =IF(X6=0," ",IF(Y6=0,"Lunas","")) -> Lunas
A7: 3 | B7: Umayah | C7: Jaket Turing DJ | D7: 270000 | E7: =D7*20% -> 54000 | F7: =D7+E7 -> 324000 | H7: 3 | I7: =F7/H7 -> 108000 | S7: 108000 | T7: 108000 | U7: 108000 | X7: =J7+K7+L7+M7+N7+O7+P7+Q7+R7+S7+T7+U7+V7+W7 -> 324000 | Y7: =F7-X7 -> 0 | Z7: =IF(X7=0," ",IF(Y7=0,"Lunas","")) -> Lunas
A8: 4 | B8: Rudiansyah | C8: Jaket Turing DJ | D8: 270000 | E8: =D8*20% -> 54000 | F8: =D8+E8 -> 324000 | H8: 3 | I8: =F8/H8 -> 108000 | S8: 108000 | T8: 108000 | U8: 108000 | X8: =J8+K8+L8+M8+N8+O8+P8+Q8+R8+S8+T8+U8+V8+W8 -> 324000 | Y8: =F8-X8 -> 0 | Z8: =IF(X8=0," ",IF(Y8=0,"Lunas","")) -> Lunas
A9: 5 | B9: Sudari | C9: Jaket Turing DJ | D9: 270000 | E9: =D9*20% -> 54000 | F9: =D9+E9 -> 324000 | H9: 3 | I9: =F9/H9 -> 108000 | S9: 108000 | T9: 108000 | U9: 108000 | X9: =J9+K9+L9+M9+N9+O9+P9+Q9+R9+S9+T9+U9+V9+W9 -> 324000 | Y9: =F9-X9 -> 0 | Z9: =IF(X9=0," ",IF(Y9=0,"Lunas","")) -> Lunas
A10: 6 | B10: Eko Junaidi | C10: Jaket Turing DJ | D10: 285000 | E10: =D10*20% -> 57000 | F10: =D10+E10 -> 342000 | H10: 3 | I10: =F10/H10 -> 114000 | S10: 114000 | T10: 114000 | U10: 114000 | X10: =J10+K10+L10+M10+N10+O10+P10+Q10+R10+S10+T10+U10+V10+W10 -> 342000 | Y10: =F10-X10 -> 0 | Z10: =IF(X10=0," ",IF(Y10=0,"Lunas","")) -> Lunas
A11: 7 | B11: Eka Yanuar Santosa | C11: Jaket Turing DJ | D11: 270000 | E11: =D11*20% -> 54000 | F11: =D11+E11 -> 324000 | H11: 3 | I11: =F11/H11 -> 108000 | S11: 108000 | T11: 108000 | U11: 108000 | X11: =J11+K11+L11+M11+N11+O11+P11+Q11+R11+S11+T11+U11+V11+W11 -> 324000 | Y11: =F11-X11 -> 0 | Z11: =IF(X11=0," ",IF(Y11=0,"Lunas","")) -> Lunas
A12: 8 | B12: I Gede Mustika | C12: Jaket Turing DJ | D12: 270000 | E12: =D12*20% -> 54000 | F12: =D12+E12 -> 324000 | H12: 3 | I12: =F12/H12 -> 108000 | S12: 108000 | T12: 108000 | U12: 108000 | X12: =J12+K12+L12+M12+N12+O12+P12+Q12+R12+S12+T12+U12+V12+W12 -> 324000 | Y12: =F12-X12 -> 0 | Z12: =IF(X12=0," ",IF(Y12=0,"Lunas","")) -> Lunas
A13: 9 | B13: Gede Suparta | C13: Jaket Turing DJ | D13: 270000 | E13: =D13*20% -> 54000 | F13: =D13+E13 -> 324000 | H13: 3 | I13: =F13/H13 -> 108000 | S13: 108000 | T13: 108000 | U13: 108000 | X13: =J13+K13+L13+M13+N13+O13+P13+Q13+R13+S13+T13+U13+V13+W13 -> 324000 | Y13: =F13-X13 -> 0 | Z13: =IF(X13=0," ",IF(Y13=0,"Lunas","")) -> Lunas
A14: 10 | B14: Hendra | C14: Jaket Turing DJ | D14: 270000 | E14: =D14*20% -> 54000 | F14: =D14+E14 -> 324000 | H14: 3 | I14: =F14/H14 -> 108000 | S14: 108000 | T14: 108000 | U14: 108000 | X14: =J14+K14+L14+M14+N14+O14+P14+Q14+R14+S14+T14+U14+V14+W14 -> 324000 | Y14: =F14-X14 -> 0 | Z14: =IF(X14=0," ",IF(Y14=0,"Lunas","")) -> Lunas
A15: 11 | E15: =D15*20% -> 0 | F15: =D15+E15 -> 0 | X15: =J15+K15+L15+M15+N15+O15+P15+Q15+R15+S15+T15+U15+V15+W15 -> 0 | Y15: =F15-X15 -> 0 | Z15: =IF(X15=0," ",IF(Y15=0,"Lunas",""))
A16: 12 | E16: 0 | F16: =D16+E16 -> 0 | X16: =J16+K16+L16+M16+N16+O16+P16+Q16+R16+S16+T16+U16+V16+W16 -> 0 | Y16: =F16-X16 -> 0 | Z16: =IF(X16=0," ",IF(Y16=0,"Lunas",""))
A17: 13 | E17: 0 | F17: =D17+E17 -> 0 | X17: =J17+K17+L17+M17+N17+O17+P17+Q17+R17+S17+T17+U17+V17+W17 -> 0 | Y17: =F17-X17 -> 0 | Z17: =IF(X17=0," ",IF(Y17=0,"Lunas",""))
A18: 14 | E18: =D18*20% -> 0 | F18: =D18+E18 -> 0 | X18: =J18+K18+L18+M18+N18+O18+P18+Q18+R18+S18+T18+U18+V18+W18 -> 0 | Y18: =F18-X18 -> 0 | Z18: =IF(X18=0," ",IF(Y18=0,"Lunas",""))
E19: =1.5%*D19 -> 0 | X19: =J19+K19+L19+M19+N19+O19+P19+Q19+R19+S19+T19+U19+V19+W19 -> 0 | Y19: =F19-X19 -> 0 | Z19: =IF(X19=0," ",IF(Y19=0,"Lunas",""))
E20: =D20*20% -> 0 | F20: =D20+E20 -> 0 | X20: =J20+K20+L20+M20+N20+O20+P20+Q20+R20+S20+T20+U20+V20+W20 -> 0 | Y20: =F20-X20 -> 0 | Z20: =IF(X20=0," ",IF(Y20=0,"Lunas",""))
E21: =D21*20% -> 0 | F21: =D21+E21 -> 0 | X21: =J21+K21+L21+M21+N21+O21+P21+Q21+R21+S21+T21+U21+V21+W21 -> 0 | Y21: =F21-X21 -> 0 | Z21: =IF(X21=0," ",IF(Y21=0,"Lunas",""))
E22: =D22*20% -> 0 | F22: =D22+E22 -> 0 | X22: =J22+K22+L22+M22+N22+O22+P22+Q22+R22+S22+T22+U22+V22+W22 -> 0 | Y22: =F22-X22 -> 0 | Z22: =IF(X22=0," ",IF(Y22=0,"Lunas",""))
K26: =SUM(K5:K18) -> 0 | L26: =SUM(L5:L18) -> 0 | M26: =SUM(M5:M18) -> 0 | N26: =SUM(N5:N18) -> 0 | O26: =SUM(O5:O18) -> 0 | P26: =SUM(P5:P18) -> 0 | Q26: =SUM(Q5:Q18) -> 0 | R26: =SUM(R5:R18) -> 0 | ... V26: =SUM(V5:V18) -> 0 | X26: =SUM(X5:X18) -> 3294000 | Y26: =SUM(Y5:Y18) -> 0

Sheet Pinjaman Barang Primer
A4: No | B4: Nama | C4: Barang | D4: Total Pesanan (kg/pcs) | E4: Jumlah Pinjaman | H4: Tgl. Pinjaman Cair | I4: Lama Angsuran (x) | J4: Cicilan Perbulan | K4: Saldo Angsuran Tahun Lalu | L4: Bulan | X4: Total Angsuran | Y4: Sisa Angsuran | Z4: Status
E5: Pokok | F5: Margin Rp. 3000 x /Kg | G5: Jumlah | L5: Jan | M5: Feb | N5: Mar | O5: Apr | P5: Mei | Q5: Jun | R5: Jul | S5: Ags | T5: Sep | U5: Okt | V5: Nov | W5: Des
A6: 1 | F6: =D6*3000 -> 0 | G6: =E6+F6 -> 0 | J6: =G6/I6 -> #DIV/0! | X6: =K6+L6+M6+N6+O6+P6+Q6+R6+S6+T6+U6+V6+W6 -> 0 | Y6: =G6-X6 -> 0 | Z6: =IF(X6=0," ",IF(Y6=0,"Lunas"," "))
A7: 2 | F7: =D7*3000 -> 0 | G7: =E7+F7 -> 0 | J7: =G7/I7 -> #DIV/0! | X7: =K7+L7+M7+N7+O7+P7+Q7+R7+S7+T7+U7+V7+W7 -> 0 | Y7: =G7-X7 -> 0 | Z7: =IF(X7=0," ",IF(Y7=0,"Lunas"," "))

Sheet Pinjaman Barang Primer Harian
A4: No | B4: Nama | C4: Bulan | O4: Total Belanja | P4: Status
C5: Jan | D5: Feb | E5: Mar | F5: Apr | G5: Mei | H5: Jun | I5: Jul | J5: Ags | K5: Sep | L5: Okt | M5: Nov | N5: Des
A6: 1 | B6: Hesby Aga | C6: 640920 | D6: 77595 | E6: 77900 | F6: 269850 | G6: 162750 | J6: =169600+(5%*169600)+ (224000+(5%*224000)) -> 413280 | O6: 353430
A7: 2 | B7: Wawan Satriawan | C7: 60900 | O7: =SUM(C7:N7) -> 60900
A8: 3 | B8: Ismail | C8: 877900 | D8: 776580 | F8: 425250 | G8: 206000 | I8: =(756000+200000)+(5%*956000) -> 1003800 | J8: =(233800+(5%*233800)) -> 245490 | O8: =SUM(C8:N8) -> 3535020
A9: 4 | B9: Ari Wibowo | E9: 462000 | O9: =SUM(C9:N9) -> 462000
A10: 5 | B10: Bayu Adhitya Permana | E10: 887565 | F10: 806400 | O10: =SUM(C10:N10) -> 1693965
A11: 6 | B11: Arsim | E11: 144900 | F11: 103950 | O11: =SUM(C11:N11) -> 248850
A12: 7 | B12: Jamsari | E12: 256200 | O12: =SUM(C12:N12) -> 256200
A13: 8 | O13: =SUM(C13:N13) -> 0
A14: 9 | O14: =SUM(C14:N14) -> 0
A15: 10 | O15: =SUM(C15:N15) -> 0
C16: =SUM(C6:C15) -> 1579720 | D16: =SUM(D6:D15) -> 854175 | E16: =SUM(E6:E15) -> 1828565 | F16: =SUM(F6:F15) -> 1605450 | G16: =SUM(G6:G15) -> 368750 | H16: =SUM(H6:H15) -> 0 | I16: =SUM(I6:I15) -> 1003800 | J16: =SUM(J6:J15) -> 658770 | ... O16: =SUM(O6:O15) -> 6610365

Sheet Pinjaman Daging Event Lebaran
A3: No | B3: Nama | C3: Barang | E3: Total Pesanan (kg/pcs) | F3: Jumlah Pinjaman | I3: Tgl. Pinjaman Cair | J3: Lama Angsuran (x) | K3: Cicilan Perbulan | L3: Saldo Angsuran Tahun Lalu | M3: Bulan | Y3: Total Angsuran | Z3: Sisa Angsuran | AA3: Status
D4: Harga Barang | F4: Pokok | G4: Margin Rp. 6000 x /Kg | H4: Jumlah | M4: Jan | N4: Feb | O4: Mar | P4: Apr | Q4: Mei | R4: Jun | S4: Jul | T4: Ags | U4: Sep | V4: Okt | W4: Nov | X4: Des
A5: 1 | B5: Jafar Dwiyanto | C5: Paha Belakang | D5: 135500 | E5: 3 | F5: =D5*E5 -> 406500 | G5: =E5*6000 -> 18000 | H5: =G5+F5 -> 424500 | J5: 3 | K5: =H5/J5 -> 141500 | P5: 141500 | Q5: 141500 | R5: 141500 | Y5: =L5+M5+N5+O5+P5+Q5+R5+S5+T5+U5+V5+W5+X5 -> 424500 | Z5: =H5-Y5 -> 0 | AA5: =IF(Y5=0," ",IF(Z5=0,"Lunas"," ")) -> Lunas
A6: 2 | B6: Eddy Sukaryan | C6: Paha Belakang | D6: 135500 | E6: 10 | F6: =D6*E6 -> 1355000 | G6: =E6*6000 -> 60000 | H6: =G6+F6 -> 1415000 | J6: 3 | K6: =H6/J6 -> 471666.67 | P6: 471666.67 | Q6: 471666.67 | R6: 471666.67 | Y6: =L6+M6+N6+O6+P6+Q6+R6+S6+T6+U6+V6+W6+X6 -> 1415000 | Z6: =H6-Y6 -> 0 | AA6: =IF(Y6=0," ",IF(Z6=0,"Lunas"," ")) -> Lunas
A7: 3 | B7: Jaimin | C7: Paha Belakang | D7: 135500 | E7: 3 | F7: =D7*E7 -> 406500 | G7: =E7*6000 -> 18000 | H7: =G7+F7 -> 424500 | J7: 3 | K7: =H7/J7 -> 141500 | P7: 141500 | Q7: 141500 | R7: 141500 | Y7: =L7+M7+N7+O7+P7+Q7+R7+S7+T7+U7+V7+W7+X7 -> 424500 | Z7: =H7-Y7 -> 0 | AA7: =IF(Y7=0," ",IF(Z7=0,"Lunas"," ")) -> Lunas
A8: 4 | B8: Suratman | C8: Paha Depan | D8: 128000 | E8: 2 | F8: =D8*E8 -> 256000 | G8: =E8*6000 -> 12000 | H8: =G8+F8 -> 268000 | J8: 3 | K8: =H8/J8 -> 89333.333 | P8: 89333.333 | Q8: 89333.333 | R8: 89333.333 | Y8: =L8+M8+N8+O8+P8+Q8+R8+S8+T8+U8+V8+W8+X8 -> 268000 | Z8: =H8-Y8 -> 0 | AA8: =IF(Y8=0," ",IF(Z8=0,"Lunas"," ")) -> Lunas
A9: 5 | B9: Ramli | C9: Paha Depan | D9: 128000 | E9: 2 | F9: =D9*E9 -> 256000 | G9: =E9*6000 -> 12000 | H9: =G9+F9 -> 268000 | J9: 3 | K9: =H9/J9 -> 89333.333 | P9: 89333.333 | Q9: 89333.333 | R9: 89333.333 | Y9: =L9+M9+N9+O9+P9+Q9+R9+S9+T9+U9+V9+W9+X9 -> 268000 | Z9: =H9-Y9 -> 0 | AA9: =IF(Y9=0," ",IF(Z9=0,"Lunas"," ")) -> Lunas
A10: 6 | B10: I Gede Mustika | C10: Paha Belakang | D10: 135500 | E10: 11 | F10: =D10*E10 -> 1490500 | G10: =E10*6000 -> 66000 | H10: =G10+F10 -> 1556500 | J10: 3 | K10: =H10/J10 -> 518833.33 | P10: 518833.33 | Q10: 518833.33 | R10: 518833.33 | Y10: =L10+M10+N10+O10+P10+Q10+R10+S10+T10+U10+V10+W10+X10 -> 1556500 | Z10: =H10-Y10 -> 0 | AA10: =IF(Y10=0," ",IF(Z10=0,"Lunas"," ")) -> Lunas
A11: 7 | B11: I Made Mustada | C11: Paha Belakang | D11: 135500 | E11: 2 | F11: =D11*E11 -> 271000 | G11: =E11*6000 -> 12000 | H11: =G11+F11 -> 283000 | J11: 3 | K11: =H11/J11 -> 94333.333 | P11: 94333.333 | Q11: 94333.333 | R11: 94333.333 | Y11: =L11+M11+N11+O11+P11+Q11+R11+S11+T11+U11+V11+W11+X11 -> 283000 | Z11: =H11-Y11 -> 0 | AA11: =IF(Y11=0," ",IF(Z11=0,"Lunas"," ")) -> Lunas
A12: 8 | B12: Darsim/PHL | C12: Paha Belakang | D12: 135500 | E12: 4 | F12: =D12*E12 -> 542000 | G12: =E12*6000 -> 24000 | H12: =G12+F12 -> 566000 | J12: 3 | K12: =H12/J12 -> 188666.67 | P12: 188666.67 | Q12: 188666.67 | R12: 188666.67 | Y12: =L12+M12+N12+O12+P12+Q12+R12+S12+T12+U12+V12+W12+X12 -> 566000 | Z12: =H12-Y12 -> 0 | AA12: =IF(Y12=0," ",IF(Z12=0,"Lunas"," ")) -> Lunas
A13: 9 | B13: Sunardi - 00376 | C13: Paha Belakang | D13: 135500 | E13: 5 | F13: =D13*E13 -> 677500 | G13: =E13*6000 -> 30000 | H13: =G13+F13 -> 707500 | J13: 3 | K13: =H13/J13 -> 235833.33 | P13: 235833.33 | Q13: 235833.33 | R13: 235833.33 | Y13: =L13+M13+N13+O13+P13+Q13+R13+S13+T13+U13+V13+W13+X13 -> 707500 | Z13: =H13-Y13 -> 0 | AA13: =IF(Y13=0," ",IF(Z13=0,"Lunas"," ")) -> Lunas
A14: 10 | B14: Sobri | C14: Paha Belakang | D14: 135500 | E14: 2 | F14: =D14*E14 -> 271000 | G14: =E14*6000 -> 12000 | H14: =G14+F14 -> 283000 | J14: 3 | K14: =H14/J14 -> 94333.333 | P14: 94333.333 | Q14: 94333.333 | R14: 94333.333 | Y14: =L14+M14+N14+O14+P14+Q14+R14+S14+T14+U14+V14+W14+X14 -> 283000 | Z14: =H14-Y14 -> 0 | AA14: =IF(Y14=0," ",IF(Z14=0,"Lunas"," ")) -> Lunas
A15: 11 | B15: Sigit Hartanto | C15: Paha Belakang | D15: 135500 | E15: 6 | F15: =D15*E15 -> 813000 | G15: =E15*6000 -> 36000 | H15: =G15+F15 -> 849000 | J15: 3 | K15: =H15/J15 -> 283000 | P15: 283000 | Q15: 283000 | R15: 283000 | Y15: =L15+M15+N15+O15+P15+Q15+R15+S15+T15+U15+V15+W15+X15 -> 849000 | Z15: =H15-Y15 -> 0 | AA15: =IF(Y15=0," ",IF(Z15=0,"Lunas"," ")) -> Lunas
A16: 12 | Y16: =L16+M16+N16+O16+P16+Q16+R16+S16+T16+U16+V16+W16+X16 -> 0 | Z16: =H16-Y16 -> 0 | AA16: =IF(Y16=0," ",IF(Z16=0,"Lunas"," "))
A17: 13 | Y17: =L17+M17+N17+O17+P17+Q17+R17+S17+T17+U17+V17+W17+X17 -> 0 | Z17: =H17-Y17 -> 0 | AA17: =IF(Y17=0," ",IF(Z17=0,"Lunas"," "))
A18: 14 | Y18: =L18+M18+N18+O18+P18+Q18+R18+S18+T18+U18+V18+W18+X18 -> 0 | Z18: =H18-Y18 -> 0 | AA18: =IF(Y18=0," ",IF(Z18=0,"Lunas"," "))
A19: 15 | Y19: =L19+M19+N19+O19+P19+Q19+R19+S19+T19+U19+V19+W19+X19 -> 0 | Z19: =H19-Y19 -> 0 | AA19: =IF(Y19=0," ",IF(Z19=0,"Lunas"," "))
A20: 16 | Y20: =L20+M20+N20+O20+P20+Q20+R20+S20+T20+U20+V20+W20+X20 -> 0 | Z20: =H20-Y20 -> 0 | AA20: =IF(Y20=0," ",IF(Z20=0,"Lunas"," "))
A21: 17 | Y21: =L21+M21+N21+O21+P21+Q21+R21+S21+T21+U21+V21+W21+X21 -> 0 | Z21: =H21-Y21 -> 0 | AA21: =IF(Y21=0," ",IF(Z21=0,"Lunas"," "))
A22: 18 | Y22: =L22+M22+N22+O22+P22+Q22+R22+S22+T22+U22+V22+W22+X22 -> 0 | Z22: =H22-Y22 -> 0 | AA22: =IF(Y22=0," ",IF(Z22=0,"Lunas"," "))
A23: 19 | Y23: =L23+M23+N23+O23+P23+Q23+R23+S23+T23+U23+V23+W23+X23 -> 0 | Z23: =H23-Y23 -> 0 | AA23: =IF(Y23=0," ",IF(Z23=0,"Lunas"," "))
A24: 20 | Y24: =L24+M24+N24+O24+P24+Q24+R24+S24+T24+U24+V24+W24+X24 -> 0 | Z24: =H24-Y24 -> 0 | AA24: =IF(Y24=0," ",IF(Z24=0,"Lunas"," "))
A25: 21 | Y25: =L25+M25+N25+O25+P25+Q25+R25+S25+T25+U25+V25+W25+X25 -> 0 | Z25: =H25-Y25 -> 0 | AA25: =IF(Y25=0," ",IF(Z25=0,"Lunas"," "))
A26: 22 | Y26: =L26+M26+N26+O26+P26+Q26+R26+S26+T26+U26+V26+W26+X26 -> 0 | Z26: =H26-Y26 -> 0 | AA26: =IF(Y26=0," ",IF(Z26=0,"Lunas"," "))
A27: 23 | Y27: =L27+M27+N27+O27+P27+Q27+R27+S27+T27+U27+V27+W27+X27 -> 0 | Z27: =H27-Y27 -> 0 | AA27: =IF(Y27=0," ",IF(Z27=0,"Lunas"," "))
... A33: 29 | Y33: =L33+M33+N33+O33+P33+Q33+R33+S33+T33+U33+V33+W33+X33 -> 0 | Z33: =H33-Y33 -> 0 | AA33: =IF(Y33=0," ",IF(Z33=0,"Lunas"," "))
P34: =SUM(P5:P33) -> 2348333.3 | Q34: =SUM(Q5:Q33) -> 2348333.3

Sheet Voucher Belanja KOKA
A4: No | B4: Nama | C4: Qty | D4: Bulan | P4: Total | Q4: Keterangan
D5: Jan | E5: Feb | F5: Mar | G5: Apr | H5: Mei | I5: Jun | J5: Jul | K5: Ags | L5: Sep | M5: Okt | N5: Nov | O5: Des
A6: 1 | B6: Budi Laksono | C6: 1 | D6: 135000 | E6: 135000 | F6: 135000 | H6: 135000 | P6: =SUM(D6:O6) -> 540000
A7: 2 | B7: Dara Maulida | C7: 1 | D7: 135000 | E7: 135000 | F7: 135000 | H7: 135000 | P7: =SUM(D7:O7) -> 540000
A8: 3 | B8: Dewi Kartini | C8: 1 | D8: 135000 | E8: 135000 | F8: 135000 | H8: 135000 | P8: =SUM(D8:O8) -> 540000
A9: 4 | B9: Ferika Pujiyanti | C9: 1 | D9: 135000 | E9: 135000 | F9: 135000 | H9: 135000 | P9: =SUM(D9:O9) -> 540000
A10: 5 | B10: Heni Triandini | C10: 1 | D10: 135000 | E10: 135000 | F10: 135000 | H10: 135000 | P10: =SUM(D10:O10) -> 540000
A11: 6 | B11: Herda | C11: 1 | D11: 135000 | E11: 135000 | F11: 135000 | H11: 135000 | P11: =SUM(D11:O11) -> 540000
A12: 7 | B12: Margono | C12: 1 | D12: 135000 | E12: 135000 | F12: 135000 | H12: 135000 | P12: =SUM(D12:O12) -> 540000
A13: 8 | B13: Mohammad Rizki | C13: 1 | D13: 135000 | E13: 135000 | F13: 135000 | H13: 135000 | P13: =SUM(D13:O13) -> 540000
A14: 9 | B14: Rico Septa Saputra | C14: 1 | D14: 135000 | E14: 135000 | F14: 135000 | H14: 135000 | P14: =SUM(D14:O14) -> 540000
A15: 10 | B15: Arno Nugroho | C15: 1 | D15: 135000 | E15: 135000 | F15: 135000 | H15: 135000 | P15: =SUM(D15:O15) -> 540000
A16: 11 | B16: Khairun Nisa | C16: 1 | D16: 135000 | E16: 135000 | F16: 135000 | H16: 135000 | P16: =SUM(D16:O16) -> 540000
A17: 12 | B17: Lita Ayu Rosida | C17: 1 | D17: 135000 | E17: 135000 | F17: 135000 | H17: 135000 | P17: =SUM(D17:O17) -> 540000
... A35: 30 | B35: Taufik Hidayat | C35: 1 | D35: 135000 | E35: 135000 | F35: 135000 | H35: 135000 | P35: =SUM(D35:O35) -> 540000
A36: 31 | B36: Rudi Nugroho | C36: 1 | D36: 135000 | E36: 135000 | P36: =SUM(D36:O36) -> 270000 | Q36: Resign
A37: 32 | B37: Rian Alandy | C37: 1 | D37: 135000 | E37: 135000 | F37: 135000 | H37: 135000 | P37: =SUM(D37:O37) -> 540000
A38: 33 | B38: Muhammad Irham | C38: 1 | D38: 135000 | E38: 135000 | F38: 135000 | H38: 135000 | P38: =SUM(D38:O38) -> 540000
A39: 34 | B39: Ahmad Zaid Mahfudi | C39: 1 | D39: 135000 | E39: 135000 | F39: 135000 | H39: 135000 | P39: =SUM(D39:O39) -> 540000
A40: 35 | B40: Abdul Cahyo Nugroho | C40: 1 | D40: 135000 | E40: 135000 | F40: 135000 | H40: 135000 | P40: =SUM(D40:O40) -> 540000
A41: 36 | B41: Arief Indrawan | C41: 1 | D41: 135000 | E41: 135000 | F41: 135000 | H41: 135000 | P41: =SUM(D41:O41) -> 540000
A42: 37 | B42: Arsim | C42: 1 | D42: 135000 | E42: 135000 | F42: 135000 | H42: 135000 | P42: =SUM(D42:O42) -> 540000
A43: 38 | B43: Didi Rahmat | C43: 1 | D43: 135000 | E43: 135000 | F43: 135000 | H43: 135000 | P43: =SUM(D43:O43) -> 540000
A44: 39 | B44: Eka Yanuar Santosa | C44: 1 | D44: 135000 | E44: 135000 | F44: 135000 | H44: 135000 | P44: =SUM(D44:O44) -> 540000
A45: 40 | B45: Heru Sri Margono | C45: 1 | D45: 135000 | E45: 135000 | F45: 135000 | H45: 135000 | P45: =SUM(D45:O45) -> 540000
A46: 41 | B46: Keren | C46: 1 | D46: 135000 | E46: 135000 | F46: 135000 | H46: 135000 | P46: =SUM(D46:O46) -> 540000
A47: 42 | B47: Muhammad Dzil Ikram Jani | C47: 1 | D47: 135000 | E47: 135000 | F47: 135000 | H47: 135000 | P47: =SUM(D47:O47) -> 540000
A48: 43 | B48: Taufiqurrahman | C48: 1 | D48: 135000 | E48: 135000 | F48: 135000 | H48: 135000 | P48: =SUM(D48:O48) -> 540000
... A71: 66 | B71: Margono | C71: 1 | D71: 135000 | E71: 135000 | F71: 135000 | H71: 135000 | P71: =SUM(D71:O71) -> 540000
A72: 67 | B72: Narto Prayitno | C72: 2 | D72: 270000 | E72: 270000 | P72: =SUM(D72:O72) -> 540000 | Q72: Resign
A73: 68 | B73: Rwandha Sutedira | C73: 1 | D73: 135000 | E73: 135000 | F73: 135000 | H73: 135000 | P73: =SUM(D73:O73) -> 540000
A74: 69 | B74: Sugiarto | C74: 1 | D74: 135000 | F74: 135000 | H74: 135000 | P74: =SUM(D74:O74) -> 405000
A75: 70 | B75: Umayah | C75: 1 | D75: 135000 | E75: 135000 | F75: 135000 | H75: 135000 | P75: =SUM(D75:O75) -> 540000
A76: 71 | B76: Tirto Bayu S | C76: 1 | D76: 135000 | E76: 135000 | F76: 135000 | H76: 135000 | P76: =SUM(D76:O76) -> 540000
A77: 72 | B77: Iwan Setiawan/Produksi | C77: 1 | D77: 135000 | E77: 135000 | F77: 135000 | H77: 135000 | P77: =SUM(D77:O77) -> 540000
A78: 73 | B78: Minan Khusnaeni | C78: 1 | D78: 135000 | E78: 135000 | F78: 135000 | H78: 135000 | P78: =SUM(D78:O78) -> 540000
A79: 74 | B79: Andrian Fadly | C79: 1 | D79: 135000 | E79: 135000 | F79: 135000 | H79: 135000 | P79: =SUM(D79:O79) -> 540000
A80: 75 | B80: Ferry Firmanto | C80: 1 | D80: 135000 | E80: 135000 | F80: 135000 | H80: 135000 | P80: =SUM(D80:O80) -> 540000
A81: 76 | B81: Hendra | C81: 1 | D81: 135000 | E81: 135000 | F81: 135000 | H81: 135000 | P81: =SUM(D81:O81) -> 540000
A82: 77 | B82: Marhasan | C82: 1 | D82: 135000 | E82: 135000 | F82: 135000 | H82: 135000 | P82: =SUM(D82:O82) -> 540000
...

Sheet Rekapan Untuk Ikrom
G1: Pinjaman Barang Sekunder
G2: Pinjaman Barang Primer
G3: Pinjaman Barang Primer Harian (Meatshop)
G4: Pinjaman Daging Event Lebaran
A5: No | B5: Nama | C5: Remark | G5: Bulan | S5: Total
G6: Jan | H6: Feb | I6: Mar | J6: Apr | K6: Mei | L6: Jun | M6: Jul | N6: Ags | O6: Sep | P6: Okt | Q6: Nov | R6: Des
A8: 1 | B8: Budi Laksono | G8: ='Voucher Belanja KOKA'!D6 -> 135000 | H8: ='Voucher Belanja KOKA'!E6 -> 135000 | I8: ='Voucher Belanja KOKA'!F6 -> 135000 | J8: ='Voucher Belanja KOKA'!G6 -> 0 | K8: ='Voucher Belanja KOKA'!H6 -> 135000 | L8: ='Voucher Belanja KOKA'!I6 -> 0 | M8: ='Voucher Belanja KOKA'!J6 -> 0 | N8: ='Voucher Belanja KOKA'!K6 -> 0 | ... R8: ='Voucher Belanja KOKA'!O6 -> 0 | S8: =SUM(G8:R8) -> 540000
A9: 2 | B9: Dara Maulida | G9: ='Voucher Belanja KOKA'!D7 -> 135000 | H9: ='Voucher Belanja KOKA'!E7 -> 135000 | I9: ='Voucher Belanja KOKA'!F7 -> 135000 | J9: ='Voucher Belanja KOKA'!G7 -> 0 | K9: ='Voucher Belanja KOKA'!H7 -> 135000 | L9: ='Voucher Belanja KOKA'!I7 -> 0 | M9: ='Voucher Belanja KOKA'!J7 -> 0 | N9: ='Voucher Belanja KOKA'!K7 -> 0 | ... R9: ='Voucher Belanja KOKA'!O7 -> 0 | S9: =SUM(G9:R9) -> 540000
A10: 3 | B10: Dewi Kartini | G10: ='Voucher Belanja KOKA'!D8 -> 135000 | H10: ='Voucher Belanja KOKA'!E8 -> 135000 | I10: ='Voucher Belanja KOKA'!F8 -> 135000 | J10: ='Voucher Belanja KOKA'!G8 -> 0 | K10: ='Voucher Belanja KOKA'!H8 -> 135000 | L10: ='Voucher Belanja KOKA'!I8 -> 0 | M10: ='Voucher Belanja KOKA'!J8 -> 0 | N10: ='Voucher Belanja KOKA'!K8 -> 0 | ... R10: ='Voucher Belanja KOKA'!O8 -> 0 | S10: =SUM(G10:R10) -> 540000
A11: 4 | B11: Ferika Pujiyanti | G11: ='Voucher Belanja KOKA'!D9 -> 135000 | H11: ='Voucher Belanja KOKA'!E9 -> 135000 | I11: ='Voucher Belanja KOKA'!F9 -> 135000 | J11: ='Voucher Belanja KOKA'!G9 -> 0 | K11: ='Voucher Belanja KOKA'!H9 -> 135000 | L11: ='Voucher Belanja KOKA'!I9 -> 0 | M11: ='Voucher Belanja KOKA'!J9 -> 0 | N11: ='Voucher Belanja KOKA'!K9 -> 0 | ... R11: ='Voucher Belanja KOKA'!O9 -> 0 | S11: =SUM(G11:R11) -> 540000
A12: 5 | B12: Heni Triandini | G12: ='Voucher Belanja KOKA'!D10 -> 135000 | H12: ='Voucher Belanja KOKA'!E10 -> 135000 | I12: ='Voucher Belanja KOKA'!F10 -> 135000 | J12: ='Voucher Belanja KOKA'!G10 -> 0 | K12: ='Voucher Belanja KOKA'!H10 -> 135000 | L12: ='Voucher Belanja KOKA'!I10 -> 0 | M12: ='Voucher Belanja KOKA'!J10 -> 0 | N12: ='Voucher Belanja KOKA'!K10 -> 0 | ... R12: ='Voucher Belanja KOKA'!O10 -> 0 | S12: =SUM(G12:R12) -> 540000
A13: 6 | B13: Herda | G13: ='Voucher Belanja KOKA'!D11 -> 135000 | H13: ='Voucher Belanja KOKA'!E11 -> 135000 | I13: ='Voucher Belanja KOKA'!F11 -> 135000 | J13: ='Voucher Belanja KOKA'!G11 -> 0 | K13: ='Voucher Belanja KOKA'!H11 -> 135000 | L13: ='Voucher Belanja KOKA'!I11 -> 0 | M13: ='Voucher Belanja KOKA'!J11 -> 0 | N13: ='Voucher Belanja KOKA'!K11 -> 0 | ... R13: ='Voucher Belanja KOKA'!O11 -> 0 | S13: =SUM(G13:R13) -> 540000
A14: 7 | B14: Margono | G14: ='Voucher Belanja KOKA'!D12 -> 135000 | H14: ='Voucher Belanja KOKA'!E12 -> 135000 | I14: ='Voucher Belanja KOKA'!F12 -> 135000 | J14: ='Voucher Belanja KOKA'!G12 -> 0 | K14: ='Voucher Belanja KOKA'!H12 -> 135000 | L14: ='Voucher Belanja KOKA'!I12 -> 0 | M14: ='Voucher Belanja KOKA'!J12 -> 0 | N14: ='Voucher Belanja KOKA'!K12 -> 0 | ... R14: ='Voucher Belanja KOKA'!O12 -> 0 | S14: =SUM(G14:R14) -> 540000
A15: 8 | B15: Mohammad Rizki | G15: ='Voucher Belanja KOKA'!D13 -> 135000 | H15: ='Voucher Belanja KOKA'!E13 -> 135000 | I15: ='Voucher Belanja KOKA'!F13 -> 135000 | J15: ='Voucher Belanja KOKA'!G13 -> 0 | K15: ='Voucher Belanja KOKA'!H13 -> 135000 | L15: ='Voucher Belanja KOKA'!I13 -> 0 | M15: ='Voucher Belanja KOKA'!J13 -> 0 | N15: ='Voucher Belanja KOKA'!K13 -> 0 | ... R15: ='Voucher Belanja KOKA'!O13 -> 0 | S15: =SUM(G15:R15) -> 540000
A16: 9 | B16: Rico Septa Saputra | G16: ='Voucher Belanja KOKA'!D14 -> 135000 | H16: ='Voucher Belanja KOKA'!E14 -> 135000 | I16: ='Voucher Belanja KOKA'!F14 -> 135000 | J16: ='Voucher Belanja KOKA'!G14 -> 0 | K16: ='Voucher Belanja KOKA'!H14 -> 135000 | L16: ='Voucher Belanja KOKA'!I14 -> 0 | M16: ='Voucher Belanja KOKA'!J14 -> 0 | N16: ='Voucher Belanja KOKA'!K14 -> 0 | ... R16: ='Voucher Belanja KOKA'!O14 -> 0 | S16: =SUM(G16:R16) -> 540000
A17: 10 | B17: Arno Nugroho | G17: ='Voucher Belanja KOKA'!D15 -> 135000 | H17: ='Voucher Belanja KOKA'!E15 -> 135000 | I17: ='Voucher Belanja KOKA'!F15 -> 135000 | J17: ='Voucher Belanja KOKA'!G15 -> 0 | K17: ='Voucher Belanja KOKA'!H15 -> 135000 | L17: ='Voucher Belanja KOKA'!I15 -> 0 | M17: ='Voucher Belanja KOKA'!J15 -> 0 | N17: ='Voucher Belanja KOKA'!K15 -> 0 | ... R17: ='Voucher Belanja KOKA'!O15 -> 0 | S17: =SUM(G17:R17) -> 540000
A18: 11 | B18: Khairun Nisa | G18: ='Voucher Belanja KOKA'!D16 -> 135000 | H18: ='Voucher Belanja KOKA'!E16 -> 135000 | I18: ='Voucher Belanja KOKA'!F16 -> 135000 | J18: ='Voucher Belanja KOKA'!G16 -> 0 | K18: ='Voucher Belanja KOKA'!H16 -> 135000 | L18: ='Voucher Belanja KOKA'!I16 -> 0 | M18: ='Voucher Belanja KOKA'!J16 -> 0 | N18: ='Voucher Belanja KOKA'!K16 -> 0 | ... R18: ='Voucher Belanja KOKA'!O16 -> 0 | S18: =SUM(G18:R18) -> 540000
A19: 12 | B19: Lita Ayu Rosida | G19: ='Voucher Belanja KOKA'!D17 -> 135000 | H19: ='Voucher Belanja KOKA'!E17 -> 135000 | I19: ='Voucher Belanja KOKA'!F17 -> 135000 | J19: ='Voucher Belanja KOKA'!G17 -> 0 | K19: ='Voucher Belanja KOKA'!H17 -> 135000 | L19: ='Voucher Belanja KOKA'!I17 -> 0 | M19: ='Voucher Belanja KOKA'!J17 -> 0 | N19: ='Voucher Belanja KOKA'!K17 -> 0 | ... R19: ='Voucher Belanja KOKA'!O17 -> 0 | S19: =SUM(G19:R19) -> 540000
... A28: 21 | B28: Fellix Stephen Willa | G28: ='Voucher Belanja KOKA'!D26 -> 135000 | H28: ='Voucher Belanja KOKA'!E26 -> 135000 | I28: ='Voucher Belanja KOKA'!F26 -> 135000 | J28: ='Voucher Belanja KOKA'!G26 -> 0 | K28: ='Voucher Belanja KOKA'!H26 -> 135000 | L28: ='Voucher Belanja KOKA'!I26 -> 0 | M28: ='Voucher Belanja KOKA'!J26 -> 0 | N28: ='Voucher Belanja KOKA'!K26 -> 0 | ... R28: ='Voucher Belanja KOKA'!O26 -> 0 | S28: =SUM(G28:R28) -> 540000
A29: 22 | B29: Wawan Satriawan | G29: ='Voucher Belanja KOKA'!D27+'Pinjaman Barang Primer Harian'!C7 -> 195900 | H29: ='Voucher Belanja KOKA'!E27+'Pinjaman Barang Primer Harian'!D7 -> 135000 | I29: ='Voucher Belanja KOKA'!F27+'Pinjaman Barang Primer Harian'!E7 -> 135000 | J29: ='Voucher Belanja KOKA'!G27+'Pinjaman Barang Primer Harian'!F7 -> 0 | K29: ='Voucher Belanja KOKA'!H27+'Pinjaman Barang Primer Harian'!G7 -> 135000 | L29: ='Voucher Belanja KOKA'!I27+'Pinjaman Barang Primer Harian'!H7 -> 0 | M29: ='Voucher Belanja KOKA'!J27+'Pinjaman Barang Primer Harian'!I7 -> 0 | N29: ='Voucher Belanja KOKA'!K27+'Pinjaman Barang Primer Harian'!J7 -> 0 | ... R29: ='Voucher Belanja KOKA'!O27+'Pinjaman Barang Primer Harian'!N7 -> 0 | S29: =SUM(G29:R29) -> 600900
A30: 23 | B30: Citra Meiliana R | G30: ='Voucher Belanja KOKA'!D28 -> 135000 | H30: ='Voucher Belanja KOKA'!E28 -> 135000 | I30: ='Voucher Belanja KOKA'!F28 -> 135000 | J30: ='Voucher Belanja KOKA'!G28 -> 0 | K30: ='Voucher Belanja KOKA'!H28 -> 135000 | L30: ='Voucher Belanja KOKA'!I28 -> 0 | M30: ='Voucher Belanja KOKA'!J28 -> 0 | N30: ='Voucher Belanja KOKA'!K28 -> 0 | ... R30: ='Voucher Belanja KOKA'!O28 -> 0 | S30: =SUM(G30:R30) -> 540000
A31: 24 | B31: Septi Priawandra | G31: ='Voucher Belanja KOKA'!D29 -> 135000 | H31: ='Voucher Belanja KOKA'!E29 -> 135000 | I31: ='Voucher Belanja KOKA'!F29 -> 135000 | J31: ='Voucher Belanja KOKA'!G29 -> 0 | K31: ='Voucher Belanja KOKA'!H29 -> 135000 | L31: ='Voucher Belanja KOKA'!I29 -> 0 | M31: ='Voucher Belanja KOKA'!J29 -> 0 | N31: ='Voucher Belanja KOKA'!K29 -> 0 | ... R31: ='Voucher Belanja KOKA'!O29 -> 0 | S31: =SUM(G31:R31) -> 540000
A32: 25 | B32: Suci Nur Khasanah | G32: ='Voucher Belanja KOKA'!D30 -> 135000 | H32: ='Voucher Belanja KOKA'!E30 -> 135000 | I32: ='Voucher Belanja KOKA'!F30 -> 135000 | J32: ='Voucher Belanja KOKA'!G30 -> 0 | K32: ='Voucher Belanja KOKA'!H30 -> 135000 | L32: ='Voucher Belanja KOKA'!I30 -> 0 | M32: ='Voucher Belanja KOKA'!J30 -> 0 | N32: ='Voucher Belanja KOKA'!K30 -> 0 | ... R32: ='Voucher Belanja KOKA'!O30 -> 0 | S32: =SUM(G32:R32) -> 540000
A33: 26 | B33: Anton | G33: ='Voucher Belanja KOKA'!D31 -> 135000 | H33: ='Voucher Belanja KOKA'!E31 -> 135000 | I33: ='Voucher Belanja KOKA'!F31 -> 135000 | J33: ='Voucher Belanja KOKA'!G31 -> 0 | K33: ='Voucher Belanja KOKA'!H31 -> 135000 | L33: ='Voucher Belanja KOKA'!I31 -> 0 | M33: ='Voucher Belanja KOKA'!J31 -> 0 | N33: ='Voucher Belanja KOKA'!K31 -> 0 | ... R33: ='Voucher Belanja KOKA'!O31 -> 0 | S33: =SUM(G33:R33) -> 540000
A34: 27 | B34: Tri Iswahyudi | G34: ='Voucher Belanja KOKA'!D32 -> 135000 | H34: ='Voucher Belanja KOKA'!E32 -> 135000 | I34: ='Voucher Belanja KOKA'!F32 -> 135000 | J34: ='Voucher Belanja KOKA'!G32 -> 0 | K34: ='Voucher Belanja KOKA'!H32 -> 135000 | L34: ='Voucher Belanja KOKA'!I32 -> 0 | M34: ='Voucher Belanja KOKA'!J32 -> 0 | N34: ='Voucher Belanja KOKA'!K32 -> 0 | ... R34: ='Voucher Belanja KOKA'!O32 -> 0 | S34: =SUM(G34:R34) -> 540000
A35: 28 | B35: Mohammad Firdaus | G35: ='Voucher Belanja KOKA'!D33 -> 135000 | H35: ='Voucher Belanja KOKA'!E33 -> 135000 | I35: ='Voucher Belanja KOKA'!F33 -> 135000 | J35: ='Voucher Belanja KOKA'!G33 -> 0 | K35: ='Voucher Belanja KOKA'!H33 -> 135000 | L35: ='Voucher Belanja KOKA'!I33 -> 0 | M35: ='Voucher Belanja KOKA'!J33 -> 0 | N35: ='Voucher Belanja KOKA'!K33 -> 0 | ... R35: ='Voucher Belanja KOKA'!O33 -> 0 | S35: =SUM(G35:R35) -> 540000
A36: 29 | B36: Mohammad Ade Faiza | G36: ='Voucher Belanja KOKA'!D34 -> 135000 | H36: ='Voucher Belanja KOKA'!E34 -> 135000 | I36: ='Voucher Belanja KOKA'!F34 -> 135000 | J36: ='Voucher Belanja KOKA'!G34 -> 0 | K36: ='Voucher Belanja KOKA'!H34 -> 135000 | L36: ='Voucher Belanja KOKA'!I34 -> 0 | M36: ='Voucher Belanja KOKA'!J34 -> 0 | N36: ='Voucher Belanja KOKA'!K34 -> 0 | ... R36: ='Voucher Belanja KOKA'!O34 -> 0 | S36: =SUM(G36:R36) -> 540000
A37: 30 | B37: Taufik Hidayat | G37: ='Voucher Belanja KOKA'!D35 -> 135000 | H37: ='Voucher Belanja KOKA'!E35 -> 135000 | I37: ='Voucher Belanja KOKA'!F35 -> 135000 | J37: ='Voucher Belanja KOKA'!G35 -> 0 | K37: ='Voucher Belanja KOKA'!H35 -> 135000 | L37: ='Voucher Belanja KOKA'!I35 -> 0 | M37: ='Voucher Belanja KOKA'!J35 -> 0 | N37: ='Voucher Belanja KOKA'!K35 -> 0 | ... R37: ='Voucher Belanja KOKA'!O35 -> 0 | S37: =SUM(G37:R37) -> 540000
A38: 31 | B38: Rudi Nugroho | G38: ='Voucher Belanja KOKA'!D36 -> 135000 | H38: ='Voucher Belanja KOKA'!E36 -> 135000 | I38: ='Voucher Belanja KOKA'!F36 -> 0 | J38: ='Voucher Belanja KOKA'!G36 -> 0 | K38: ='Voucher Belanja KOKA'!H36 -> 0 | L38: ='Voucher Belanja KOKA'!I36 -> 0 | M38: ='Voucher Belanja KOKA'!J36 -> 0 | N38: ='Voucher Belanja KOKA'!K36 -> 0 | ... R38: ='Voucher Belanja KOKA'!O36 -> 0 | S38: =SUM(G38:R38) -> 270000
A39: 32 | B39: Rian Alandy | G39: ='Voucher Belanja KOKA'!D37 -> 135000 | H39: ='Voucher Belanja KOKA'!E37 -> 135000 | I39: ='Voucher Belanja KOKA'!F37 -> 135000 | J39: ='Voucher Belanja KOKA'!G37 -> 0 | K39: ='Voucher Belanja KOKA'!H37 -> 135000 | L39: ='Voucher Belanja KOKA'!I37 -> 0 | M39: ='Voucher Belanja KOKA'!J37 -> 0 | N39: ='Voucher Belanja KOKA'!K37 -> 0 | ... R39: ='Voucher Belanja KOKA'!O37 -> 0 | S39: =SUM(G39:R39) -> 540000
A40: 33 | B40: Muhammad Irham | G40: ='Voucher Belanja KOKA'!D38 -> 135000 | H40: ='Voucher Belanja KOKA'!E38 -> 135000 | I40: ='Voucher Belanja KOKA'!F38 -> 135000 | J40: ='Voucher Belanja KOKA'!G38 -> 0 | K40: ='Voucher Belanja KOKA'!H38 -> 135000 | L40: ='Voucher Belanja KOKA'!I38 -> 0 | M40: ='Voucher Belanja KOKA'!J38 -> 0 | N40: ='Voucher Belanja KOKA'!K38 -> 0 | ... R40: ='Voucher Belanja KOKA'!O38 -> 0 | S40: =SUM(G40:R40) -> 540000
A41: 34 | B41: Ahmad Zaid Mahfudi | G41: ='Voucher Belanja KOKA'!D39 -> 135000 | H41: ='Voucher Belanja KOKA'!E39 -> 135000 | I41: ='Voucher Belanja KOKA'!F39 -> 135000 | J41: ='Voucher Belanja KOKA'!G39 -> 0 | K41: ='Voucher Belanja KOKA'!H39 -> 135000 | L41: ='Voucher Belanja KOKA'!I39 -> 0 | M41: ='Voucher Belanja KOKA'!J39 -> 0 | N41: ='Voucher Belanja KOKA'!K39 -> 0 | ... R41: ='Voucher Belanja KOKA'!O39 -> 0 | S41: =SUM(G41:R41) -> 540000
... A43: 36 | B43: Arief Indrawan | G43: ='Voucher Belanja KOKA'!D41 -> 135000 | H43: ='Voucher Belanja KOKA'!E41 -> 135000 | I43: ='Voucher Belanja KOKA'!F41 -> 135000 | J43: ='Voucher Belanja KOKA'!G41 -> 0 | K43: ='Voucher Belanja KOKA'!H41 -> 135000 | L43: ='Voucher Belanja KOKA'!I41 -> 0 | M43: ='Voucher Belanja KOKA'!J41 -> 0 | N43: ='Voucher Belanja KOKA'!K41 -> 0 | ... R43: ='Voucher Belanja KOKA'!O41 -> 0 | S43: =SUM(G43:R43) -> 540000
A44: 37 | B44: Arsim | G44: ='Voucher Belanja KOKA'!D42 -> 135000 | H44: ='Voucher Belanja KOKA'!E42 -> 135000 | I44: ='Voucher Belanja KOKA'!F42+'Pinjaman Barang Primer Harian'!E11 -> 279900 | J44: ='Voucher Belanja KOKA'!G42 -> 0 | K44: ='Voucher Belanja KOKA'!H42 -> 135000 | L44: ='Voucher Belanja KOKA'!I42 -> 0 | M44: ='Voucher Belanja KOKA'!J42 -> 0 | N44: ='Voucher Belanja KOKA'!K42 -> 0 | O44: ='Voucher Belanja KOKA'!L42 -> 0 | P44: ='Voucher Belanja KOKA'!M42 -> 0 | Q44: ='Voucher Belanja KOKA'!N42 -> 0 | R44: ='Voucher Belanja KOKA'!O42 -> 0 | S44: =SUM(G44:R44) -> 684900
A45: 38 | B45: Didi Rahmat | G45: ='Voucher Belanja KOKA'!D43 -> 135000 | H45: ='Voucher Belanja KOKA'!E43 -> 135000 | I45: ='Voucher Belanja KOKA'!F43 -> 135000 | J45: ='Voucher Belanja KOKA'!G43 -> 0 | K45: ='Voucher Belanja KOKA'!H43 -> 135000 | L45: ='Voucher Belanja KOKA'!I43 -> 0 | M45: ='Voucher Belanja KOKA'!J43 -> 0 | N45: ='Voucher Belanja KOKA'!K43 -> 0 | ... R45: ='Voucher Belanja KOKA'!O43 -> 0 | S45: =SUM(G45:R45) -> 540000
A46: 39 | B46: Eka Yanuar Santosa | G46: ='Voucher Belanja KOKA'!D44 -> 135000 | H46: ='Voucher Belanja KOKA'!E44 -> 135000 | I46: ='Voucher Belanja KOKA'!F44 -> 135000 | J46: ='Voucher Belanja KOKA'!G44 -> 0 | K46: ='Voucher Belanja KOKA'!H44 -> 135000 | L46: ='Voucher Belanja KOKA'!I44 -> 0 | M46: ='Voucher Belanja KOKA'!J44 -> 0 | N46: ='Voucher Belanja KOKA'!K44 -> 0 | ... R46: ='Voucher Belanja KOKA'!O44 -> 0 | S46: =SUM(G46:R46) -> 540000
A47: 40 | B47: Heru Sri Margono | G47: ='Voucher Belanja KOKA'!D45 -> 135000 | H47: ='Voucher Belanja KOKA'!E45 -> 135000 | I47: ='Voucher Belanja KOKA'!F45 -> 135000 | J47: ='Voucher Belanja KOKA'!G45 -> 0 | K47: ='Voucher Belanja KOKA'!H45 -> 135000 | L47: ='Voucher Belanja KOKA'!I45 -> 0 | M47: ='Voucher Belanja KOKA'!J45 -> 0 | N47: ='Voucher Belanja KOKA'!K45 -> 0 | ... R47: ='Voucher Belanja KOKA'!O45 -> 0 | S47: =SUM(G47:R47) -> 540000
A48: 41 | B48: Keren | G48: ='Voucher Belanja KOKA'!D46 -> 135000 | H48: ='Voucher Belanja KOKA'!E46 -> 135000 | I48: ='Voucher Belanja KOKA'!F46 -> 135000 | J48: ='Voucher Belanja KOKA'!G46 -> 0 | K48: ='Voucher Belanja KOKA'!H46 -> 135000 | L48: ='Voucher Belanja KOKA'!I46 -> 0 | M48: ='Voucher Belanja KOKA'!J46 -> 0 | N48: ='Voucher Belanja KOKA'!K46 -> 0 | ... R48: ='Voucher Belanja KOKA'!O46 -> 0 | S48: =SUM(G48:R48) -> 540000
A49: 42 | B49: Muhammad Dzil Ikram Jani | G49: ='Voucher Belanja KOKA'!D47 -> 135000 | H49: ='Voucher Belanja KOKA'!E47 -> 135000 | I49: ='Voucher Belanja KOKA'!F47 -> 135000 | J49: ='Voucher Belanja KOKA'!G47 -> 0 | K49: ='Voucher Belanja KOKA'!H47 -> 135000 | L49: ='Voucher Belanja KOKA'!I47 -> 0 | M49: ='Voucher Belanja KOKA'!J47 -> 0 | N49: ='Voucher Belanja KOKA'!K47 -> 0 | ... R49: ='Voucher Belanja KOKA'!O47 -> 0 | S49: =SUM(G49:R49) -> 540000
A50: 43 | B50: Taufiqurrahman | G50: ='Voucher Belanja KOKA'!D48 -> 135000 | H50: ='Voucher Belanja KOKA'!E48 -> 135000 | I50: ='Voucher Belanja KOKA'!F48 -> 135000 | J50: ='Voucher Belanja KOKA'!G48 -> 0 | K50: ='Voucher Belanja KOKA'!H48 -> 135000 | L50: ='Voucher Belanja KOKA'!I48 -> 0 | M50: ='Voucher Belanja KOKA'!J48 -> 0 | N50: ='Voucher Belanja KOKA'!K48 -> 0 | ... R50: ='Voucher Belanja KOKA'!O48 -> 0 | S50: =SUM(G50:R50) -> 540000
...
