Workbook

Sheet 00_Petunjuk
A1: Petunjuk pengisian data
A2: Isi sel berwarna kuning. Jangan mengubah judul kolom.
A3: Tanda * = wajib diisi. Kolom otomatis berwarna biru muda. Di Simpanan, isi angka pada jenis yang tersedia.
A4: Urutan | B4: Yang dilakukan
A5: 1 | B5: Isi 01_Anggota terlebih dahulu. Satu orang cukup satu baris.
A6: 2 | B6: Jika nama/NPP dari file lama berbeda, isi 02_Pencocokan_Nama.
A7: 3 | B7: Isi 03_Simpanan satu baris untuk setiap anggota. Isi nilai KHUSUS, MANASUKA, WAJIB, dan SHU pada kolom masing-masing.
A8: 4 | B8: Isi 04_Pinjaman satu baris untuk setiap pinjaman. Buat nomor pinjaman yang unik.
A9: 5 | B9: Isi 05_Angsuran dan pastikan setiap angsuran punya satu nomor pinjaman.
A10: 6 | B10: Gunakan 06_Pengecualian untuk data yang memang tidak boleh masuk.
A11: 7 | B11: Lihat 09_Contoh_Isian, isi kolom bertanda *, pilih nama dari daftar jika tersedia, jawab 07_Pertanyaan, lalu periksa 08_Pemeriksaan.
A13: Warna | B13: Arti | C13: Contoh
A14: Kuning | B14: Tempat yang perlu diisi atau diperbaiki | C14: Nama, NPP, tanggal, jumlah
A15: Biru tua | B15: Judul kolom; jangan diubah | C15: Nama Lengkap
A16: Hijau / merah | B16: Hasil pemeriksaan | C16: 0 = tidak ada masalah; angka > 0 = perlu dicek
A18: Aturan penting
A19: NPP | B19: Simpan NPP sebagai teks agar angka 0 di depan tidak hilang. NPP PHL yang bukan angka harus dibuat unik dan tidak boleh kosong.
A20: Tanggal | B20: Gunakan format YYYY-MM-DD. Jika tanggal bergabung kosong, gunakan 2026-09-07 dan tulis 'tanggal sementara' di catatan.
A21: Jumlah | B21: Isi angka Rupiah utuh tanpa pembulatan. Contoh: 1500000, bukan Rp1.500.000 dan bukan 1.500.000,50.
A22: Simpanan | B22: Satu baris Simpanan = satu anggota. Isi angka pada kolom KHUSUS, MANASUKA, WAJIB, dan SHU. Kosong atau 0 berarti tidak ada nilai.
A23: Pinjaman | B23: Pokok, admin, total kewajiban, lama cicilan, tanggal cair, dan status harus berasal dari sumber atau keputusan yang disetujui.
A24: Angsuran | B24: Satu angsuran harus menunjuk ke satu nomor pinjaman. Jangan memakai nomor baris sebagai nomor pinjaman.
A25: Anggota aktif | B25: Anggota Aktif, Baru, dan PHL dapat dibuatkan akun. Anggota Purna Bakti tetap dicatat untuk sejarah, tetapi tidak dibuatkan akun.
A26: Pengecualian | B26: Catat data yang sengaja tidak dimasukkan di 06_Pengecualian, lengkap dengan alasan dan persetujuan.
A27: Sumber | B27: Asal Sheet dan Baris Asal adalah catatan audit untuk pencocokan atau pengecualian. Tidak perlu diisi di Simpanan dan Angsuran.
A28: Pemeriksaan | B28: Sebelum dikirim, angka merah harus menjadi 0 atau sudah memiliki keputusan tertulis.

Sheet 01_Anggota
A1: Daftar anggota
A2: Satu orang satu baris. Anggota aktif dan tidak aktif tetap dicatat jika punya sejarah transaksi.
A4: No (otomatis) | B4: NPP Koperasi * | C4: NPP Lama | D4: Nama Lengkap * | E4: Status * | F4: Jenis Anggota | G4: Tanggal Bergabung * | H4: Area | I4: No. HP | J4: Alamat | K4: Keputusan Identitas * | L4: Masukkan? * | M4: Catatan
A5: =IF(D5="","",ROW()-4) -> 1 | B5: KKSUK-000001 | C5: 00553 | D5: Abdul Cahyo Nugroho | E5: Aktif | F5: Pegawai | H5: Cakung
A6: =IF(D6="","",ROW()-4) -> 2 | B6: KKSUK-000002 | C6: 00549 | D6: Ahmad Fauzi - 00549 | E6: Aktif | F6: Pegawai | H6: Cakung
A7: =IF(D7="","",ROW()-4) -> 3 | B7: KKSUK-000003 | C7: 00546 | D7: Andrian Fadly | E7: Aktif | F7: Pegawai | H7: Cakung
A8: =IF(D8="","",ROW()-4) -> 4 | B8: KKSUK-000004 | C8: 00511 | D8: Andung Juanda | E8: Aktif | F8: Pegawai | H8: Cakung
A9: =IF(D9="","",ROW()-4) -> 5 | B9: KKSUK-000005 | C9: 00340 | D9: Anwari | E9: Aktif | F9: Pegawai | H9: Cakung
A10: =IF(D10="","",ROW()-4) -> 6 | B10: KKSUK-000006 | C10: 00345 | D10: Ardiansyah | E10: Purna Bakti 2026 | F10: Pegawai | H10: Cakung
A11: =IF(D11="","",ROW()-4) -> 7 | B11: KKSUK-000007 | C11: 00519 | D11: Budi Laksono | E11: Aktif | F11: Pegawai | H11: Cakung
A12: =IF(D12="","",ROW()-4) -> 8 | B12: KKSUK-000008 | C12: 00325 | D12: Dadi Muhamad Mulyadi | E12: Aktif | F12: Pegawai | H12: Pulogadung
A13: =IF(D13="","",ROW()-4) -> 9 | B13: KKSUK-000009 | C13: 00543 | D13: Dara Maulida | E13: Aktif | F13: Pegawai | H13: Cakung
A14: =IF(D14="","",ROW()-4) -> 10 | B14: KKSUK-000010 | C14: 00540 | D14: Dedy Kurniawan | E14: Aktif | F14: Pegawai | H14: Cakung
A15: =IF(D15="","",ROW()-4) -> 11 | B15: KKSUK-000011 | C15: 00539 | D15: Dewi Kartini | E15: Aktif | F15: Pegawai | H15: Cakung
A16: =IF(D16="","",ROW()-4) -> 12 | B16: KKSUK-000012 | C16: 00518 | D16: Diki Firmansyah | E16: Aktif | F16: Pegawai | H16: Cakung
... A41: =IF(D41="","",ROW()-4) -> 37 | B41: KKSUK-000037 | C41: 00497 | D41: Riana Merry Natalia | E41: Aktif | F41: Pegawai | H41: Cakung
A42: =IF(D42="","",ROW()-4) -> 38 | B42: KKSUK-000038 | C42: 0 | D42: Riana Merry Natalia QQ Lasman | E42: Aktif | F42: Pegawai | H42: Cakung
A43: =IF(D43="","",ROW()-4) -> 39 | B43: KKSUK-000039 | C43: 00544 | D43: Rico Septa Saputra | E43: Aktif | F43: Pegawai | H43: Cakung
A44: =IF(D44="","",ROW()-4) -> 40 | B44: KKSUK-000040 | C44: 00485 | D44: Rosmiati | E44: Aktif | F44: Pegawai | H44: Cakung
A45: =IF(D45="","",ROW()-4) -> 41 | B45: KKSUK-000041 | C45: 00343 | D45: Sudadi | E45: Aktif | F45: Pegawai | H45: Cakung
A46: =IF(D46="","",ROW()-4) -> 42 | B46: KKSUK-000042 | C46: 00293 | D46: Sugiarto | E46: Aktif | F46: Pegawai | H46: Cakung
A47: =IF(D47="","",ROW()-4) -> 43 | B47: KKSUK-000043 | C47: 00527 | D47: Toni | E47: Aktif | F47: Pegawai | H47: Cakung
A48: =IF(D48="","",ROW()-4) -> 44 | B48: KKSUK-000044 | C48: 00362 | D48: Umayah | E48: Aktif | F48: Pegawai | H48: Cakung
A49: =IF(D49="","",ROW()-4) -> 45 | B49: KKSUK-000045 | C49: 00548 | D49: Wawan Satriawan | E49: Aktif | F49: Pegawai | H49: Cakung
A50: =IF(D50="","",ROW()-4) -> 46 | B50: KKSUK-000046 | C50: 00499 | D50: Wiyan Eko Supriyanto | E50: Aktif | F50: Pegawai | H50: Cakung
A51: =IF(D51="","",ROW()-4) -> 47 | B51: KKSUK-000047 | C51: 00633 | D51: Sri Wahyuningsih | E51: Aktif | F51: Pegawai | H51: Cakung
A52: =IF(D52="","",ROW()-4) -> 48 | B52: KKSUK-000048 | C52: 00571 | D52: Indra Jaya Nugraha Putra | E52: Purna Bakti 2026 | F52: Pegawai | H52: Cakung
A53: =IF(D53="","",ROW()-4) -> 49 | B53: KKSUK-000049 | C53: 00642 | D53: Dehur | E53: Aktif | F53: Pegawai | H53: Cakung
A54: =IF(D54="","",ROW()-4) -> 50 | B54: KKSUK-000050 | C54: K637 | D54: Yonatan Banobe | E54: Aktif | F54: PKWT | H54: Cakung
... A101: =IF(D101="","",ROW()-4) -> 97 | B101: KKSUK-000097 | C101: K879 | D101: Sartono | E101: Aktif | F101: PKWT | H101: Kapuk
A102: =IF(D102="","",ROW()-4) -> 98 | B102: KKSUK-000098 | C102: 0 | D102: Marwanto | E102: Aktif | F102: PHL | H102: Kapuk
A103: =IF(D103="","",ROW()-4) -> 99 | B103: KKSUK-000099 | C103: K598 | D103: Kadek Sudarsana | E103: Aktif | F103: PKWT | H103: Kapuk
A104: =IF(D104="","",ROW()-4) -> 100 | B104: KKSUK-000100 | C104: 00574 | D104: Dian Suanto | E104: Aktif | F104: Pegawai | H104: Kapuk
A105: =IF(D105="","",ROW()-4) -> 101 | B105: KKSUK-000101 | C105: 0 | D105: Darsim | E105: Purna Bakti 2026 | F105: Pegawai | H105: Kapuk
A106: =IF(D106="","",ROW()-4) -> 102 | B106: KKSUK-000102 | C106: 0 | D106: Jaimin | E106: Aktif | F106: PHL | H106: Kapuk
A107: =IF(D107="","",ROW()-4) -> 103 | B107: KKSUK-000103 | C107: K1563 | D107: Hesby Aga Ardila Nugroho | E107: Purna Bakti 2026 | F107: PKWT | H107: Kapuk
A108: =IF(D108="","",ROW()-4) -> 104 | B108: KKSUK-000104 | C108: 00585 | D108: Gede Suparta | E108: Aktif | F108: Pegawai | H108: Kapuk
A109: =IF(D109="","",ROW()-4) -> 105 | B109: KKSUK-000105 | C109: 0 | D109: Jais Hartono | E109: Aktif | F109: PHL | H109: Kapuk
A110: =IF(D110="","",ROW()-4) -> 106 | B110: KKSUK-000106 | C110: 00611 | D110: Repki Ariyanto | E110: Aktif | F110: Pegawai | H110: Cakung
A111: =IF(D111="","",ROW()-4) -> 107 | B111: KKSUK-000107 | C111: 00614 | D111: Anton Efendi | E111: Aktif | F111: Pegawai | H111: Cakung
...

Sheet 03_Simpanan
A1: Data simpanan
A2: Satu baris untuk satu anggota. Isi angka pada jenis simpanan yang tersedia. Kosong atau 0 berarti tidak ada nilai.
A4: No (otomatis) | B4: Nama Anggota * | C4: NPP (otomatis) | D4: KHUSUS (Rp) | E4: MANASUKA (Rp) | F4: WAJIB (Rp) | G4: SHU (Rp) | H4: Tanggal | I4: Catatan
A5: =IF(B5="","",ROW()-4) -> 1 | B5: A. Rafik | C5: =IF(B5="","",IF(COUNTIF('01_Anggota'!$D$5:$D$1212,B5)=0,"NAMA TIDAK DITEMUKAN",INDEX('01_Anggota'!$B$5:$B$1212,MATCH(B5,'01_Anggota'!$D$5:$D$1212,0)))) -> KKSUK-000166 | D5: 0 | E5: 1600000 | F5: 800000 | G5: 0 | H5: 46023 | I5: 00. Saldo Akhir 2025
A6: =IF(B6="","",ROW()-4) -> 2 | B6: A. Rafik | C6: =IF(B6="","",IF(COUNTIF('01_Anggota'!$D$5:$D$1212,B6)=0,"NAMA TIDAK DITEMUKAN",INDEX('01_Anggota'!$B$5:$B$1212,MATCH(B6,'01_Anggota'!$D$5:$D$1212,0)))) -> KKSUK-000166 | D6: 0 | E6: 200000 | F6: 100000 | G6: 0 | H6: 46045 | I6: 01. Jan 2026
A7: =IF(B7="","",ROW()-4) -> 3 | B7: A. Rafik | C7: =IF(B7="","",IF(COUNTIF('01_Anggota'!$D$5:$D$1212,B7)=0,"NAMA TIDAK DITEMUKAN",INDEX('01_Anggota'!$B$5:$B$1212,MATCH(B7,'01_Anggota'!$D$5:$D$1212,0)))) -> KKSUK-000166 | D7: 0 | E7: 200000 | F7: 100000 | G7: 0 | H7: 46078 | I7: 02. Feb 2026
A8: =IF(B8="","",ROW()-4) -> 4 | B8: A. Rafik | C8: =IF(B8="","",IF(COUNTIF('01_Anggota'!$D$5:$D$1212,B8)=0,"NAMA TIDAK DITEMUKAN",INDEX('01_Anggota'!$B$5:$B$1212,MATCH(B8,'01_Anggota'!$D$5:$D$1212,0)))) -> KKSUK-000166 | D8: 0 | E8: 200000 | F8: 100000 | G8: 0 | H8: 46106 | I8: 03. Mar 2026
A9: =IF(B9="","",ROW()-4) -> 5 | B9: A. Rafik | C9: =IF(B9="","",IF(COUNTIF('01_Anggota'!$D$5:$D$1212,B9)=0,"NAMA TIDAK DITEMUKAN",INDEX('01_Anggota'!$B$5:$B$1212,MATCH(B9,'01_Anggota'!$D$5:$D$1212,0)))) -> KKSUK-000166 | D9: 0 | E9: 200000 | F9: 100000 | G9: 0 | H9: 46136 | I9: 04. Apr 2026
A10: =IF(B10="","",ROW()-4) -> 6 | B10: A. Rafik | C10: =IF(B10="","",IF(COUNTIF('01_Anggota'!$D$5:$D$1212,B10)=0,"NAMA TIDAK DITEMUKAN",INDEX('01_Anggota'!$B$5:$B$1212,MATCH(B10,'01_Anggota'!$D$5:$D$1212,0)))) -> KKSUK-000166 | D10: 0 | E10: 200000 | F10: 100000 | G10: 0 | H10: 46167 | I10: 05. Mei 2026
A11: =IF(B11="","",ROW()-4) -> 7 | B11: A. Rafik | C11: =IF(B11="","",IF(COUNTIF('01_Anggota'!$D$5:$D$1212,B11)=0,"NAMA TIDAK DITEMUKAN",INDEX('01_Anggota'!$B$5:$B$1212,MATCH(B11,'01_Anggota'!$D$5:$D$1212,0)))) -> KKSUK-000166 | D11: 0 | E11: 200000 | F11: 100000 | G11: 0 | H11: 46198 | I11: 06. Jun 2026
A12: =IF(B12="","",ROW()-4) -> 8 | B12: A. Rafik | C12: =IF(B12="","",IF(COUNTIF('01_Anggota'!$D$5:$D$1212,B12)=0,"NAMA TIDAK DITEMUKAN",INDEX('01_Anggota'!$B$5:$B$1212,MATCH(B12,'01_Anggota'!$D$5:$D$1212,0)))) -> KKSUK-000166 | D12: 0 | E12: 200000 | F12: 100000 | G12: 0 | H12: 46227 | I12: 07. Jul 2026
A13: =IF(B13="","",ROW()-4) -> 9 | B13: A. Rafik | C13: =IF(B13="","",IF(COUNTIF('01_Anggota'!$D$5:$D$1212,B13)=0,"NAMA TIDAK DITEMUKAN",INDEX('01_Anggota'!$B$5:$B$1212,MATCH(B13,'01_Anggota'!$D$5:$D$1212,0)))) -> KKSUK-000166 | D13: 0 | E13: 200000 | F13: 100000 | G13: 0 | H13: 46258 | I13: 08. Agu 2026
A14: =IF(B14="","",ROW()-4) -> 10 | B14: Aan Supriyatin | C14: =IF(B14="","",IF(COUNTIF('01_Anggota'!$D$5:$D$1212,B14)=0,"NAMA TIDAK DITEMUKAN",INDEX('01_Anggota'!$B$5:$B$1212,MATCH(B14,'01_Anggota'!$D$5:$D$1212,0)))) -> KKSUK-000158 | D14: 0 | E14: 1800000 | F14: 1000000 | G14: 0 | H14: 46023 | I14: 00. Saldo Akhir 2025
A15: =IF(B15="","",ROW()-4) -> 11 | B15: Aan Supriyatin | C15: =IF(B15="","",IF(COUNTIF('01_Anggota'!$D$5:$D$1212,B15)=0,"NAMA TIDAK DITEMUKAN",INDEX('01_Anggota'!$B$5:$B$1212,MATCH(B15,'01_Anggota'!$D$5:$D$1212,0)))) -> KKSUK-000158 | D15: 0 | E15: 150000 | F15: 100000 | G15: 0 | H15: 46045 | I15: 01. Jan 2026
A16: =IF(B16="","",ROW()-4) -> 12 | B16: Aan Supriyatin | C16: =IF(B16="","",IF(COUNTIF('01_Anggota'!$D$5:$D$1212,B16)=0,"NAMA TIDAK DITEMUKAN",INDEX('01_Anggota'!$B$5:$B$1212,MATCH(B16,'01_Anggota'!$D$5:$D$1212,0)))) -> KKSUK-000158 | D16: 0 | E16: 150000 | F16: 100000 | G16: 0 | H16: 46078 | I16: 02. Feb 2026
... A994: =IF(B994="","",ROW()-4) -> 990 | B994: Mohamad Firdaus | C994: =IF(B994="","",IF(COUNTIF('01_Anggota'!$D$5:$D$1212,B994)=0,"NAMA TIDAK DITEMUKAN",INDEX('01_Anggota'!$B$5:$B$1212,MATCH(B994,'01_Anggota'!$D$5:$D$1212,0)))) -> KKSUK-000143 | D994: 0 | E994: 100000 | F994: 100000 | G994: 0 | H994: 46258 | I994: 08. Agu 2026
A995: =IF(B995="","",ROW()-4) -> 991 | B995: Mohammad Rizki | C995: =IF(B995="","",IF(COUNTIF('01_Anggota'!$D$5:$D$1212,B995)=0,"NAMA TIDAK DITEMUKAN",INDEX('01_Anggota'!$B$5:$B$1212,MATCH(B995,'01_Anggota'!$D$5:$D$1212,0)))) -> KKSUK-000032 | E995: 2083058 | F995: 7954113.3 | G995: 2800919 | H995: 46023 | I995: 00. Saldo Akhir 2025
A996: =IF(B996="","",ROW()-4) -> 992 | B996: Mohammad Rizki | C996: =IF(B996="","",IF(COUNTIF('01_Anggota'!$D$5:$D$1212,B996)=0,"NAMA TIDAK DITEMUKAN",INDEX('01_Anggota'!$B$5:$B$1212,MATCH(B996,'01_Anggota'!$D$5:$D$1212,0)))) -> KKSUK-000032 | D996: 0 | E996: 50000 | F996: 100000 | G996: 0 | H996: 46045 | I996: 01. Jan 2026
A997: =IF(B997="","",ROW()-4) -> 993 | B997: Mohammad Rizki | C997: =IF(B997="","",IF(COUNTIF('01_Anggota'!$D$5:$D$1212,B997)=0,"NAMA TIDAK DITEMUKAN",INDEX('01_Anggota'!$B$5:$B$1212,MATCH(B997,'01_Anggota'!$D$5:$D$1212,0)))) -> KKSUK-000032 | D997: 0 | E997: 50000 | F997: 100000 | G997: 0 | H997: 46078 | I997: 02. Feb 2026
A998: =IF(B998="","",ROW()-4) -> 994 | B998: Mohammad Rizki | C998: =IF(B998="","",IF(COUNTIF('01_Anggota'!$D$5:$D$1212,B998)=0,"NAMA TIDAK DITEMUKAN",INDEX('01_Anggota'!$B$5:$B$1212,MATCH(B998,'01_Anggota'!$D$5:$D$1212,0)))) -> KKSUK-000032 | D998: 0 | E998: 50000 | F998: 100000 | G998: 0 | H998: 46106 | I998: 03. Mar 2026
A999: =IF(B999="","",ROW()-4) -> 995 | B999: Mohammad Rizki | C999: =IF(B999="","",IF(COUNTIF('01_Anggota'!$D$5:$D$1212,B999)=0,"NAMA TIDAK DITEMUKAN",INDEX('01_Anggota'!$B$5:$B$1212,MATCH(B999,'01_Anggota'!$D$5:$D$1212,0)))) -> KKSUK-000032 | D999: 0 | E999: 50000 | F999: 150000 | G999: 0 | H999: 46136 | I999: 04. Apr 2026
A1000: =IF(B1000="","",ROW()-4) -> 996 | B1000: Mohammad Rizki | C1000: =IF(B1000="","",IF(COUNTIF('01_Anggota'!$D$5:$D$1212,B1000)=0,"NAMA TIDAK DITEMUKAN",INDEX('01_Anggota'!$B$5:$B$1212,MATCH(B1000,'01_Anggota'!$D$5:$D$1212,0)))) -> KKSUK-000032 | D1000: 0 | E1000: 50000 | F1000: 150000 | G1000: 0 | H1000: 46167 | I1000: 05. Mei 2026
A1001: =IF(B1001="","",ROW()-4) -> 997 | B1001: Mohammad Rizki | C1001: =IF(B1001="","",IF(COUNTIF('01_Anggota'!$D$5:$D$1212,B1001)=0,"NAMA TIDAK DITEMUKAN",INDEX('01_Anggota'!$B$5:$B$1212,MATCH(B1001,'01_Anggota'!$D$5:$D$1212,0)))) -> KKSUK-000032 | D1001: 0 | E1001: 50000 | F1001: 150000 | G1001: 0 | H1001: 46198 | I1001: 06. Jun 2026
A1002: =IF(B1002="","",ROW()-4) -> 998 | B1002: Mohammad Rizki | C1002: =IF(B1002="","",IF(COUNTIF('01_Anggota'!$D$5:$D$1212,B1002)=0,"NAMA TIDAK DITEMUKAN",INDEX('01_Anggota'!$B$5:$B$1212,MATCH(B1002,'01_Anggota'!$D$5:$D$1212,0)))) -> KKSUK-000032 | D1002: 0 | E1002: 50000 | F1002: 150000 | G1002: 0 | H1002: 46227 | I1002: 07. Jul 2026
A1003: =IF(B1003="","",ROW()-4) -> 999 | B1003: Mohammad Rizki | C1003: =IF(B1003="","",IF(COUNTIF('01_Anggota'!$D$5:$D$1212,B1003)=0,"NAMA TIDAK DITEMUKAN",INDEX('01_Anggota'!$B$5:$B$1212,MATCH(B1003,'01_Anggota'!$D$5:$D$1212,0)))) -> KKSUK-000032 | D1003: 0 | E1003: 50000 | F1003: 150000 | G1003: 0 | H1003: 46258 | I1003: 08. Agu 2026
A1004: =IF(B1004="","",ROW()-4) -> 1000 | B1004: Muhammad Ade Faizal | C1004: =IF(B1004="","",IF(COUNTIF('01_Anggota'!$D$5:$D$1212,B1004)=0,"NAMA TIDAK DITEMUKAN",INDEX('01_Anggota'!$B$5:$B$1212,MATCH(B1004,'01_Anggota'!$D$5:$D$1212,0)))) -> KKSUK-000145 | D1004: 0 | E1004: 1500000 | F1004: 1500000 | G1004: 152081 | H1004: 46023 | I1004: 00. Saldo Akhir 2025
A1005: =IF(B1005="","",ROW()-4) -> 1001 | B1005: Muhammad Ade Faizal | C1005: =IF(B1005="","",IF(COUNTIF('01_Anggota'!$D$5:$D$1212,B1005)=0,"NAMA TIDAK DITEMUKAN",INDEX('01_Anggota'!$B$5:$B$1212,MATCH(B1005,'01_Anggota'!$D$5:$D$1212,0)))) -> KKSUK-000145 | D1005: 0 | E1005: 100000 | F1005: 100000 | G1005: 0 | H1005: 46045 | I1005: 01. Jan 2026
A1006: =IF(B1006="","",ROW()-4) -> 1002 | B1006: Muhammad Ade Faizal | C1006: =IF(B1006="","",IF(COUNTIF('01_Anggota'!$D$5:$D$1212,B1006)=0,"NAMA TIDAK DITEMUKAN",INDEX('01_Anggota'!$B$5:$B$1212,MATCH(B1006,'01_Anggota'!$D$5:$D$1212,0)))) -> KKSUK-000145 | D1006: 0 | E1006: 100000 | F1006: 100000 | G1006: 0 | H1006: 46078 | I1006: 02. Feb 2026
A1007: =IF(B1007="","",ROW()-4) -> 1003 | B1007: Muhammad Ade Faizal | C1007: =IF(B1007="","",IF(COUNTIF('01_Anggota'!$D$5:$D$1212,B1007)=0,"NAMA TIDAK DITEMUKAN",INDEX('01_Anggota'!$B$5:$B$1212,MATCH(B1007,'01_Anggota'!$D$5:$D$1212,0)))) -> KKSUK-000145 | D1007: 0 | E1007: 100000 | F1007: 100000 | G1007: 0 | H1007: 46106 | I1007: 03. Mar 2026
... A1739: =IF(B1739="","",ROW()-4) -> 1735 | B1739: Zalu Febri Lesmana | C1739: =IF(B1739="","",IF(COUNTIF('01_Anggota'!$D$5:$D$1212,B1739)=0,"NAMA TIDAK DITEMUKAN",INDEX('01_Anggota'!$B$5:$B$1212,MATCH(B1739,'01_Anggota'!$D$5:$D$1212,0)))) -> KKSUK-000188 | D1739: 0 | E1739: 200000 | F1739: 100000 | G1739: 0 | H1739: 46258 | I1739: 08. Agu 2026

Sheet 04_Pinjaman
A1: Data pinjaman
A2: Satu baris untuk setiap pinjaman. Buat Nomor Pinjaman yang unik agar angsuran dapat disambungkan.
A4: No Pinjaman * | B4: Nama Anggota * | C4: NPP (otomatis) | D4: Jenis Pinjaman * | E4: Pokok (Rp) * | F4: Admin (Rp) | G4: Total Kewajiban (Rp) * | H4: Lama Cicilan (Bulan) * | I4: Tanggal Cair * | J4: Status * | K4: Catatan
A5: 1 | B5: Abdul Cahyo Nugroho | C5: =IF(B5="","",IF(COUNTIF('01_Anggota'!$D$5:$D$1212,B5)=0,"NAMA TIDAK DITEMUKAN",INDEX('01_Anggota'!$B$5:$B$1212,MATCH(B5,'01_Anggota'!$D$5:$D$1212,0)))) -> KKSUK-000001 | D5: Reguler | E5: 6000000 | F5: 600000 | G5: =PinjamanTable[[#This Row],[Pokok (Rp) *]]+PinjamanTable[[#This Row],[Admin (Rp)]] -> 6600000 | H5: 10 | I5: 46022 | J5: Berjalan
A6: 2 | B6: Abdul Cahyo Nugroho | C6: =IF(B6="","",IF(COUNTIF('01_Anggota'!$D$5:$D$1212,B6)=0,"NAMA TIDAK DITEMUKAN",INDEX('01_Anggota'!$B$5:$B$1212,MATCH(B6,'01_Anggota'!$D$5:$D$1212,0)))) -> KKSUK-000001 | D6: Reguler | E6: 3000000 | F6: 30000 | G6: =PinjamanTable[[#This Row],[Pokok (Rp) *]]+PinjamanTable[[#This Row],[Admin (Rp)]] -> 3030000 | H6: 1 | I6: 46141 | J6: Lunas
A7: 3 | B7: Ade Kurnia | C7: =IF(B7="","",IF(COUNTIF('01_Anggota'!$D$5:$D$1212,B7)=0,"NAMA TIDAK DITEMUKAN",INDEX('01_Anggota'!$B$5:$B$1212,MATCH(B7,'01_Anggota'!$D$5:$D$1212,0)))) -> KKSUK-000120 | D7: Reguler | E7: 800000 | F7: 80000 | G7: =PinjamanTable[[#This Row],[Pokok (Rp) *]]+PinjamanTable[[#This Row],[Admin (Rp)]] -> 880000 | H7: 1 | I7: 46022 | J7: Lunas
A8: 4 | B8: Ade Kurnia | C8: =IF(B8="","",IF(COUNTIF('01_Anggota'!$D$5:$D$1212,B8)=0,"NAMA TIDAK DITEMUKAN",INDEX('01_Anggota'!$B$5:$B$1212,MATCH(B8,'01_Anggota'!$D$5:$D$1212,0)))) -> KKSUK-000120 | D8: Reguler | E8: 3000000 | F8: 300000 | G8: =PinjamanTable[[#This Row],[Pokok (Rp) *]]+PinjamanTable[[#This Row],[Admin (Rp)]] -> 3300000 | H8: 10 | I8: 46038 | J8: Lunas
A9: 5 | B9: Ade Kurnia | C9: =IF(B9="","",IF(COUNTIF('01_Anggota'!$D$5:$D$1212,B9)=0,"NAMA TIDAK DITEMUKAN",INDEX('01_Anggota'!$B$5:$B$1212,MATCH(B9,'01_Anggota'!$D$5:$D$1212,0)))) -> KKSUK-000120 | D9: Reguler | E9: 5000000 | F9: 500000 | G9: =PinjamanTable[[#This Row],[Pokok (Rp) *]]+PinjamanTable[[#This Row],[Admin (Rp)]] -> 5500000 | H9: 10 | I9: 46176 | J9: Berjalan
A10: 6 | B10: Agung Pambudi | C10: =IF(B10="","",IF(COUNTIF('01_Anggota'!$D$5:$D$1212,B10)=0,"NAMA TIDAK DITEMUKAN",INDEX('01_Anggota'!$B$5:$B$1212,MATCH(B10,'01_Anggota'!$D$5:$D$1212,0)))) -> KKSUK-000067 | D10: Reguler | E10: 6400000 | F10: 768000 | G10: =PinjamanTable[[#This Row],[Pokok (Rp) *]]+PinjamanTable[[#This Row],[Admin (Rp)]] -> 7168000 | H10: 12 | I10: 45945 | J10: Berjalan
A11: 7 | B11: Ahmad Fauzi - 01743 | C11: =IF(B11="","",IF(COUNTIF('01_Anggota'!$D$5:$D$1212,B11)=0,"NAMA TIDAK DITEMUKAN",INDEX('01_Anggota'!$B$5:$B$1212,MATCH(B11,'01_Anggota'!$D$5:$D$1212,0)))) -> KKSUK-000144 | D11: Reguler | E11: 700000 | F11: 14000 | G11: =PinjamanTable[[#This Row],[Pokok (Rp) *]]+PinjamanTable[[#This Row],[Admin (Rp)]] -> 714000 | H11: 2 | I11: 46062 | J11: Lunas
A12: 8 | B12: Ahmad Fauzi - 01743 | C12: =IF(B12="","",IF(COUNTIF('01_Anggota'!$D$5:$D$1212,B12)=0,"NAMA TIDAK DITEMUKAN",INDEX('01_Anggota'!$B$5:$B$1212,MATCH(B12,'01_Anggota'!$D$5:$D$1212,0)))) -> KKSUK-000144 | D12: Reguler | E12: 3000000 | F12: 210000 | G12: =PinjamanTable[[#This Row],[Pokok (Rp) *]]+PinjamanTable[[#This Row],[Admin (Rp)]] -> 3210000 | H12: 7 | I12: 46182 | J12: Berjalan
A13: 9 | B13: Ahmad Jamaludin | C13: =IF(B13="","",IF(COUNTIF('01_Anggota'!$D$5:$D$1212,B13)=0,"NAMA TIDAK DITEMUKAN",INDEX('01_Anggota'!$B$5:$B$1212,MATCH(B13,'01_Anggota'!$D$5:$D$1212,0)))) -> KKSUK-000129 | D13: Reguler | E13: 25000000 | F13: 400000 | G13: =PinjamanTable[[#This Row],[Pokok (Rp) *]]+PinjamanTable[[#This Row],[Admin (Rp)]] -> 25400000 | H13: 14 | I13: 45709 | J13: Lunas
A14: 10 | B14: Ahmat Saifudin | C14: =IF(B14="","",IF(COUNTIF('01_Anggota'!$D$5:$D$1212,B14)=0,"NAMA TIDAK DITEMUKAN",INDEX('01_Anggota'!$B$5:$B$1212,MATCH(B14,'01_Anggota'!$D$5:$D$1212,0)))) -> KKSUK-000127 | D14: Reguler | E14: 3000000 | F14: 210000 | G14: =PinjamanTable[[#This Row],[Pokok (Rp) *]]+PinjamanTable[[#This Row],[Admin (Rp)]] -> 3210000 | H14: 7 | I14: 45820 | J14: Lunas
A15: 11 | B15: Ahmat Saifudin | C15: =IF(B15="","",IF(COUNTIF('01_Anggota'!$D$5:$D$1212,B15)=0,"NAMA TIDAK DITEMUKAN",INDEX('01_Anggota'!$B$5:$B$1212,MATCH(B15,'01_Anggota'!$D$5:$D$1212,0)))) -> KKSUK-000127 | D15: Reguler | E15: 3500000 | F15: 210000 | G15: =PinjamanTable[[#This Row],[Pokok (Rp) *]]+PinjamanTable[[#This Row],[Admin (Rp)]] -> 3710000 | H15: 6 | I15: 46055 | J15: Lunas
A16: 12 | B16: Ahmat Saifudin | C16: =IF(B16="","",IF(COUNTIF('01_Anggota'!$D$5:$D$1212,B16)=0,"NAMA TIDAK DITEMUKAN",INDEX('01_Anggota'!$B$5:$B$1212,MATCH(B16,'01_Anggota'!$D$5:$D$1212,0)))) -> KKSUK-000127 | D16: Reguler | E16: 5000000 | F16: 400000 | G16: =PinjamanTable[[#This Row],[Pokok (Rp) *]]+PinjamanTable[[#This Row],[Admin (Rp)]] -> 5400000 | H16: 8 | I16: 46233 | J16: Berjalan
... A43: 39 | B43: Eddy Sukaryan | C43: =IF(B43="","",IF(COUNTIF('01_Anggota'!$D$5:$D$1212,B43)=0,"NAMA TIDAK DITEMUKAN",INDEX('01_Anggota'!$B$5:$B$1212,MATCH(B43,'01_Anggota'!$D$5:$D$1212,0)))) -> KKSUK-000070 | D43: Reguler | E43: 57787193 | F43: 17803389 | G43: =PinjamanTable[[#This Row],[Pokok (Rp) *]]+PinjamanTable[[#This Row],[Admin (Rp)]] -> 75590582 | H43: 24 | I43: 45943 | J43: Berjalan
A44: 40 | B44: Eddy Sukaryan | C44: =IF(B44="","",IF(COUNTIF('01_Anggota'!$D$5:$D$1212,B44)=0,"NAMA TIDAK DITEMUKAN",INDEX('01_Anggota'!$B$5:$B$1212,MATCH(B44,'01_Anggota'!$D$5:$D$1212,0)))) -> KKSUK-000070 | D44: Reguler | E44: 47716469 | F44: 7157470 | G44: =PinjamanTable[[#This Row],[Pokok (Rp) *]]+PinjamanTable[[#This Row],[Admin (Rp)]] -> 54873939 | H44: 1 | I44: 46182 | J44: Berjalan | K44: Dipotong saat Pensiun
A45: 41 | B45: Eka Yanuar Santosa | C45: =IF(B45="","",IF(COUNTIF('01_Anggota'!$D$5:$D$1212,B45)=0,"NAMA TIDAK DITEMUKAN",INDEX('01_Anggota'!$B$5:$B$1212,MATCH(B45,'01_Anggota'!$D$5:$D$1212,0)))) -> KKSUK-000013 | D45: Reguler | E45: 25000000 | F45: 2500000 | G45: =PinjamanTable[[#This Row],[Pokok (Rp) *]]+PinjamanTable[[#This Row],[Admin (Rp)]] -> 27500000 | H45: 10 | I45: 45764 | J45: Lunas
A46: 42 | B46: Eka Yanuar Santosa | C46: =IF(B46="","",IF(COUNTIF('01_Anggota'!$D$5:$D$1212,B46)=0,"NAMA TIDAK DITEMUKAN",INDEX('01_Anggota'!$B$5:$B$1212,MATCH(B46,'01_Anggota'!$D$5:$D$1212,0)))) -> KKSUK-000013 | D46: Reguler | E46: 30000000 | F46: 4875000 | G46: =PinjamanTable[[#This Row],[Pokok (Rp) *]]+PinjamanTable[[#This Row],[Admin (Rp)]] -> 34875000 | H46: 15 | I46: 46108 | J46: Berjalan
A47: 43 | B47: Eko Junaidi | C47: =IF(B47="","",IF(COUNTIF('01_Anggota'!$D$5:$D$1212,B47)=0,"NAMA TIDAK DITEMUKAN",INDEX('01_Anggota'!$B$5:$B$1212,MATCH(B47,'01_Anggota'!$D$5:$D$1212,0)))) -> KKSUK-000071 | D47: Reguler | E47: 15000000 | F47: 1500000 | G47: =PinjamanTable[[#This Row],[Pokok (Rp) *]]+PinjamanTable[[#This Row],[Admin (Rp)]] -> 16500000 | H47: 10 | I47: 45985 | J47: Berjalan
A48: 44 | B48: Erfan Faulana | C48: =IF(B48="","",IF(COUNTIF('01_Anggota'!$D$5:$D$1212,B48)=0,"NAMA TIDAK DITEMUKAN",INDEX('01_Anggota'!$B$5:$B$1212,MATCH(B48,'01_Anggota'!$D$5:$D$1212,0)))) -> KKSUK-000152 | D48: Reguler | E48: 2000000 | F48: 100000 | G48: =PinjamanTable[[#This Row],[Pokok (Rp) *]]+PinjamanTable[[#This Row],[Admin (Rp)]] -> 2100000 | H48: 10 | I48: 45959 | J48: Lunas
A49: 45 | B49: Erfan Faulana | C49: =IF(B49="","",IF(COUNTIF('01_Anggota'!$D$5:$D$1212,B49)=0,"NAMA TIDAK DITEMUKAN",INDEX('01_Anggota'!$B$5:$B$1212,MATCH(B49,'01_Anggota'!$D$5:$D$1212,0)))) -> KKSUK-000152 | D49: Reguler | E49: 4000000 | F49: 240000 | G49: =PinjamanTable[[#This Row],[Pokok (Rp) *]]+PinjamanTable[[#This Row],[Admin (Rp)]] -> 4240000 | H49: 6 | I49: 46030 | J49: Lunas
A50: 46 | B50: Erfan Faulana | C50: =IF(B50="","",IF(COUNTIF('01_Anggota'!$D$5:$D$1212,B50)=0,"NAMA TIDAK DITEMUKAN",INDEX('01_Anggota'!$B$5:$B$1212,MATCH(B50,'01_Anggota'!$D$5:$D$1212,0)))) -> KKSUK-000152 | D50: Reguler | E50: 6000000 | F50: 600000 | G50: =PinjamanTable[[#This Row],[Pokok (Rp) *]]+PinjamanTable[[#This Row],[Admin (Rp)]] -> 6600000 | H50: 10 | I50: 46161 | J50: Berjalan
A51: 47 | B51: Fajar Bintara | C51: =IF(B51="","",IF(COUNTIF('01_Anggota'!$D$5:$D$1212,B51)=0,"NAMA TIDAK DITEMUKAN",INDEX('01_Anggota'!$B$5:$B$1212,MATCH(B51,'01_Anggota'!$D$5:$D$1212,0)))) -> KKSUK-000175 | D51: Reguler | E51: 3520000 | F51: 0 | G51: =PinjamanTable[[#This Row],[Pokok (Rp) *]]+PinjamanTable[[#This Row],[Admin (Rp)]] -> 3520000 | H51: 3 | I51: 46022 | J51: Lunas
A52: 48 | B52: Fellix Stephen Willa | C52: =IF(B52="","",IF(COUNTIF('01_Anggota'!$D$5:$D$1212,B52)=0,"NAMA TIDAK DITEMUKAN",INDEX('01_Anggota'!$B$5:$B$1212,MATCH(B52,'01_Anggota'!$D$5:$D$1212,0)))) -> KKSUK-000061 | D52: Reguler | E52: 50000000 | F52: 12500000 | G52: =PinjamanTable[[#This Row],[Pokok (Rp) *]]+PinjamanTable[[#This Row],[Admin (Rp)]] -> 62500000 | H52: 24 | I52: 45992 | J52: Lunas
A53: 49 | B53: Fellix Stephen Willa | C53: =IF(B53="","",IF(COUNTIF('01_Anggota'!$D$5:$D$1212,B53)=0,"NAMA TIDAK DITEMUKAN",INDEX('01_Anggota'!$B$5:$B$1212,MATCH(B53,'01_Anggota'!$D$5:$D$1212,0)))) -> KKSUK-000061 | D53: Reguler | E53: 56000000 | F53: 17160000 | G53: =PinjamanTable[[#This Row],[Pokok (Rp) *]]+PinjamanTable[[#This Row],[Admin (Rp)]] -> 73160000 | H53: 24 | I53: 46261 | J53: Berjalan
A54: 50 | B54: Ferry Firmanto | C54: =IF(B54="","",IF(COUNTIF('01_Anggota'!$D$5:$D$1212,B54)=0,"NAMA TIDAK DITEMUKAN",INDEX('01_Anggota'!$B$5:$B$1212,MATCH(B54,'01_Anggota'!$D$5:$D$1212,0)))) -> KKSUK-000055 | D54: Reguler | E54: 38231670 | F54: 0 | G54: =PinjamanTable[[#This Row],[Pokok (Rp) *]]+PinjamanTable[[#This Row],[Admin (Rp)]] -> 38231670 | H54: 24 | I54: 46022 | J54: Lunas
A55: 51 | B55: Ferry Firmanto | C55: =IF(B55="","",IF(COUNTIF('01_Anggota'!$D$5:$D$1212,B55)=0,"NAMA TIDAK DITEMUKAN",INDEX('01_Anggota'!$B$5:$B$1212,MATCH(B55,'01_Anggota'!$D$5:$D$1212,0)))) -> KKSUK-000055 | D55: Reguler | E55: 50000000 | F55: 15000000 | G55: =PinjamanTable[[#This Row],[Pokok (Rp) *]]+PinjamanTable[[#This Row],[Admin (Rp)]] -> 65000000 | H55: 24 | I55: 46045 | J55: Berjalan
A56: 52 | B56: Ferry Firmanto | C56: =IF(B56="","",IF(COUNTIF('01_Anggota'!$D$5:$D$1212,B56)=0,"NAMA TIDAK DITEMUKAN",INDEX('01_Anggota'!$B$5:$B$1212,MATCH(B56,'01_Anggota'!$D$5:$D$1212,0)))) -> KKSUK-000055 | D56: Reguler | E56: 12000000 | F56: 4320000 | G56: =PinjamanTable[[#This Row],[Pokok (Rp) *]]+PinjamanTable[[#This Row],[Admin (Rp)]] -> 16320000 | H56: 24 | I56: 46245 | J56: Berjalan
... A81: 77 | B81: Indra Suwanda | C81: =IF(B81="","",IF(COUNTIF('01_Anggota'!$D$5:$D$1212,B81)=0,"NAMA TIDAK DITEMUKAN",INDEX('01_Anggota'!$B$5:$B$1212,MATCH(B81,'01_Anggota'!$D$5:$D$1212,0)))) -> KKSUK-000021 | D81: Reguler | E81: 3000000 | F81: 180000 | G81: =PinjamanTable[[#This Row],[Pokok (Rp) *]]+PinjamanTable[[#This Row],[Admin (Rp)]] -> 3180000 | H81: 6 | I81: 45987 | J81: Lunas
C82: =IF(B82="","",IF(COUNTIF('01_Anggota'!$D$5:$D$1212,B82)=0,"NAMA TIDAK DITEMUKAN",INDEX('01_Anggota'!$B$5:$B$1212,MATCH(B82,'01_Anggota'!$D$5:$D$1212,0)))) | G82: =PinjamanTable[[#This Row],[Pokok (Rp) *]]+PinjamanTable[[#This Row],[Admin (Rp)]] -> 0
C83: =IF(B83="","",IF(COUNTIF('01_Anggota'!$D$5:$D$1212,B83)=0,"NAMA TIDAK DITEMUKAN",INDEX('01_Anggota'!$B$5:$B$1212,MATCH(B83,'01_Anggota'!$D$5:$D$1212,0)))) | G83: =PinjamanTable[[#This Row],[Pokok (Rp) *]]+PinjamanTable[[#This Row],[Admin (Rp)]] -> 0
C84: =IF(B84="","",IF(COUNTIF('01_Anggota'!$D$5:$D$1212,B84)=0,"NAMA TIDAK DITEMUKAN",INDEX('01_Anggota'!$B$5:$B$1212,MATCH(B84,'01_Anggota'!$D$5:$D$1212,0)))) | G84: =PinjamanTable[[#This Row],[Pokok (Rp) *]]+PinjamanTable[[#This Row],[Admin (Rp)]] -> 0
C85: =IF(B85="","",IF(COUNTIF('01_Anggota'!$D$5:$D$1212,B85)=0,"NAMA TIDAK DITEMUKAN",INDEX('01_Anggota'!$B$5:$B$1212,MATCH(B85,'01_Anggota'!$D$5:$D$1212,0)))) | G85: =PinjamanTable[[#This Row],[Pokok (Rp) *]]+PinjamanTable[[#This Row],[Admin (Rp)]] -> 0
C86: =IF(B86="","",IF(COUNTIF('01_Anggota'!$D$5:$D$1212,B86)=0,"NAMA TIDAK DITEMUKAN",INDEX('01_Anggota'!$B$5:$B$1212,MATCH(B86,'01_Anggota'!$D$5:$D$1212,0)))) | G86: =PinjamanTable[[#This Row],[Pokok (Rp) *]]+PinjamanTable[[#This Row],[Admin (Rp)]] -> 0
C87: =IF(B87="","",IF(COUNTIF('01_Anggota'!$D$5:$D$1212,B87)=0,"NAMA TIDAK DITEMUKAN",INDEX('01_Anggota'!$B$5:$B$1212,MATCH(B87,'01_Anggota'!$D$5:$D$1212,0)))) | G87: =PinjamanTable[[#This Row],[Pokok (Rp) *]]+PinjamanTable[[#This Row],[Admin (Rp)]] -> 0
C88: =IF(B88="","",IF(COUNTIF('01_Anggota'!$D$5:$D$1212,B88)=0,"NAMA TIDAK DITEMUKAN",INDEX('01_Anggota'!$B$5:$B$1212,MATCH(B88,'01_Anggota'!$D$5:$D$1212,0)))) | G88: =PinjamanTable[[#This Row],[Pokok (Rp) *]]+PinjamanTable[[#This Row],[Admin (Rp)]] -> 0
C89: =IF(B89="","",IF(COUNTIF('01_Anggota'!$D$5:$D$1212,B89)=0,"NAMA TIDAK DITEMUKAN",INDEX('01_Anggota'!$B$5:$B$1212,MATCH(B89,'01_Anggota'!$D$5:$D$1212,0)))) | G89: =PinjamanTable[[#This Row],[Pokok (Rp) *]]+PinjamanTable[[#This Row],[Admin (Rp)]] -> 0
C90: =IF(B90="","",IF(COUNTIF('01_Anggota'!$D$5:$D$1212,B90)=0,"NAMA TIDAK DITEMUKAN",INDEX('01_Anggota'!$B$5:$B$1212,MATCH(B90,'01_Anggota'!$D$5:$D$1212,0)))) | G90: =PinjamanTable[[#This Row],[Pokok (Rp) *]]+PinjamanTable[[#This Row],[Admin (Rp)]] -> 0
C91: =IF(B91="","",IF(COUNTIF('01_Anggota'!$D$5:$D$1212,B91)=0,"NAMA TIDAK DITEMUKAN",INDEX('01_Anggota'!$B$5:$B$1212,MATCH(B91,'01_Anggota'!$D$5:$D$1212,0)))) | G91: =PinjamanTable[[#This Row],[Pokok (Rp) *]]+PinjamanTable[[#This Row],[Admin (Rp)]] -> 0
...

Sheet 05_Angsuran
A1: Data angsuran
A2: Satu baris untuk setiap pembayaran. Pilih No Pinjaman dari daftar.
A4: No Angsuran (otomatis) | B4: No Pinjaman * | C4: Nama Anggota (otomatis) | D4: NPP (otomatis) | E4: Tanggal * | F4: Jumlah (Rp) * | G4: Catatan
A5: =IF(B5="","",ROW()-4) -> 1 | B5: 1 | C5: =IF(B5="","",IF(COUNTIF('04_Pinjaman'!$A$5:$A$1004,B5)=0,"NO PINJAMAN TIDAK DITEMUKAN",INDEX('04_Pinjaman'!$B$5:$B$1004,MATCH(B5,'04_Pinjaman'!$A$5:$A$1004,0)))) -> Abdul Cahyo Nugroho | D5: =IF(B5="","",IF(COUNTIF('04_Pinjaman'!$A$5:$A$1004,B5)=0,"NPP TIDAK DITEMUKAN",INDEX('04_Pinjaman'!$C$5:$C$1004,MATCH(B5,'04_Pinjaman'!$A$5:$A$1004,0)))) -> KKSUK-000001 | E5: 46045 | F5: 660000
A6: =IF(B6="","",ROW()-4) -> 2 | B6: 1 | C6: =IF(B6="","",IF(COUNTIF('04_Pinjaman'!$A$5:$A$1004,B6)=0,"NO PINJAMAN TIDAK DITEMUKAN",INDEX('04_Pinjaman'!$B$5:$B$1004,MATCH(B6,'04_Pinjaman'!$A$5:$A$1004,0)))) -> Abdul Cahyo Nugroho | D6: =IF(B6="","",IF(COUNTIF('04_Pinjaman'!$A$5:$A$1004,B6)=0,"NPP TIDAK DITEMUKAN",INDEX('04_Pinjaman'!$C$5:$C$1004,MATCH(B6,'04_Pinjaman'!$A$5:$A$1004,0)))) -> KKSUK-000001 | E6: 46078 | F6: 660000
A7: =IF(B7="","",ROW()-4) -> 3 | B7: 1 | C7: =IF(B7="","",IF(COUNTIF('04_Pinjaman'!$A$5:$A$1004,B7)=0,"NO PINJAMAN TIDAK DITEMUKAN",INDEX('04_Pinjaman'!$B$5:$B$1004,MATCH(B7,'04_Pinjaman'!$A$5:$A$1004,0)))) -> Abdul Cahyo Nugroho | D7: =IF(B7="","",IF(COUNTIF('04_Pinjaman'!$A$5:$A$1004,B7)=0,"NPP TIDAK DITEMUKAN",INDEX('04_Pinjaman'!$C$5:$C$1004,MATCH(B7,'04_Pinjaman'!$A$5:$A$1004,0)))) -> KKSUK-000001 | E7: 46106 | F7: 660000
A8: =IF(B8="","",ROW()-4) -> 4 | B8: 1 | C8: =IF(B8="","",IF(COUNTIF('04_Pinjaman'!$A$5:$A$1004,B8)=0,"NO PINJAMAN TIDAK DITEMUKAN",INDEX('04_Pinjaman'!$B$5:$B$1004,MATCH(B8,'04_Pinjaman'!$A$5:$A$1004,0)))) -> Abdul Cahyo Nugroho | D8: =IF(B8="","",IF(COUNTIF('04_Pinjaman'!$A$5:$A$1004,B8)=0,"NPP TIDAK DITEMUKAN",INDEX('04_Pinjaman'!$C$5:$C$1004,MATCH(B8,'04_Pinjaman'!$A$5:$A$1004,0)))) -> KKSUK-000001 | E8: 46136 | F8: 660000
A9: =IF(B9="","",ROW()-4) -> 5 | B9: 1 | C9: =IF(B9="","",IF(COUNTIF('04_Pinjaman'!$A$5:$A$1004,B9)=0,"NO PINJAMAN TIDAK DITEMUKAN",INDEX('04_Pinjaman'!$B$5:$B$1004,MATCH(B9,'04_Pinjaman'!$A$5:$A$1004,0)))) -> Abdul Cahyo Nugroho | D9: =IF(B9="","",IF(COUNTIF('04_Pinjaman'!$A$5:$A$1004,B9)=0,"NPP TIDAK DITEMUKAN",INDEX('04_Pinjaman'!$C$5:$C$1004,MATCH(B9,'04_Pinjaman'!$A$5:$A$1004,0)))) -> KKSUK-000001 | E9: 46167 | F9: 660000
A10: =IF(B10="","",ROW()-4) -> 6 | B10: 2 | C10: =IF(B10="","",IF(COUNTIF('04_Pinjaman'!$A$5:$A$1004,B10)=0,"NO PINJAMAN TIDAK DITEMUKAN",INDEX('04_Pinjaman'!$B$5:$B$1004,MATCH(B10,'04_Pinjaman'!$A$5:$A$1004,0)))) -> Abdul Cahyo Nugroho | D10: =IF(B10="","",IF(COUNTIF('04_Pinjaman'!$A$5:$A$1004,B10)=0,"NPP TIDAK DITEMUKAN",INDEX('04_Pinjaman'!$C$5:$C$1004,MATCH(B10,'04_Pinjaman'!$A$5:$A$1004,0)))) -> KKSUK-000001 | E10: 46198 | F10: 3030000
A11: =IF(B11="","",ROW()-4) -> 7 | B11: 1 | C11: =IF(B11="","",IF(COUNTIF('04_Pinjaman'!$A$5:$A$1004,B11)=0,"NO PINJAMAN TIDAK DITEMUKAN",INDEX('04_Pinjaman'!$B$5:$B$1004,MATCH(B11,'04_Pinjaman'!$A$5:$A$1004,0)))) -> Abdul Cahyo Nugroho | D11: =IF(B11="","",IF(COUNTIF('04_Pinjaman'!$A$5:$A$1004,B11)=0,"NPP TIDAK DITEMUKAN",INDEX('04_Pinjaman'!$C$5:$C$1004,MATCH(B11,'04_Pinjaman'!$A$5:$A$1004,0)))) -> KKSUK-000001 | E11: 46198 | F11: 660000
A12: =IF(B12="","",ROW()-4) -> 8 | B12: 1 | C12: =IF(B12="","",IF(COUNTIF('04_Pinjaman'!$A$5:$A$1004,B12)=0,"NO PINJAMAN TIDAK DITEMUKAN",INDEX('04_Pinjaman'!$B$5:$B$1004,MATCH(B12,'04_Pinjaman'!$A$5:$A$1004,0)))) -> Abdul Cahyo Nugroho | D12: =IF(B12="","",IF(COUNTIF('04_Pinjaman'!$A$5:$A$1004,B12)=0,"NPP TIDAK DITEMUKAN",INDEX('04_Pinjaman'!$C$5:$C$1004,MATCH(B12,'04_Pinjaman'!$A$5:$A$1004,0)))) -> KKSUK-000001 | E12: 46227 | F12: 660000
A13: =IF(B13="","",ROW()-4) -> 9 | B13: 1 | C13: =IF(B13="","",IF(COUNTIF('04_Pinjaman'!$A$5:$A$1004,B13)=0,"NO PINJAMAN TIDAK DITEMUKAN",INDEX('04_Pinjaman'!$B$5:$B$1004,MATCH(B13,'04_Pinjaman'!$A$5:$A$1004,0)))) -> Abdul Cahyo Nugroho | D13: =IF(B13="","",IF(COUNTIF('04_Pinjaman'!$A$5:$A$1004,B13)=0,"NPP TIDAK DITEMUKAN",INDEX('04_Pinjaman'!$C$5:$C$1004,MATCH(B13,'04_Pinjaman'!$A$5:$A$1004,0)))) -> KKSUK-000001 | E13: 46258 | F13: 660000
A14: =IF(B14="","",ROW()-4) -> 10 | B14: 3 | C14: =IF(B14="","",IF(COUNTIF('04_Pinjaman'!$A$5:$A$1004,B14)=0,"NO PINJAMAN TIDAK DITEMUKAN",INDEX('04_Pinjaman'!$B$5:$B$1004,MATCH(B14,'04_Pinjaman'!$A$5:$A$1004,0)))) -> Ade Kurnia | D14: =IF(B14="","",IF(COUNTIF('04_Pinjaman'!$A$5:$A$1004,B14)=0,"NPP TIDAK DITEMUKAN",INDEX('04_Pinjaman'!$C$5:$C$1004,MATCH(B14,'04_Pinjaman'!$A$5:$A$1004,0)))) -> KKSUK-000120 | E14: 46176 | F14: 880000 | G14: Pelunasan Karena Topup
A15: =IF(B15="","",ROW()-4) -> 11 | B15: 4 | C15: =IF(B15="","",IF(COUNTIF('04_Pinjaman'!$A$5:$A$1004,B15)=0,"NO PINJAMAN TIDAK DITEMUKAN",INDEX('04_Pinjaman'!$B$5:$B$1004,MATCH(B15,'04_Pinjaman'!$A$5:$A$1004,0)))) -> Ade Kurnia | D15: =IF(B15="","",IF(COUNTIF('04_Pinjaman'!$A$5:$A$1004,B15)=0,"NPP TIDAK DITEMUKAN",INDEX('04_Pinjaman'!$C$5:$C$1004,MATCH(B15,'04_Pinjaman'!$A$5:$A$1004,0)))) -> KKSUK-000120 | E15: 46078 | F15: 330000
A16: =IF(B16="","",ROW()-4) -> 12 | B16: 4 | C16: =IF(B16="","",IF(COUNTIF('04_Pinjaman'!$A$5:$A$1004,B16)=0,"NO PINJAMAN TIDAK DITEMUKAN",INDEX('04_Pinjaman'!$B$5:$B$1004,MATCH(B16,'04_Pinjaman'!$A$5:$A$1004,0)))) -> Ade Kurnia | D16: =IF(B16="","",IF(COUNTIF('04_Pinjaman'!$A$5:$A$1004,B16)=0,"NPP TIDAK DITEMUKAN",INDEX('04_Pinjaman'!$C$5:$C$1004,MATCH(B16,'04_Pinjaman'!$A$5:$A$1004,0)))) -> KKSUK-000120 | E16: 46106 | F16: 330000
A17: =IF(B17="","",ROW()-4) -> 13 | B17: 4 | C17: =IF(B17="","",IF(COUNTIF('04_Pinjaman'!$A$5:$A$1004,B17)=0,"NO PINJAMAN TIDAK DITEMUKAN",INDEX('04_Pinjaman'!$B$5:$B$1004,MATCH(B17,'04_Pinjaman'!$A$5:$A$1004,0)))) -> Ade Kurnia | D17: =IF(B17="","",IF(COUNTIF('04_Pinjaman'!$A$5:$A$1004,B17)=0,"NPP TIDAK DITEMUKAN",INDEX('04_Pinjaman'!$C$5:$C$1004,MATCH(B17,'04_Pinjaman'!$A$5:$A$1004,0)))) -> KKSUK-000120 | E17: 46136 | F17: 330000
A18: =IF(B18="","",ROW()-4) -> 14 | B18: 4 | C18: =IF(B18="","",IF(COUNTIF('04_Pinjaman'!$A$5:$A$1004,B18)=0,"NO PINJAMAN TIDAK DITEMUKAN",INDEX('04_Pinjaman'!$B$5:$B$1004,MATCH(B18,'04_Pinjaman'!$A$5:$A$1004,0)))) -> Ade Kurnia | D18: =IF(B18="","",IF(COUNTIF('04_Pinjaman'!$A$5:$A$1004,B18)=0,"NPP TIDAK DITEMUKAN",INDEX('04_Pinjaman'!$C$5:$C$1004,MATCH(B18,'04_Pinjaman'!$A$5:$A$1004,0)))) -> KKSUK-000120 | E18: 46167 | F18: 330000
A19: =IF(B19="","",ROW()-4) -> 15 | B19: 4 | C19: =IF(B19="","",IF(COUNTIF('04_Pinjaman'!$A$5:$A$1004,B19)=0,"NO PINJAMAN TIDAK DITEMUKAN",INDEX('04_Pinjaman'!$B$5:$B$1004,MATCH(B19,'04_Pinjaman'!$A$5:$A$1004,0)))) -> Ade Kurnia | D19: =IF(B19="","",IF(COUNTIF('04_Pinjaman'!$A$5:$A$1004,B19)=0,"NPP TIDAK DITEMUKAN",INDEX('04_Pinjaman'!$C$5:$C$1004,MATCH(B19,'04_Pinjaman'!$A$5:$A$1004,0)))) -> KKSUK-000120 | E19: 46176 | F19: 2860000 | G19: Pelunasan Karena Topup
A20: =IF(B20="","",ROW()-4) -> 16 | B20: 5 | C20: =IF(B20="","",IF(COUNTIF('04_Pinjaman'!$A$5:$A$1004,B20)=0,"NO PINJAMAN TIDAK DITEMUKAN",INDEX('04_Pinjaman'!$B$5:$B$1004,MATCH(B20,'04_Pinjaman'!$A$5:$A$1004,0)))) -> Ade Kurnia | D20: =IF(B20="","",IF(COUNTIF('04_Pinjaman'!$A$5:$A$1004,B20)=0,"NPP TIDAK DITEMUKAN",INDEX('04_Pinjaman'!$C$5:$C$1004,MATCH(B20,'04_Pinjaman'!$A$5:$A$1004,0)))) -> KKSUK-000120 | E20: 46227 | F20: 550000
A21: =IF(B21="","",ROW()-4) -> 17 | B21: 5 | C21: =IF(B21="","",IF(COUNTIF('04_Pinjaman'!$A$5:$A$1004,B21)=0,"NO PINJAMAN TIDAK DITEMUKAN",INDEX('04_Pinjaman'!$B$5:$B$1004,MATCH(B21,'04_Pinjaman'!$A$5:$A$1004,0)))) -> Ade Kurnia | D21: =IF(B21="","",IF(COUNTIF('04_Pinjaman'!$A$5:$A$1004,B21)=0,"NPP TIDAK DITEMUKAN",INDEX('04_Pinjaman'!$C$5:$C$1004,MATCH(B21,'04_Pinjaman'!$A$5:$A$1004,0)))) -> KKSUK-000120 | E21: 46258 | F21: 550000
A22: =IF(B22="","",ROW()-4) -> 18 | B22: 6 | C22: =IF(B22="","",IF(COUNTIF('04_Pinjaman'!$A$5:$A$1004,B22)=0,"NO PINJAMAN TIDAK DITEMUKAN",INDEX('04_Pinjaman'!$B$5:$B$1004,MATCH(B22,'04_Pinjaman'!$A$5:$A$1004,0)))) -> Agung Pambudi | D22: =IF(B22="","",IF(COUNTIF('04_Pinjaman'!$A$5:$A$1004,B22)=0,"NPP TIDAK DITEMUKAN",INDEX('04_Pinjaman'!$C$5:$C$1004,MATCH(B22,'04_Pinjaman'!$A$5:$A$1004,0)))) -> KKSUK-000067 | E22: 46010 | F22: 597333
A23: =IF(B23="","",ROW()-4) -> 19 | B23: 6 | C23: =IF(B23="","",IF(COUNTIF('04_Pinjaman'!$A$5:$A$1004,B23)=0,"NO PINJAMAN TIDAK DITEMUKAN",INDEX('04_Pinjaman'!$B$5:$B$1004,MATCH(B23,'04_Pinjaman'!$A$5:$A$1004,0)))) -> Agung Pambudi | D23: =IF(B23="","",IF(COUNTIF('04_Pinjaman'!$A$5:$A$1004,B23)=0,"NPP TIDAK DITEMUKAN",INDEX('04_Pinjaman'!$C$5:$C$1004,MATCH(B23,'04_Pinjaman'!$A$5:$A$1004,0)))) -> KKSUK-000067 | E23: 46045 | F23: 597333
A24: =IF(B24="","",ROW()-4) -> 20 | B24: 6 | C24: =IF(B24="","",IF(COUNTIF('04_Pinjaman'!$A$5:$A$1004,B24)=0,"NO PINJAMAN TIDAK DITEMUKAN",INDEX('04_Pinjaman'!$B$5:$B$1004,MATCH(B24,'04_Pinjaman'!$A$5:$A$1004,0)))) -> Agung Pambudi | D24: =IF(B24="","",IF(COUNTIF('04_Pinjaman'!$A$5:$A$1004,B24)=0,"NPP TIDAK DITEMUKAN",INDEX('04_Pinjaman'!$C$5:$C$1004,MATCH(B24,'04_Pinjaman'!$A$5:$A$1004,0)))) -> KKSUK-000067 | E24: 46078 | F24: 597333
A25: =IF(B25="","",ROW()-4) -> 21 | B25: 6 | C25: =IF(B25="","",IF(COUNTIF('04_Pinjaman'!$A$5:$A$1004,B25)=0,"NO PINJAMAN TIDAK DITEMUKAN",INDEX('04_Pinjaman'!$B$5:$B$1004,MATCH(B25,'04_Pinjaman'!$A$5:$A$1004,0)))) -> Agung Pambudi | D25: =IF(B25="","",IF(COUNTIF('04_Pinjaman'!$A$5:$A$1004,B25)=0,"NPP TIDAK DITEMUKAN",INDEX('04_Pinjaman'!$C$5:$C$1004,MATCH(B25,'04_Pinjaman'!$A$5:$A$1004,0)))) -> KKSUK-000067 | E25: 46106 | F25: 597333
A26: =IF(B26="","",ROW()-4) -> 22 | B26: 6 | C26: =IF(B26="","",IF(COUNTIF('04_Pinjaman'!$A$5:$A$1004,B26)=0,"NO PINJAMAN TIDAK DITEMUKAN",INDEX('04_Pinjaman'!$B$5:$B$1004,MATCH(B26,'04_Pinjaman'!$A$5:$A$1004,0)))) -> Agung Pambudi | D26: =IF(B26="","",IF(COUNTIF('04_Pinjaman'!$A$5:$A$1004,B26)=0,"NPP TIDAK DITEMUKAN",INDEX('04_Pinjaman'!$C$5:$C$1004,MATCH(B26,'04_Pinjaman'!$A$5:$A$1004,0)))) -> KKSUK-000067 | E26: 46136 | F26: 597333
A27: =IF(B27="","",ROW()-4) -> 23 | B27: 6 | C27: =IF(B27="","",IF(COUNTIF('04_Pinjaman'!$A$5:$A$1004,B27)=0,"NO PINJAMAN TIDAK DITEMUKAN",INDEX('04_Pinjaman'!$B$5:$B$1004,MATCH(B27,'04_Pinjaman'!$A$5:$A$1004,0)))) -> Agung Pambudi | D27: =IF(B27="","",IF(COUNTIF('04_Pinjaman'!$A$5:$A$1004,B27)=0,"NPP TIDAK DITEMUKAN",INDEX('04_Pinjaman'!$C$5:$C$1004,MATCH(B27,'04_Pinjaman'!$A$5:$A$1004,0)))) -> KKSUK-000067 | E27: 46167 | F27: 597333
A28: =IF(B28="","",ROW()-4) -> 24 | B28: 6 | C28: =IF(B28="","",IF(COUNTIF('04_Pinjaman'!$A$5:$A$1004,B28)=0,"NO PINJAMAN TIDAK DITEMUKAN",INDEX('04_Pinjaman'!$B$5:$B$1004,MATCH(B28,'04_Pinjaman'!$A$5:$A$1004,0)))) -> Agung Pambudi | D28: =IF(B28="","",IF(COUNTIF('04_Pinjaman'!$A$5:$A$1004,B28)=0,"NPP TIDAK DITEMUKAN",INDEX('04_Pinjaman'!$C$5:$C$1004,MATCH(B28,'04_Pinjaman'!$A$5:$A$1004,0)))) -> KKSUK-000067 | E28: 46198 | F28: 597333
A29: =IF(B29="","",ROW()-4) -> 25 | B29: 6 | C29: =IF(B29="","",IF(COUNTIF('04_Pinjaman'!$A$5:$A$1004,B29)=0,"NO PINJAMAN TIDAK DITEMUKAN",INDEX('04_Pinjaman'!$B$5:$B$1004,MATCH(B29,'04_Pinjaman'!$A$5:$A$1004,0)))) -> Agung Pambudi | D29: =IF(B29="","",IF(COUNTIF('04_Pinjaman'!$A$5:$A$1004,B29)=0,"NPP TIDAK DITEMUKAN",INDEX('04_Pinjaman'!$C$5:$C$1004,MATCH(B29,'04_Pinjaman'!$A$5:$A$1004,0)))) -> KKSUK-000067 | E29: 46227 | F29: 597333
A30: =IF(B30="","",ROW()-4) -> 26 | B30: 6 | C30: =IF(B30="","",IF(COUNTIF('04_Pinjaman'!$A$5:$A$1004,B30)=0,"NO PINJAMAN TIDAK DITEMUKAN",INDEX('04_Pinjaman'!$B$5:$B$1004,MATCH(B30,'04_Pinjaman'!$A$5:$A$1004,0)))) -> Agung Pambudi | D30: =IF(B30="","",IF(COUNTIF('04_Pinjaman'!$A$5:$A$1004,B30)=0,"NPP TIDAK DITEMUKAN",INDEX('04_Pinjaman'!$C$5:$C$1004,MATCH(B30,'04_Pinjaman'!$A$5:$A$1004,0)))) -> KKSUK-000067 | E30: 46258 | F30: 597333
A31: =IF(B31="","",ROW()-4) -> 27 | B31: 7 | C31: =IF(B31="","",IF(COUNTIF('04_Pinjaman'!$A$5:$A$1004,B31)=0,"NO PINJAMAN TIDAK DITEMUKAN",INDEX('04_Pinjaman'!$B$5:$B$1004,MATCH(B31,'04_Pinjaman'!$A$5:$A$1004,0)))) -> Ahmad Fauzi - 01743 | D31: =IF(B31="","",IF(COUNTIF('04_Pinjaman'!$A$5:$A$1004,B31)=0,"NPP TIDAK DITEMUKAN",INDEX('04_Pinjaman'!$C$5:$C$1004,MATCH(B31,'04_Pinjaman'!$A$5:$A$1004,0)))) -> KKSUK-000144 | E31: 46106 | F31: 357000
... A56: =IF(B56="","",ROW()-4) -> 52 | B56: 10 | C56: =IF(B56="","",IF(COUNTIF('04_Pinjaman'!$A$5:$A$1004,B56)=0,"NO PINJAMAN TIDAK DITEMUKAN",INDEX('04_Pinjaman'!$B$5:$B$1004,MATCH(B56,'04_Pinjaman'!$A$5:$A$1004,0)))) -> Ahmat Saifudin | D56: =IF(B56="","",IF(COUNTIF('04_Pinjaman'!$A$5:$A$1004,B56)=0,"NPP TIDAK DITEMUKAN",INDEX('04_Pinjaman'!$C$5:$C$1004,MATCH(B56,'04_Pinjaman'!$A$5:$A$1004,0)))) -> KKSUK-000127 | E56: 46045 | F56: 458572
A57: =IF(B57="","",ROW()-4) -> 53 | B57: 10 | C57: =IF(B57="","",IF(COUNTIF('04_Pinjaman'!$A$5:$A$1004,B57)=0,"NO PINJAMAN TIDAK DITEMUKAN",INDEX('04_Pinjaman'!$B$5:$B$1004,MATCH(B57,'04_Pinjaman'!$A$5:$A$1004,0)))) -> Ahmat Saifudin | D57: =IF(B57="","",IF(COUNTIF('04_Pinjaman'!$A$5:$A$1004,B57)=0,"NPP TIDAK DITEMUKAN",INDEX('04_Pinjaman'!$C$5:$C$1004,MATCH(B57,'04_Pinjaman'!$A$5:$A$1004,0)))) -> KKSUK-000127 | E57: 46055 | F57: 458568 | G57: Pelunasan Karena Topup
A58: =IF(B58="","",ROW()-4) -> 54 | B58: 11 | C58: =IF(B58="","",IF(COUNTIF('04_Pinjaman'!$A$5:$A$1004,B58)=0,"NO PINJAMAN TIDAK DITEMUKAN",INDEX('04_Pinjaman'!$B$5:$B$1004,MATCH(B58,'04_Pinjaman'!$A$5:$A$1004,0)))) -> Ahmat Saifudin | D58: =IF(B58="","",IF(COUNTIF('04_Pinjaman'!$A$5:$A$1004,B58)=0,"NPP TIDAK DITEMUKAN",INDEX('04_Pinjaman'!$C$5:$C$1004,MATCH(B58,'04_Pinjaman'!$A$5:$A$1004,0)))) -> KKSUK-000127 | E58: 46106 | F58: 618333
A59: =IF(B59="","",ROW()-4) -> 55 | B59: 11 | C59: =IF(B59="","",IF(COUNTIF('04_Pinjaman'!$A$5:$A$1004,B59)=0,"NO PINJAMAN TIDAK DITEMUKAN",INDEX('04_Pinjaman'!$B$5:$B$1004,MATCH(B59,'04_Pinjaman'!$A$5:$A$1004,0)))) -> Ahmat Saifudin | D59: =IF(B59="","",IF(COUNTIF('04_Pinjaman'!$A$5:$A$1004,B59)=0,"NPP TIDAK DITEMUKAN",INDEX('04_Pinjaman'!$C$5:$C$1004,MATCH(B59,'04_Pinjaman'!$A$5:$A$1004,0)))) -> KKSUK-000127 | E59: 46136 | F59: 618333
A60: =IF(B60="","",ROW()-4) -> 56 | B60: 11 | C60: =IF(B60="","",IF(COUNTIF('04_Pinjaman'!$A$5:$A$1004,B60)=0,"NO PINJAMAN TIDAK DITEMUKAN",INDEX('04_Pinjaman'!$B$5:$B$1004,MATCH(B60,'04_Pinjaman'!$A$5:$A$1004,0)))) -> Ahmat Saifudin | D60: =IF(B60="","",IF(COUNTIF('04_Pinjaman'!$A$5:$A$1004,B60)=0,"NPP TIDAK DITEMUKAN",INDEX('04_Pinjaman'!$C$5:$C$1004,MATCH(B60,'04_Pinjaman'!$A$5:$A$1004,0)))) -> KKSUK-000127 | E60: 46167 | F60: 618333
A61: =IF(B61="","",ROW()-4) -> 57 | B61: 11 | C61: =IF(B61="","",IF(COUNTIF('04_Pinjaman'!$A$5:$A$1004,B61)=0,"NO PINJAMAN TIDAK DITEMUKAN",INDEX('04_Pinjaman'!$B$5:$B$1004,MATCH(B61,'04_Pinjaman'!$A$5:$A$1004,0)))) -> Ahmat Saifudin | D61: =IF(B61="","",IF(COUNTIF('04_Pinjaman'!$A$5:$A$1004,B61)=0,"NPP TIDAK DITEMUKAN",INDEX('04_Pinjaman'!$C$5:$C$1004,MATCH(B61,'04_Pinjaman'!$A$5:$A$1004,0)))) -> KKSUK-000127 | E61: 46198 | F61: 618333
A62: =IF(B62="","",ROW()-4) -> 58 | B62: 11 | C62: =IF(B62="","",IF(COUNTIF('04_Pinjaman'!$A$5:$A$1004,B62)=0,"NO PINJAMAN TIDAK DITEMUKAN",INDEX('04_Pinjaman'!$B$5:$B$1004,MATCH(B62,'04_Pinjaman'!$A$5:$A$1004,0)))) -> Ahmat Saifudin | D62: =IF(B62="","",IF(COUNTIF('04_Pinjaman'!$A$5:$A$1004,B62)=0,"NPP TIDAK DITEMUKAN",INDEX('04_Pinjaman'!$C$5:$C$1004,MATCH(B62,'04_Pinjaman'!$A$5:$A$1004,0)))) -> KKSUK-000127 | E62: 46227 | F62: 618333
A63: =IF(B63="","",ROW()-4) -> 59 | B63: 11 | C63: =IF(B63="","",IF(COUNTIF('04_Pinjaman'!$A$5:$A$1004,B63)=0,"NO PINJAMAN TIDAK DITEMUKAN",INDEX('04_Pinjaman'!$B$5:$B$1004,MATCH(B63,'04_Pinjaman'!$A$5:$A$1004,0)))) -> Ahmat Saifudin | D63: =IF(B63="","",IF(COUNTIF('04_Pinjaman'!$A$5:$A$1004,B63)=0,"NPP TIDAK DITEMUKAN",INDEX('04_Pinjaman'!$C$5:$C$1004,MATCH(B63,'04_Pinjaman'!$A$5:$A$1004,0)))) -> KKSUK-000127 | E63: 46258 | F63: 618335
A64: =IF(B64="","",ROW()-4) -> 60 | B64: 13 | C64: =IF(B64="","",IF(COUNTIF('04_Pinjaman'!$A$5:$A$1004,B64)=0,"NO PINJAMAN TIDAK DITEMUKAN",INDEX('04_Pinjaman'!$B$5:$B$1004,MATCH(B64,'04_Pinjaman'!$A$5:$A$1004,0)))) -> Alfian Noor | D64: =IF(B64="","",IF(COUNTIF('04_Pinjaman'!$A$5:$A$1004,B64)=0,"NPP TIDAK DITEMUKAN",INDEX('04_Pinjaman'!$C$5:$C$1004,MATCH(B64,'04_Pinjaman'!$A$5:$A$1004,0)))) -> KKSUK-000016 | E64: 46045 | F64: 4408333
A65: =IF(B65="","",ROW()-4) -> 61 | B65: 13 | C65: =IF(B65="","",IF(COUNTIF('04_Pinjaman'!$A$5:$A$1004,B65)=0,"NO PINJAMAN TIDAK DITEMUKAN",INDEX('04_Pinjaman'!$B$5:$B$1004,MATCH(B65,'04_Pinjaman'!$A$5:$A$1004,0)))) -> Alfian Noor | D65: =IF(B65="","",IF(COUNTIF('04_Pinjaman'!$A$5:$A$1004,B65)=0,"NPP TIDAK DITEMUKAN",INDEX('04_Pinjaman'!$C$5:$C$1004,MATCH(B65,'04_Pinjaman'!$A$5:$A$1004,0)))) -> KKSUK-000016 | E65: 46078 | F65: 4408333
...

Sheet 08_Pemeriksaan
A1: Pemeriksaan kelengkapan
A2: Angka merah menunjukkan data yang masih perlu diisi atau diputuskan.
A4: Yang diperiksa | B4: Jumlah | C4: Artinya | D4: Yang harus dilakukan
A5: Anggota tanpa NPP | B5: =SUMPRODUCT(--('01_Anggota'!$D$5:$D$1212<>""),--('01_Anggota'!$B$5:$B$1212="")) -> 0 | C5: Identitas belum lengkap | D5: Lengkapi 01_Anggota
A6: Anggota tanpa tanggal bergabung | B6: =SUMPRODUCT(--('01_Anggota'!$D$5:$D$1212<>""),--('01_Anggota'!$G$5:$G$1212="")) -> 158 | C6: Tanggal wajib diisi | D6: Isi tanggal atau gunakan 2026-09-07
A7: Identitas anggota belum disetujui | B7: =COUNTIF('01_Anggota'!$K$5:$K$1212,"Belum Dipastikan") -> 0 | C7: Nama/NPP belum dipastikan | D7: Setujui atau keluarkan
A8: Simpanan tanpa nama | B8: =SUMPRODUCT(--('03_Simpanan'!$B$5:$B$1739=""),--((('03_Simpanan'!$D$5:$D$1739<>0)+('03_Simpanan'!$E$5:$E$1739<>0)+('03_Simpanan'!$F$5:$F$1739<>0)+('03_Simpanan'!$G$5:$G$1739<>0))>0)) -> 0 | C8: Ada nilai simpanan tetapi belum tersambung | D8: Pilih nama dari daftar
A9: Simpanan tanpa NPP | B9: =SUMPRODUCT(--('03_Simpanan'!$B$5:$B$1739<>""),--(('03_Simpanan'!$C$5:$C$1739="")+('03_Simpanan'!$C$5:$C$1739="NPP TIDAK DITEMUKAN")>0)) -> 0 | C9: Nama simpanan belum punya NPP | D9: Periksa 01_Anggota
A10: Pinjaman tanpa nomor atau nama | B10: =SUMPRODUCT(--(((('04_Pinjaman'!$A$5:$A$1004<>"")+('04_Pinjaman'!$B$5:$B$1004<>"")+('04_Pinjaman'!$D$5:$D$1004<>"")+('04_Pinjaman'!$E$5:$E$1004<>"")+('04_Pinjaman'!$G$5:$G$1004<>"")+('04_Pinjaman'!$H$5:$H$1004<>"")+('04_Pinjaman'!$I$5:$I$1004<>"")+('04_Pinjaman'!$J$5:$J$1004<>"")+('04_Pinjaman'!#REF!<>"")+('04_Pinjaman'!$K$5:$K$1004<>""))>0)),--((('04_Pinjaman'!$A$5:$A$1004="")+('04_Pinjaman'!$B$5:$B$1004=""))>0)) -> #REF! | C10: Pinjaman belum tersambung | D10: Isi nomor dan pilih nama
A11: Pinjaman tanpa pokok atau lama cicilan | B11: =SUMPRODUCT(--('04_Pinjaman'!$A$5:$A$1004<>""),--((('04_Pinjaman'!$E$5:$E$1004="")+('04_Pinjaman'!$H$5:$H$1004="")>0))) -> 0 | C11: Nilai pinjaman belum lengkap | D11: Lengkapi angka
A12: Pinjaman tanpa tanggal cair | B12: =SUMPRODUCT(--('04_Pinjaman'!$A$5:$A$1004<>""),--('04_Pinjaman'!$I$5:$I$1004="")) -> 0 | C12: Jadwal belum dapat dibuat | D12: Lengkapi tanggal
A13: Angsuran tanpa No Pinjaman | B13: =SUMPRODUCT(--('05_Angsuran'!$B$5:$B$1004=""),--(('05_Angsuran'!$E$5:$E$1004<>"")+('05_Angsuran'!$F$5:$F$1004<>"")>0)) -> 0 | C13: Angsuran belum tersambung | D13: Pilih No Pinjaman
A14: Angsuran tanpa tanggal atau jumlah | B14: =SUMPRODUCT(--('05_Angsuran'!$B$5:$B$1004<>""),--(('05_Angsuran'!$E$5:$E$1004="")+('05_Angsuran'!$F$5:$F$1004="")>0)) -> 0 | C14: Data angsuran belum lengkap | D14: Isi tanggal dan jumlah

Sheet 09_Contoh_Isian
A1: Contoh pengisian
A2: Semua baris di tab ini hanya contoh. Jangan kirim atau masukkan baris contoh sebagai data sebenarnya.
A3: Cara memakai: ikuti susunan kolomnya, ganti isi contoh dengan data asli, lalu hapus tab ini sebelum workbook dikirim.
A5: Contoh 01_Anggota
A6: No | B6: NPP Koperasi | C6: NPP Lama | D6: Nama Lengkap | E6: Status | F6: Jenis Anggota | G6: Tanggal Bergabung | H6: Area | I6: No. HP | J6: Alamat | K6: Keputusan Identitas | L6: Masukkan? | M6: Catatan
A7: 1 | B7: 00555 | C7: 00444 | D7: Budi Santoso | E7: Aktif | F7: Pegawai | G7: 45306 | H7: Cakung | I7: 081234567890 | J7: Alamat contoh | K7: Setuju | L7: Tidak | M7: CONTOH - HAPUS BARIS INI
A10: Contoh 02_Pencocokan_Nama
A11: No | B11: Nama dari File Asal | C11: NPP dari File Asal | D11: Nama yang Benar | E11: NPP yang Dipakai | F11: Keputusan | G11: Catatan | H11: Asal Sheet | I11: Baris Asal
A12: 1 | B12: Budi Sntoso | C12: 00555 | D12: Budi Santoso | E12: 00555 | F12: Setuju | G12: Nama typo diperbaiki | H12: Master Anggota | I12: 12
A15: Contoh 03_Simpanan
A16: No | B16: Nama Anggota | C16: NPP | D16: KHUSUS (Rp) | E16: MANASUKA (Rp) | F16: WAJIB (Rp) | G16: SHU (Rp) | H16: Catatan
A17: 1 | B17: Budi Santoso | C17: 00555 | D17: 1000 | E17: 10000 | F17: 2000 | G17: 9000 | H17: CONTOH - HAPUS BARIS INI
A20: Contoh 04_Pinjaman
A21: No Pinjaman | B21: Nama Anggota | C21: NPP | D21: Jenis Pinjaman | E21: Pokok (Rp) | F21: Admin (Rp) | G21: Total Kewajiban (Rp) | H21: Lama Cicilan (Bulan) | I21: Tanggal Cair | J21: Status | K21: Masukkan? | L21: Catatan
A22: PINJ-0001 | B22: Budi Santoso | C22: 00555 | D22: Reguler | E22: 1000000 | F22: 10000 | G22: 1010000 | H22: 10 | I22: 46023 | J22: Berjalan | K22: Ya | L22: CONTOH - HAPUS BARIS INI
A25: Contoh 05_Angsuran
A26: No Angsuran | B26: No Pinjaman | C26: Nama Anggota | D26: NPP | E26: Tanggal | F26: Jumlah (Rp) | G26: Metode | H26: Catatan
A27: 1 | B27: PINJ-0001 | C27: Budi Santoso | D27: 00555 | E27: 46081 | F27: 101000 | G27: 3. Cicilan | H27: CONTOH - HAPUS BARIS INI
A30: Contoh 06_Pengecualian
A31: Asal Sheet | B31: Baris | C31: Jenis Data | D31: Nama | E31: NPP | F31: Nilai Asli | G31: Alasan | H31: Disetujui Oleh | I31: Tanggal Persetujuan | J31: Catatan
A32: Detail Simpanan | B32: 99 | C32: Simpanan | D32: Nama Tidak Dikenal | E32: 0 | F32: Rp 20.000 | G32: Nama tidak ditemukan di daftar anggota | H32: Admin | I32: 46272 | J32: Tetap disimpan sebagai catatan
A35: Contoh 07_Pertanyaan
A36: Topik | B36: Pertanyaan | C36: Jawaban | D36: Status | E36: Asal Sheet | F36: Baris | G36: Catatan
A37: Identitas | B37: Nama dari file asal cocok dengan anggota siapa? | C37: Budi Santoso, NPP 00555 | D37: Sudah Dijawab | E37: Detail Simpanan | F37: 25 | G37: Contoh jawaban
